t id1 7
t id2 8
t id2 7
Traceback (most recent call last):
  File "/home/user/.local/lib/python3.5/site-packages/urllib3/connectionpool.py", line 672, in urlopen
    chunked=chunked,
  File "/home/user/.local/lib/python3.5/site-packages/urllib3/connectionpool.py", line 421, in _make_request
    six.raise_from(e, None)
  File "<string>", line 3, in raise_from
  File "/home/user/.local/lib/python3.5/site-packages/urllib3/connectionpool.py", line 416, in _make_request
    httplib_response = conn.getresponse()
  File "/usr/lib/python3.5/http/client.py", line 1213, in getresponse
    response.begin()
  File "/usr/lib/python3.5/http/client.py", line 307, in begin
    version, status, reason = self._read_status()
  File "/usr/lib/python3.5/http/client.py", line 276, in _read_status
    raise RemoteDisconnected("Remote end closed connection without"
http.client.RemoteDisconnected: Remote end closed connection without response

During handling of the above exception, another exception occurred:

Traceback (most recent call last):
  File "/home/user/.local/lib/python3.5/site-packages/requests/adapters.py", line 449, in send
    timeout=timeout
  File "/home/user/.local/lib/python3.5/site-packages/urllib3/connectionpool.py", line 720, in urlopen
    method, url, error=e, _pool=self, _stacktrace=sys.exc_info()[2]
  File "/home/user/.local/lib/python3.5/site-packages/urllib3/util/retry.py", line 400, in increment
    raise six.reraise(type(error), error, _stacktrace)
  File "/home/user/.local/lib/python3.5/site-packages/urllib3/packages/six.py", line 734, in reraise
    raise value.with_traceback(tb)
  File "/home/user/.local/lib/python3.5/site-packages/urllib3/connectionpool.py", line 672, in urlopen
    chunked=chunked,
  File "/home/user/.local/lib/python3.5/site-packages/urllib3/connectionpool.py", line 421, in _make_request
    six.raise_from(e, None)
  File "<string>", line 3, in raise_from
  File "/home/user/.local/lib/python3.5/site-packages/urllib3/connectionpool.py", line 416, in _make_request
    httplib_response = conn.getresponse()
  File "/usr/lib/python3.5/http/client.py", line 1213, in getresponse
    response.begin()
  File "/usr/lib/python3.5/http/client.py", line 307, in begin
    version, status, reason = self._read_status()
  File "/usr/lib/python3.5/http/client.py", line 276, in _read_status
    raise RemoteDisconnected("Remote end closed connection without"
urllib3.exceptions.ProtocolError: ('Connection aborted.', RemoteDisconnected('Remote end closed connection without response',))

During handling of the above exception, another exception occurred:

Traceback (most recent call last):
  File "cli.py", line 88, in <module>
    response = requests.post('{}/new_transaction'.format(HOST), json = json.dumps({'recipient_address': '{}'.format(node_id), 'amount': '{}'.format(amount)}))
  File "/home/user/.local/lib/python3.5/site-packages/requests/api.py", line 119, in post
    return request('post', url, data=data, json=json, **kwargs)
  File "/home/user/.local/lib/python3.5/site-packages/requests/api.py", line 61, in request
    return session.request(method=method, url=url, **kwargs)
  File "/home/user/.local/lib/python3.5/site-packages/requests/sessions.py", line 530, in request
    resp = self.send(prep, **send_kwargs)
  File "/home/user/.local/lib/python3.5/site-packages/requests/sessions.py", line 643, in send
    r = adapter.send(request, **kwargs)
  File "/home/user/.local/lib/python3.5/site-packages/requests/adapters.py", line 498, in send
    raise ConnectionError(err, request=request)
requests.exceptions.ConnectionError: ('Connection aborted.', RemoteDisconnected('Remote end closed connection without response',))
