t id1 7
t id2 8
t id2 7
t id2 5
t id1 5
t id3 6
t id1 6
t id4 6
t id4 3
t id4 4
t id3 8
t id4 7
t id4 8
t id2 4
t id1 2
t id3 3
t id2 3
t id1 1
t id3 1014
Invalid Transaction
t id1 7
t id4 5
t id4 1025
Invalid Transaction
t id3 10
t id3 1
t id4 9
t id2 1
t id1 3
t id2 1035
Invalid Transaction
t id4 3
t id4 2
t id4 1
t id1 2
t id4 6
t id2 1
t id3 1
t id2 5
t id4 6
t id2 4
t id3 10
t id4 9
t id4 3
t id3 2
t id2 4
t id4 2
t id3 5
t id2 1
t id2 10
t id2 7
t id3 1055
Invalid Transaction
t id3 4
t id1 6
t id2 8
t id3 2
t id2 8
t id2 1
t id1 1
t id1 6
t id3 8
t id4 8
t id3 3
t id1 7
t id1 1
Traceback (most recent call last):
  File "/home/nikitas/anaconda3/lib/python3.7/site-packages/urllib3/connectionpool.py", line 600, in urlopen
    chunked=chunked)
  File "/home/nikitas/anaconda3/lib/python3.7/site-packages/urllib3/connectionpool.py", line 384, in _make_request
    six.raise_from(e, None)
  File "<string>", line 2, in raise_from
  File "/home/nikitas/anaconda3/lib/python3.7/site-packages/urllib3/connectionpool.py", line 380, in _make_request
    httplib_response = conn.getresponse()
  File "/home/nikitas/anaconda3/lib/python3.7/http/client.py", line 1336, in getresponse
    response.begin()
  File "/home/nikitas/anaconda3/lib/python3.7/http/client.py", line 306, in begin
    version, status, reason = self._read_status()
  File "/home/nikitas/anaconda3/lib/python3.7/http/client.py", line 275, in _read_status
    raise RemoteDisconnected("Remote end closed connection without"
http.client.RemoteDisconnected: Remote end closed connection without response

During handling of the above exception, another exception occurred:

Traceback (most recent call last):
  File "/home/nikitas/anaconda3/lib/python3.7/site-packages/requests/adapters.py", line 449, in send
    timeout=timeout
  File "/home/nikitas/anaconda3/lib/python3.7/site-packages/urllib3/connectionpool.py", line 638, in urlopen
    _stacktrace=sys.exc_info()[2])
  File "/home/nikitas/anaconda3/lib/python3.7/site-packages/urllib3/util/retry.py", line 368, in increment
    raise six.reraise(type(error), error, _stacktrace)
  File "/home/nikitas/anaconda3/lib/python3.7/site-packages/urllib3/packages/six.py", line 685, in reraise
    raise value.with_traceback(tb)
  File "/home/nikitas/anaconda3/lib/python3.7/site-packages/urllib3/connectionpool.py", line 600, in urlopen
    chunked=chunked)
  File "/home/nikitas/anaconda3/lib/python3.7/site-packages/urllib3/connectionpool.py", line 384, in _make_request
    six.raise_from(e, None)
  File "<string>", line 2, in raise_from
  File "/home/nikitas/anaconda3/lib/python3.7/site-packages/urllib3/connectionpool.py", line 380, in _make_request
    httplib_response = conn.getresponse()
  File "/home/nikitas/anaconda3/lib/python3.7/http/client.py", line 1336, in getresponse
    response.begin()
  File "/home/nikitas/anaconda3/lib/python3.7/http/client.py", line 306, in begin
    version, status, reason = self._read_status()
  File "/home/nikitas/anaconda3/lib/python3.7/http/client.py", line 275, in _read_status
    raise RemoteDisconnected("Remote end closed connection without"
urllib3.exceptions.ProtocolError: ('Connection aborted.', RemoteDisconnected('Remote end closed connection without response'))

During handling of the above exception, another exception occurred:

Traceback (most recent call last):
  File "cli.py", line 88, in <module>
    response = requests.post('{}/new_transaction'.format(HOST), json = json.dumps({'recipient_address': '{}'.format(node_id), 'amount': '{}'.format(amount)}))
  File "/home/nikitas/anaconda3/lib/python3.7/site-packages/requests/api.py", line 116, in post
    return request('post', url, data=data, json=json, **kwargs)
  File "/home/nikitas/anaconda3/lib/python3.7/site-packages/requests/api.py", line 60, in request
    return session.request(method=method, url=url, **kwargs)
  File "/home/nikitas/anaconda3/lib/python3.7/site-packages/requests/sessions.py", line 533, in request
    resp = self.send(prep, **send_kwargs)
  File "/home/nikitas/anaconda3/lib/python3.7/site-packages/requests/sessions.py", line 646, in send
    r = adapter.send(request, **kwargs)
  File "/home/nikitas/anaconda3/lib/python3.7/site-packages/requests/adapters.py", line 498, in send
    raise ConnectionError(err, request=request)
requests.exceptions.ConnectionError: ('Connection aborted.', RemoteDisconnected('Remote end closed connection without response'))
