 * Serving Flask app "server" (lazy loading)
 * Environment: production
   WARNING: This is a development server. Do not use it in a production deployment.
   Use a production WSGI server instead.
 * Debug mode: on
 * Running on http://192.168.1.1:1234/ (Press CTRL+C to quit)
 * Restarting with stat
 * Debugger is active!
 * Debugger PIN: 193-972-195
5
-------- genesis --------
192.168.1.1 - - [05/Apr/2020 04:17:51] "[37mPOST /start_coordinator HTTP/1.1[0m" 201 -
new node id is: 1
192.168.1.2 - - [05/Apr/2020 04:17:51] "[37mPOST /register_node HTTP/1.1[0m" 200 -
new node id is: 2
192.168.1.4 - - [05/Apr/2020 04:17:51] "[37mPOST /register_node HTTP/1.1[0m" 200 -
new node id is: 3
192.168.1.3 - - [05/Apr/2020 04:17:51] "[37mPOST /register_node HTTP/1.1[0m" 200 -
192.168.1.1 - - [05/Apr/2020 04:17:51] "[37mGET /notify_start HTTP/1.1[0m" 200 -
192.168.1.1 - - [05/Apr/2020 04:17:51] "[37mGET /notify_start HTTP/1.1[0m" 200 -
192.168.1.1 - - [05/Apr/2020 04:17:51] "[37mGET /notify_start HTTP/1.1[0m" 200 -
new node id is: 4
Broadcasting info
Broadcasting info
192.168.1.1 - - [05/Apr/2020 04:17:51] "[37mGET /notify_start HTTP/1.1[0m" 200 -
True
True
True
192.168.1.1 - - [05/Apr/2020 04:17:52] "[37mGET /notify_start HTTP/1.1[0m" 200 -
True
True
Giving command to start
192.168.1.5 - - [05/Apr/2020 04:17:52] "[37mPOST /register_node HTTP/1.1[0m" 200 -
192.168.1.1 - - [05/Apr/2020 04:17:52] "[37mGET /notify_start HTTP/1.1[0m" 200 -
192.168.1.1 - - [05/Apr/2020 04:17:52] "[35m[1mPOST /new_transaction HTTP/1.1[0m" 500 -
Traceback (most recent call last):
  File "/home/user/.local/lib/python3.5/site-packages/flask/app.py", line 2464, in __call__
    return self.wsgi_app(environ, start_response)
  File "/home/user/.local/lib/python3.5/site-packages/flask/app.py", line 2450, in wsgi_app
    response = self.handle_exception(e)
  File "/home/user/.local/lib/python3.5/site-packages/flask/app.py", line 1867, in handle_exception
    reraise(exc_type, exc_value, tb)
  File "/home/user/.local/lib/python3.5/site-packages/flask/_compat.py", line 39, in reraise
    raise value
  File "/home/user/.local/lib/python3.5/site-packages/flask/app.py", line 2447, in wsgi_app
    response = self.full_dispatch_request()
  File "/home/user/.local/lib/python3.5/site-packages/flask/app.py", line 1952, in full_dispatch_request
    rv = self.handle_user_exception(e)
  File "/home/user/.local/lib/python3.5/site-packages/flask/app.py", line 1821, in handle_user_exception
    reraise(exc_type, exc_value, tb)
  File "/home/user/.local/lib/python3.5/site-packages/flask/_compat.py", line 39, in reraise
    raise value
  File "/home/user/.local/lib/python3.5/site-packages/flask/app.py", line 1950, in full_dispatch_request
    rv = self.dispatch_request()
  File "/home/user/.local/lib/python3.5/site-packages/flask/app.py", line 1936, in dispatch_request
    return self.view_functions[rule.endpoint](**req.view_args)
  File "/home/user/noobcash/noobcash/backend/broadcast.py", line 221, in cli_new_transaction
    node = State.state.nodes[node_id]
KeyError: 'id1'
192.168.1.1 - - [05/Apr/2020 04:17:52] "[37mGET /balance HTTP/1.1[0m" 200 -
192.168.1.1 - - [05/Apr/2020 04:17:52] "[35m[1mPOST /new_transaction HTTP/1.1[0m" 500 -
Traceback (most recent call last):
  File "/home/user/.local/lib/python3.5/site-packages/flask/app.py", line 2464, in __call__
    return self.wsgi_app(environ, start_response)
  File "/home/user/.local/lib/python3.5/site-packages/flask/app.py", line 2450, in wsgi_app
    response = self.handle_exception(e)
  File "/home/user/.local/lib/python3.5/site-packages/flask/app.py", line 1867, in handle_exception
    reraise(exc_type, exc_value, tb)
  File "/home/user/.local/lib/python3.5/site-packages/flask/_compat.py", line 39, in reraise
    raise value
  File "/home/user/.local/lib/python3.5/site-packages/flask/app.py", line 2447, in wsgi_app
    response = self.full_dispatch_request()
  File "/home/user/.local/lib/python3.5/site-packages/flask/app.py", line 1952, in full_dispatch_request
    rv = self.handle_user_exception(e)
  File "/home/user/.local/lib/python3.5/site-packages/flask/app.py", line 1821, in handle_user_exception
    reraise(exc_type, exc_value, tb)
  File "/home/user/.local/lib/python3.5/site-packages/flask/_compat.py", line 39, in reraise
    raise value
  File "/home/user/.local/lib/python3.5/site-packages/flask/app.py", line 1950, in full_dispatch_request
    rv = self.dispatch_request()
  File "/home/user/.local/lib/python3.5/site-packages/flask/app.py", line 1936, in dispatch_request
    return self.view_functions[rule.endpoint](**req.view_args)
  File "/home/user/noobcash/noobcash/backend/broadcast.py", line 221, in cli_new_transaction
    node = State.state.nodes[node_id]
KeyError: 'id2'
192.168.1.1 - - [05/Apr/2020 04:17:52] "[37mGET /balance HTTP/1.1[0m" 200 -
192.168.1.1 - - [05/Apr/2020 04:17:52] "[35m[1mPOST /new_transaction HTTP/1.1[0m" 500 -
Traceback (most recent call last):
  File "/home/user/.local/lib/python3.5/site-packages/flask/app.py", line 2464, in __call__
    return self.wsgi_app(environ, start_response)
  File "/home/user/.local/lib/python3.5/site-packages/flask/app.py", line 2450, in wsgi_app
    response = self.handle_exception(e)
  File "/home/user/.local/lib/python3.5/site-packages/flask/app.py", line 1867, in handle_exception
    reraise(exc_type, exc_value, tb)
  File "/home/user/.local/lib/python3.5/site-packages/flask/_compat.py", line 39, in reraise
    raise value
  File "/home/user/.local/lib/python3.5/site-packages/flask/app.py", line 2447, in wsgi_app
    response = self.full_dispatch_request()
  File "/home/user/.local/lib/python3.5/site-packages/flask/app.py", line 1952, in full_dispatch_request
    rv = self.handle_user_exception(e)
  File "/home/user/.local/lib/python3.5/site-packages/flask/app.py", line 1821, in handle_user_exception
    reraise(exc_type, exc_value, tb)
  File "/home/user/.local/lib/python3.5/site-packages/flask/_compat.py", line 39, in reraise
    raise value
  File "/home/user/.local/lib/python3.5/site-packages/flask/app.py", line 1950, in full_dispatch_request
    rv = self.dispatch_request()
  File "/home/user/.local/lib/python3.5/site-packages/flask/app.py", line 1936, in dispatch_request
    return self.view_functions[rule.endpoint](**req.view_args)
  File "/home/user/noobcash/noobcash/backend/broadcast.py", line 221, in cli_new_transaction
    node = State.state.nodes[node_id]
KeyError: 'id2'
192.168.1.1 - - [05/Apr/2020 04:17:52] "[37mGET /balance HTTP/1.1[0m" 200 -
192.168.1.1 - - [05/Apr/2020 04:17:52] "[35m[1mPOST /new_transaction HTTP/1.1[0m" 500 -
Traceback (most recent call last):
  File "/home/user/.local/lib/python3.5/site-packages/flask/app.py", line 2464, in __call__
    return self.wsgi_app(environ, start_response)
  File "/home/user/.local/lib/python3.5/site-packages/flask/app.py", line 2450, in wsgi_app
    response = self.handle_exception(e)
  File "/home/user/.local/lib/python3.5/site-packages/flask/app.py", line 1867, in handle_exception
    reraise(exc_type, exc_value, tb)
  File "/home/user/.local/lib/python3.5/site-packages/flask/_compat.py", line 39, in reraise
    raise value
  File "/home/user/.local/lib/python3.5/site-packages/flask/app.py", line 2447, in wsgi_app
    response = self.full_dispatch_request()
  File "/home/user/.local/lib/python3.5/site-packages/flask/app.py", line 1952, in full_dispatch_request
    rv = self.handle_user_exception(e)
  File "/home/user/.local/lib/python3.5/site-packages/flask/app.py", line 1821, in handle_user_exception
    reraise(exc_type, exc_value, tb)
  File "/home/user/.local/lib/python3.5/site-packages/flask/_compat.py", line 39, in reraise
    raise value
  File "/home/user/.local/lib/python3.5/site-packages/flask/app.py", line 1950, in full_dispatch_request
    rv = self.dispatch_request()
  File "/home/user/.local/lib/python3.5/site-packages/flask/app.py", line 1936, in dispatch_request
    return self.view_functions[rule.endpoint](**req.view_args)
  File "/home/user/noobcash/noobcash/backend/broadcast.py", line 221, in cli_new_transaction
    node = State.state.nodes[node_id]
KeyError: 'id2'
192.168.1.1 - - [05/Apr/2020 04:17:52] "[37mGET /balance HTTP/1.1[0m" 200 -
192.168.1.1 - - [05/Apr/2020 04:17:52] "[35m[1mPOST /new_transaction HTTP/1.1[0m" 500 -
Traceback (most recent call last):
  File "/home/user/.local/lib/python3.5/site-packages/flask/app.py", line 2464, in __call__
    return self.wsgi_app(environ, start_response)
  File "/home/user/.local/lib/python3.5/site-packages/flask/app.py", line 2450, in wsgi_app
    response = self.handle_exception(e)
  File "/home/user/.local/lib/python3.5/site-packages/flask/app.py", line 1867, in handle_exception
    reraise(exc_type, exc_value, tb)
  File "/home/user/.local/lib/python3.5/site-packages/flask/_compat.py", line 39, in reraise
    raise value
  File "/home/user/.local/lib/python3.5/site-packages/flask/app.py", line 2447, in wsgi_app
    response = self.full_dispatch_request()
  File "/home/user/.local/lib/python3.5/site-packages/flask/app.py", line 1952, in full_dispatch_request
    rv = self.handle_user_exception(e)
  File "/home/user/.local/lib/python3.5/site-packages/flask/app.py", line 1821, in handle_user_exception
    reraise(exc_type, exc_value, tb)
  File "/home/user/.local/lib/python3.5/site-packages/flask/_compat.py", line 39, in reraise
    raise value
  File "/home/user/.local/lib/python3.5/site-packages/flask/app.py", line 1950, in full_dispatch_request
    rv = self.dispatch_request()
  File "/home/user/.local/lib/python3.5/site-packages/flask/app.py", line 1936, in dispatch_request
    return self.view_functions[rule.endpoint](**req.view_args)
  File "/home/user/noobcash/noobcash/backend/broadcast.py", line 221, in cli_new_transaction
    node = State.state.nodes[node_id]
KeyError: 'id1'
192.168.1.1 - - [05/Apr/2020 04:17:52] "[37mGET /balance HTTP/1.1[0m" 200 -
192.168.1.1 - - [05/Apr/2020 04:17:52] "[35m[1mPOST /new_transaction HTTP/1.1[0m" 500 -
Traceback (most recent call last):
  File "/home/user/.local/lib/python3.5/site-packages/flask/app.py", line 2464, in __call__
    return self.wsgi_app(environ, start_response)
  File "/home/user/.local/lib/python3.5/site-packages/flask/app.py", line 2450, in wsgi_app
    response = self.handle_exception(e)
  File "/home/user/.local/lib/python3.5/site-packages/flask/app.py", line 1867, in handle_exception
    reraise(exc_type, exc_value, tb)
  File "/home/user/.local/lib/python3.5/site-packages/flask/_compat.py", line 39, in reraise
    raise value
  File "/home/user/.local/lib/python3.5/site-packages/flask/app.py", line 2447, in wsgi_app
    response = self.full_dispatch_request()
  File "/home/user/.local/lib/python3.5/site-packages/flask/app.py", line 1952, in full_dispatch_request
    rv = self.handle_user_exception(e)
  File "/home/user/.local/lib/python3.5/site-packages/flask/app.py", line 1821, in handle_user_exception
    reraise(exc_type, exc_value, tb)
  File "/home/user/.local/lib/python3.5/site-packages/flask/_compat.py", line 39, in reraise
    raise value
  File "/home/user/.local/lib/python3.5/site-packages/flask/app.py", line 1950, in full_dispatch_request
    rv = self.dispatch_request()
  File "/home/user/.local/lib/python3.5/site-packages/flask/app.py", line 1936, in dispatch_request
    return self.view_functions[rule.endpoint](**req.view_args)
  File "/home/user/noobcash/noobcash/backend/broadcast.py", line 221, in cli_new_transaction
    node = State.state.nodes[node_id]
KeyError: 'id3'
192.168.1.1 - - [05/Apr/2020 04:17:52] "[37mGET /balance HTTP/1.1[0m" 200 -
192.168.1.1 - - [05/Apr/2020 04:17:52] "[35m[1mPOST /new_transaction HTTP/1.1[0m" 500 -
Traceback (most recent call last):
  File "/home/user/.local/lib/python3.5/site-packages/flask/app.py", line 2464, in __call__
    return self.wsgi_app(environ, start_response)
  File "/home/user/.local/lib/python3.5/site-packages/flask/app.py", line 2450, in wsgi_app
    response = self.handle_exception(e)
  File "/home/user/.local/lib/python3.5/site-packages/flask/app.py", line 1867, in handle_exception
    reraise(exc_type, exc_value, tb)
  File "/home/user/.local/lib/python3.5/site-packages/flask/_compat.py", line 39, in reraise
    raise value
  File "/home/user/.local/lib/python3.5/site-packages/flask/app.py", line 2447, in wsgi_app
    response = self.full_dispatch_request()
  File "/home/user/.local/lib/python3.5/site-packages/flask/app.py", line 1952, in full_dispatch_request
    rv = self.handle_user_exception(e)
  File "/home/user/.local/lib/python3.5/site-packages/flask/app.py", line 1821, in handle_user_exception
    reraise(exc_type, exc_value, tb)
  File "/home/user/.local/lib/python3.5/site-packages/flask/_compat.py", line 39, in reraise
    raise value
  File "/home/user/.local/lib/python3.5/site-packages/flask/app.py", line 1950, in full_dispatch_request
    rv = self.dispatch_request()
  File "/home/user/.local/lib/python3.5/site-packages/flask/app.py", line 1936, in dispatch_request
    return self.view_functions[rule.endpoint](**req.view_args)
  File "/home/user/noobcash/noobcash/backend/broadcast.py", line 221, in cli_new_transaction
    node = State.state.nodes[node_id]
KeyError: 'id1'
192.168.1.1 - - [05/Apr/2020 04:17:52] "[37mGET /balance HTTP/1.1[0m" 200 -
192.168.1.1 - - [05/Apr/2020 04:17:52] "[35m[1mPOST /new_transaction HTTP/1.1[0m" 500 -
Traceback (most recent call last):
  File "/home/user/.local/lib/python3.5/site-packages/flask/app.py", line 2464, in __call__
    return self.wsgi_app(environ, start_response)
  File "/home/user/.local/lib/python3.5/site-packages/flask/app.py", line 2450, in wsgi_app
    response = self.handle_exception(e)
  File "/home/user/.local/lib/python3.5/site-packages/flask/app.py", line 1867, in handle_exception
    reraise(exc_type, exc_value, tb)
  File "/home/user/.local/lib/python3.5/site-packages/flask/_compat.py", line 39, in reraise
    raise value
  File "/home/user/.local/lib/python3.5/site-packages/flask/app.py", line 2447, in wsgi_app
    response = self.full_dispatch_request()
  File "/home/user/.local/lib/python3.5/site-packages/flask/app.py", line 1952, in full_dispatch_request
    rv = self.handle_user_exception(e)
  File "/home/user/.local/lib/python3.5/site-packages/flask/app.py", line 1821, in handle_user_exception
    reraise(exc_type, exc_value, tb)
  File "/home/user/.local/lib/python3.5/site-packages/flask/_compat.py", line 39, in reraise
    raise value
  File "/home/user/.local/lib/python3.5/site-packages/flask/app.py", line 1950, in full_dispatch_request
    rv = self.dispatch_request()
  File "/home/user/.local/lib/python3.5/site-packages/flask/app.py", line 1936, in dispatch_request
    return self.view_functions[rule.endpoint](**req.view_args)
  File "/home/user/noobcash/noobcash/backend/broadcast.py", line 221, in cli_new_transaction
    node = State.state.nodes[node_id]
KeyError: 'id4'
192.168.1.1 - - [05/Apr/2020 04:17:52] "[37mGET /balance HTTP/1.1[0m" 200 -
192.168.1.1 - - [05/Apr/2020 04:17:52] "[35m[1mPOST /new_transaction HTTP/1.1[0m" 500 -
Traceback (most recent call last):
  File "/home/user/.local/lib/python3.5/site-packages/flask/app.py", line 2464, in __call__
    return self.wsgi_app(environ, start_response)
  File "/home/user/.local/lib/python3.5/site-packages/flask/app.py", line 2450, in wsgi_app
    response = self.handle_exception(e)
  File "/home/user/.local/lib/python3.5/site-packages/flask/app.py", line 1867, in handle_exception
    reraise(exc_type, exc_value, tb)
  File "/home/user/.local/lib/python3.5/site-packages/flask/_compat.py", line 39, in reraise
    raise value
  File "/home/user/.local/lib/python3.5/site-packages/flask/app.py", line 2447, in wsgi_app
    response = self.full_dispatch_request()
  File "/home/user/.local/lib/python3.5/site-packages/flask/app.py", line 1952, in full_dispatch_request
    rv = self.handle_user_exception(e)
  File "/home/user/.local/lib/python3.5/site-packages/flask/app.py", line 1821, in handle_user_exception
    reraise(exc_type, exc_value, tb)
  File "/home/user/.local/lib/python3.5/site-packages/flask/_compat.py", line 39, in reraise
    raise value
  File "/home/user/.local/lib/python3.5/site-packages/flask/app.py", line 1950, in full_dispatch_request
    rv = self.dispatch_request()
  File "/home/user/.local/lib/python3.5/site-packages/flask/app.py", line 1936, in dispatch_request
    return self.view_functions[rule.endpoint](**req.view_args)
  File "/home/user/noobcash/noobcash/backend/broadcast.py", line 221, in cli_new_transaction
    node = State.state.nodes[node_id]
KeyError: 'id4'
192.168.1.1 - - [05/Apr/2020 04:17:52] "[37mGET /balance HTTP/1.1[0m" 200 -
192.168.1.1 - - [05/Apr/2020 04:17:52] "[35m[1mPOST /new_transaction HTTP/1.1[0m" 500 -
Traceback (most recent call last):
  File "/home/user/.local/lib/python3.5/site-packages/flask/app.py", line 2464, in __call__
    return self.wsgi_app(environ, start_response)
  File "/home/user/.local/lib/python3.5/site-packages/flask/app.py", line 2450, in wsgi_app
    response = self.handle_exception(e)
  File "/home/user/.local/lib/python3.5/site-packages/flask/app.py", line 1867, in handle_exception
    reraise(exc_type, exc_value, tb)
  File "/home/user/.local/lib/python3.5/site-packages/flask/_compat.py", line 39, in reraise
    raise value
  File "/home/user/.local/lib/python3.5/site-packages/flask/app.py", line 2447, in wsgi_app
    response = self.full_dispatch_request()
  File "/home/user/.local/lib/python3.5/site-packages/flask/app.py", line 1952, in full_dispatch_request
    rv = self.handle_user_exception(e)
  File "/home/user/.local/lib/python3.5/site-packages/flask/app.py", line 1821, in handle_user_exception
    reraise(exc_type, exc_value, tb)
  File "/home/user/.local/lib/python3.5/site-packages/flask/_compat.py", line 39, in reraise
    raise value
  File "/home/user/.local/lib/python3.5/site-packages/flask/app.py", line 1950, in full_dispatch_request
    rv = self.dispatch_request()
  File "/home/user/.local/lib/python3.5/site-packages/flask/app.py", line 1936, in dispatch_request
    return self.view_functions[rule.endpoint](**req.view_args)
  File "/home/user/noobcash/noobcash/backend/broadcast.py", line 221, in cli_new_transaction
    node = State.state.nodes[node_id]
KeyError: 'id4'
192.168.1.1 - - [05/Apr/2020 04:17:52] "[37mGET /balance HTTP/1.1[0m" 200 -
192.168.1.1 - - [05/Apr/2020 04:17:52] "[35m[1mPOST /new_transaction HTTP/1.1[0m" 500 -
Traceback (most recent call last):
  File "/home/user/.local/lib/python3.5/site-packages/flask/app.py", line 2464, in __call__
    return self.wsgi_app(environ, start_response)
  File "/home/user/.local/lib/python3.5/site-packages/flask/app.py", line 2450, in wsgi_app
    response = self.handle_exception(e)
  File "/home/user/.local/lib/python3.5/site-packages/flask/app.py", line 1867, in handle_exception
    reraise(exc_type, exc_value, tb)
  File "/home/user/.local/lib/python3.5/site-packages/flask/_compat.py", line 39, in reraise
    raise value
  File "/home/user/.local/lib/python3.5/site-packages/flask/app.py", line 2447, in wsgi_app
    response = self.full_dispatch_request()
  File "/home/user/.local/lib/python3.5/site-packages/flask/app.py", line 1952, in full_dispatch_request
    rv = self.handle_user_exception(e)
  File "/home/user/.local/lib/python3.5/site-packages/flask/app.py", line 1821, in handle_user_exception
    reraise(exc_type, exc_value, tb)
  File "/home/user/.local/lib/python3.5/site-packages/flask/_compat.py", line 39, in reraise
    raise value
  File "/home/user/.local/lib/python3.5/site-packages/flask/app.py", line 1950, in full_dispatch_request
    rv = self.dispatch_request()
  File "/home/user/.local/lib/python3.5/site-packages/flask/app.py", line 1936, in dispatch_request
    return self.view_functions[rule.endpoint](**req.view_args)
  File "/home/user/noobcash/noobcash/backend/broadcast.py", line 221, in cli_new_transaction
    node = State.state.nodes[node_id]
KeyError: 'id3'
192.168.1.1 - - [05/Apr/2020 04:17:52] "[37mGET /balance HTTP/1.1[0m" 200 -
192.168.1.1 - - [05/Apr/2020 04:17:52] "[35m[1mPOST /new_transaction HTTP/1.1[0m" 500 -
Traceback (most recent call last):
  File "/home/user/.local/lib/python3.5/site-packages/flask/app.py", line 2464, in __call__
    return self.wsgi_app(environ, start_response)
  File "/home/user/.local/lib/python3.5/site-packages/flask/app.py", line 2450, in wsgi_app
    response = self.handle_exception(e)
  File "/home/user/.local/lib/python3.5/site-packages/flask/app.py", line 1867, in handle_exception
    reraise(exc_type, exc_value, tb)
  File "/home/user/.local/lib/python3.5/site-packages/flask/_compat.py", line 39, in reraise
    raise value
  File "/home/user/.local/lib/python3.5/site-packages/flask/app.py", line 2447, in wsgi_app
    response = self.full_dispatch_request()
  File "/home/user/.local/lib/python3.5/site-packages/flask/app.py", line 1952, in full_dispatch_request
    rv = self.handle_user_exception(e)
  File "/home/user/.local/lib/python3.5/site-packages/flask/app.py", line 1821, in handle_user_exception
    reraise(exc_type, exc_value, tb)
  File "/home/user/.local/lib/python3.5/site-packages/flask/_compat.py", line 39, in reraise
    raise value
  File "/home/user/.local/lib/python3.5/site-packages/flask/app.py", line 1950, in full_dispatch_request
    rv = self.dispatch_request()
  File "/home/user/.local/lib/python3.5/site-packages/flask/app.py", line 1936, in dispatch_request
    return self.view_functions[rule.endpoint](**req.view_args)
  File "/home/user/noobcash/noobcash/backend/broadcast.py", line 221, in cli_new_transaction
    node = State.state.nodes[node_id]
KeyError: 'id4'
192.168.1.1 - - [05/Apr/2020 04:17:52] "[37mGET /balance HTTP/1.1[0m" 200 -
192.168.1.1 - - [05/Apr/2020 04:17:52] "[35m[1mPOST /new_transaction HTTP/1.1[0m" 500 -
Traceback (most recent call last):
  File "/home/user/.local/lib/python3.5/site-packages/flask/app.py", line 2464, in __call__
    return self.wsgi_app(environ, start_response)
  File "/home/user/.local/lib/python3.5/site-packages/flask/app.py", line 2450, in wsgi_app
    response = self.handle_exception(e)
  File "/home/user/.local/lib/python3.5/site-packages/flask/app.py", line 1867, in handle_exception
    reraise(exc_type, exc_value, tb)
  File "/home/user/.local/lib/python3.5/site-packages/flask/_compat.py", line 39, in reraise
    raise value
  File "/home/user/.local/lib/python3.5/site-packages/flask/app.py", line 2447, in wsgi_app
    response = self.full_dispatch_request()
  File "/home/user/.local/lib/python3.5/site-packages/flask/app.py", line 1952, in full_dispatch_request
    rv = self.handle_user_exception(e)
  File "/home/user/.local/lib/python3.5/site-packages/flask/app.py", line 1821, in handle_user_exception
    reraise(exc_type, exc_value, tb)
  File "/home/user/.local/lib/python3.5/site-packages/flask/_compat.py", line 39, in reraise
    raise value
  File "/home/user/.local/lib/python3.5/site-packages/flask/app.py", line 1950, in full_dispatch_request
    rv = self.dispatch_request()
  File "/home/user/.local/lib/python3.5/site-packages/flask/app.py", line 1936, in dispatch_request
    return self.view_functions[rule.endpoint](**req.view_args)
  File "/home/user/noobcash/noobcash/backend/broadcast.py", line 221, in cli_new_transaction
    node = State.state.nodes[node_id]
KeyError: 'id4'
192.168.1.1 - - [05/Apr/2020 04:17:52] "[37mGET /balance HTTP/1.1[0m" 200 -
192.168.1.1 - - [05/Apr/2020 04:17:52] "[35m[1mPOST /new_transaction HTTP/1.1[0m" 500 -
Traceback (most recent call last):
  File "/home/user/.local/lib/python3.5/site-packages/flask/app.py", line 2464, in __call__
    return self.wsgi_app(environ, start_response)
  File "/home/user/.local/lib/python3.5/site-packages/flask/app.py", line 2450, in wsgi_app
    response = self.handle_exception(e)
  File "/home/user/.local/lib/python3.5/site-packages/flask/app.py", line 1867, in handle_exception
    reraise(exc_type, exc_value, tb)
  File "/home/user/.local/lib/python3.5/site-packages/flask/_compat.py", line 39, in reraise
    raise value
  File "/home/user/.local/lib/python3.5/site-packages/flask/app.py", line 2447, in wsgi_app
    response = self.full_dispatch_request()
  File "/home/user/.local/lib/python3.5/site-packages/flask/app.py", line 1952, in full_dispatch_request
    rv = self.handle_user_exception(e)
  File "/home/user/.local/lib/python3.5/site-packages/flask/app.py", line 1821, in handle_user_exception
    reraise(exc_type, exc_value, tb)
  File "/home/user/.local/lib/python3.5/site-packages/flask/_compat.py", line 39, in reraise
    raise value
  File "/home/user/.local/lib/python3.5/site-packages/flask/app.py", line 1950, in full_dispatch_request
    rv = self.dispatch_request()
  File "/home/user/.local/lib/python3.5/site-packages/flask/app.py", line 1936, in dispatch_request
    return self.view_functions[rule.endpoint](**req.view_args)
  File "/home/user/noobcash/noobcash/backend/broadcast.py", line 221, in cli_new_transaction
    node = State.state.nodes[node_id]
KeyError: 'id2'
192.168.1.1 - - [05/Apr/2020 04:17:52] "[37mGET /balance HTTP/1.1[0m" 200 -
192.168.1.1 - - [05/Apr/2020 04:17:52] "[35m[1mPOST /new_transaction HTTP/1.1[0m" 500 -
Traceback (most recent call last):
  File "/home/user/.local/lib/python3.5/site-packages/flask/app.py", line 2464, in __call__
    return self.wsgi_app(environ, start_response)
  File "/home/user/.local/lib/python3.5/site-packages/flask/app.py", line 2450, in wsgi_app
    response = self.handle_exception(e)
  File "/home/user/.local/lib/python3.5/site-packages/flask/app.py", line 1867, in handle_exception
    reraise(exc_type, exc_value, tb)
  File "/home/user/.local/lib/python3.5/site-packages/flask/_compat.py", line 39, in reraise
    raise value
  File "/home/user/.local/lib/python3.5/site-packages/flask/app.py", line 2447, in wsgi_app
    response = self.full_dispatch_request()
  File "/home/user/.local/lib/python3.5/site-packages/flask/app.py", line 1952, in full_dispatch_request
    rv = self.handle_user_exception(e)
  File "/home/user/.local/lib/python3.5/site-packages/flask/app.py", line 1821, in handle_user_exception
    reraise(exc_type, exc_value, tb)
  File "/home/user/.local/lib/python3.5/site-packages/flask/_compat.py", line 39, in reraise
    raise value
  File "/home/user/.local/lib/python3.5/site-packages/flask/app.py", line 1950, in full_dispatch_request
    rv = self.dispatch_request()
  File "/home/user/.local/lib/python3.5/site-packages/flask/app.py", line 1936, in dispatch_request
    return self.view_functions[rule.endpoint](**req.view_args)
  File "/home/user/noobcash/noobcash/backend/broadcast.py", line 221, in cli_new_transaction
    node = State.state.nodes[node_id]
KeyError: 'id1'
192.168.1.1 - - [05/Apr/2020 04:17:52] "[37mGET /balance HTTP/1.1[0m" 200 -
192.168.1.1 - - [05/Apr/2020 04:17:52] "[35m[1mPOST /new_transaction HTTP/1.1[0m" 500 -
Traceback (most recent call last):
  File "/home/user/.local/lib/python3.5/site-packages/flask/app.py", line 2464, in __call__
    return self.wsgi_app(environ, start_response)
  File "/home/user/.local/lib/python3.5/site-packages/flask/app.py", line 2450, in wsgi_app
    response = self.handle_exception(e)
  File "/home/user/.local/lib/python3.5/site-packages/flask/app.py", line 1867, in handle_exception
    reraise(exc_type, exc_value, tb)
  File "/home/user/.local/lib/python3.5/site-packages/flask/_compat.py", line 39, in reraise
    raise value
  File "/home/user/.local/lib/python3.5/site-packages/flask/app.py", line 2447, in wsgi_app
    response = self.full_dispatch_request()
  File "/home/user/.local/lib/python3.5/site-packages/flask/app.py", line 1952, in full_dispatch_request
    rv = self.handle_user_exception(e)
  File "/home/user/.local/lib/python3.5/site-packages/flask/app.py", line 1821, in handle_user_exception
    reraise(exc_type, exc_value, tb)
  File "/home/user/.local/lib/python3.5/site-packages/flask/_compat.py", line 39, in reraise
    raise value
  File "/home/user/.local/lib/python3.5/site-packages/flask/app.py", line 1950, in full_dispatch_request
    rv = self.dispatch_request()
  File "/home/user/.local/lib/python3.5/site-packages/flask/app.py", line 1936, in dispatch_request
    return self.view_functions[rule.endpoint](**req.view_args)
  File "/home/user/noobcash/noobcash/backend/broadcast.py", line 221, in cli_new_transaction
    node = State.state.nodes[node_id]
KeyError: 'id3'
192.168.1.1 - - [05/Apr/2020 04:17:52] "[37mGET /balance HTTP/1.1[0m" 200 -
192.168.1.1 - - [05/Apr/2020 04:17:52] "[35m[1mPOST /new_transaction HTTP/1.1[0m" 500 -
Traceback (most recent call last):
  File "/home/user/.local/lib/python3.5/site-packages/flask/app.py", line 2464, in __call__
    return self.wsgi_app(environ, start_response)
  File "/home/user/.local/lib/python3.5/site-packages/flask/app.py", line 2450, in wsgi_app
    response = self.handle_exception(e)
  File "/home/user/.local/lib/python3.5/site-packages/flask/app.py", line 1867, in handle_exception
    reraise(exc_type, exc_value, tb)
  File "/home/user/.local/lib/python3.5/site-packages/flask/_compat.py", line 39, in reraise
    raise value
  File "/home/user/.local/lib/python3.5/site-packages/flask/app.py", line 2447, in wsgi_app
    response = self.full_dispatch_request()
  File "/home/user/.local/lib/python3.5/site-packages/flask/app.py", line 1952, in full_dispatch_request
    rv = self.handle_user_exception(e)
  File "/home/user/.local/lib/python3.5/site-packages/flask/app.py", line 1821, in handle_user_exception
    reraise(exc_type, exc_value, tb)
  File "/home/user/.local/lib/python3.5/site-packages/flask/_compat.py", line 39, in reraise
    raise value
  File "/home/user/.local/lib/python3.5/site-packages/flask/app.py", line 1950, in full_dispatch_request
    rv = self.dispatch_request()
  File "/home/user/.local/lib/python3.5/site-packages/flask/app.py", line 1936, in dispatch_request
    return self.view_functions[rule.endpoint](**req.view_args)
  File "/home/user/noobcash/noobcash/backend/broadcast.py", line 221, in cli_new_transaction
    node = State.state.nodes[node_id]
KeyError: 'id2'
192.168.1.1 - - [05/Apr/2020 04:17:52] "[37mGET /balance HTTP/1.1[0m" 200 -
192.168.1.1 - - [05/Apr/2020 04:17:52] "[35m[1mPOST /new_transaction HTTP/1.1[0m" 500 -
Traceback (most recent call last):
  File "/home/user/.local/lib/python3.5/site-packages/flask/app.py", line 2464, in __call__
    return self.wsgi_app(environ, start_response)
  File "/home/user/.local/lib/python3.5/site-packages/flask/app.py", line 2450, in wsgi_app
    response = self.handle_exception(e)
  File "/home/user/.local/lib/python3.5/site-packages/flask/app.py", line 1867, in handle_exception
    reraise(exc_type, exc_value, tb)
  File "/home/user/.local/lib/python3.5/site-packages/flask/_compat.py", line 39, in reraise
    raise value
  File "/home/user/.local/lib/python3.5/site-packages/flask/app.py", line 2447, in wsgi_app
    response = self.full_dispatch_request()
  File "/home/user/.local/lib/python3.5/site-packages/flask/app.py", line 1952, in full_dispatch_request
    rv = self.handle_user_exception(e)
  File "/home/user/.local/lib/python3.5/site-packages/flask/app.py", line 1821, in handle_user_exception
    reraise(exc_type, exc_value, tb)
  File "/home/user/.local/lib/python3.5/site-packages/flask/_compat.py", line 39, in reraise
    raise value
  File "/home/user/.local/lib/python3.5/site-packages/flask/app.py", line 1950, in full_dispatch_request
    rv = self.dispatch_request()
  File "/home/user/.local/lib/python3.5/site-packages/flask/app.py", line 1936, in dispatch_request
    return self.view_functions[rule.endpoint](**req.view_args)
  File "/home/user/noobcash/noobcash/backend/broadcast.py", line 221, in cli_new_transaction
    node = State.state.nodes[node_id]
KeyError: 'id1'
192.168.1.1 - - [05/Apr/2020 04:17:52] "[37mGET /balance HTTP/1.1[0m" 200 -
192.168.1.1 - - [05/Apr/2020 04:17:52] "[35m[1mPOST /new_transaction HTTP/1.1[0m" 500 -
Traceback (most recent call last):
  File "/home/user/.local/lib/python3.5/site-packages/flask/app.py", line 2464, in __call__
    return self.wsgi_app(environ, start_response)
  File "/home/user/.local/lib/python3.5/site-packages/flask/app.py", line 2450, in wsgi_app
    response = self.handle_exception(e)
  File "/home/user/.local/lib/python3.5/site-packages/flask/app.py", line 1867, in handle_exception
    reraise(exc_type, exc_value, tb)
  File "/home/user/.local/lib/python3.5/site-packages/flask/_compat.py", line 39, in reraise
    raise value
  File "/home/user/.local/lib/python3.5/site-packages/flask/app.py", line 2447, in wsgi_app
    response = self.full_dispatch_request()
  File "/home/user/.local/lib/python3.5/site-packages/flask/app.py", line 1952, in full_dispatch_request
    rv = self.handle_user_exception(e)
  File "/home/user/.local/lib/python3.5/site-packages/flask/app.py", line 1821, in handle_user_exception
    reraise(exc_type, exc_value, tb)
  File "/home/user/.local/lib/python3.5/site-packages/flask/_compat.py", line 39, in reraise
    raise value
  File "/home/user/.local/lib/python3.5/site-packages/flask/app.py", line 1950, in full_dispatch_request
    rv = self.dispatch_request()
  File "/home/user/.local/lib/python3.5/site-packages/flask/app.py", line 1936, in dispatch_request
    return self.view_functions[rule.endpoint](**req.view_args)
  File "/home/user/noobcash/noobcash/backend/broadcast.py", line 221, in cli_new_transaction
    node = State.state.nodes[node_id]
KeyError: 'id3'
192.168.1.1 - - [05/Apr/2020 04:17:52] "[37mGET /balance HTTP/1.1[0m" 200 -
192.168.1.1 - - [05/Apr/2020 04:17:52] "[35m[1mPOST /new_transaction HTTP/1.1[0m" 500 -
Traceback (most recent call last):
  File "/home/user/.local/lib/python3.5/site-packages/flask/app.py", line 2464, in __call__
    return self.wsgi_app(environ, start_response)
  File "/home/user/.local/lib/python3.5/site-packages/flask/app.py", line 2450, in wsgi_app
    response = self.handle_exception(e)
  File "/home/user/.local/lib/python3.5/site-packages/flask/app.py", line 1867, in handle_exception
    reraise(exc_type, exc_value, tb)
  File "/home/user/.local/lib/python3.5/site-packages/flask/_compat.py", line 39, in reraise
    raise value
  File "/home/user/.local/lib/python3.5/site-packages/flask/app.py", line 2447, in wsgi_app
    response = self.full_dispatch_request()
  File "/home/user/.local/lib/python3.5/site-packages/flask/app.py", line 1952, in full_dispatch_request
    rv = self.handle_user_exception(e)
  File "/home/user/.local/lib/python3.5/site-packages/flask/app.py", line 1821, in handle_user_exception
    reraise(exc_type, exc_value, tb)
  File "/home/user/.local/lib/python3.5/site-packages/flask/_compat.py", line 39, in reraise
    raise value
  File "/home/user/.local/lib/python3.5/site-packages/flask/app.py", line 1950, in full_dispatch_request
    rv = self.dispatch_request()
  File "/home/user/.local/lib/python3.5/site-packages/flask/app.py", line 1936, in dispatch_request
    return self.view_functions[rule.endpoint](**req.view_args)
  File "/home/user/noobcash/noobcash/backend/broadcast.py", line 221, in cli_new_transaction
    node = State.state.nodes[node_id]
KeyError: 'id1'
192.168.1.1 - - [05/Apr/2020 04:17:52] "[37mGET /balance HTTP/1.1[0m" 200 -
192.168.1.1 - - [05/Apr/2020 04:17:52] "[35m[1mPOST /new_transaction HTTP/1.1[0m" 500 -
Traceback (most recent call last):
  File "/home/user/.local/lib/python3.5/site-packages/flask/app.py", line 2464, in __call__
    return self.wsgi_app(environ, start_response)
  File "/home/user/.local/lib/python3.5/site-packages/flask/app.py", line 2450, in wsgi_app
    response = self.handle_exception(e)
  File "/home/user/.local/lib/python3.5/site-packages/flask/app.py", line 1867, in handle_exception
    reraise(exc_type, exc_value, tb)
  File "/home/user/.local/lib/python3.5/site-packages/flask/_compat.py", line 39, in reraise
    raise value
  File "/home/user/.local/lib/python3.5/site-packages/flask/app.py", line 2447, in wsgi_app
    response = self.full_dispatch_request()
  File "/home/user/.local/lib/python3.5/site-packages/flask/app.py", line 1952, in full_dispatch_request
    rv = self.handle_user_exception(e)
  File "/home/user/.local/lib/python3.5/site-packages/flask/app.py", line 1821, in handle_user_exception
    reraise(exc_type, exc_value, tb)
  File "/home/user/.local/lib/python3.5/site-packages/flask/_compat.py", line 39, in reraise
    raise value
  File "/home/user/.local/lib/python3.5/site-packages/flask/app.py", line 1950, in full_dispatch_request
    rv = self.dispatch_request()
  File "/home/user/.local/lib/python3.5/site-packages/flask/app.py", line 1936, in dispatch_request
    return self.view_functions[rule.endpoint](**req.view_args)
  File "/home/user/noobcash/noobcash/backend/broadcast.py", line 221, in cli_new_transaction
    node = State.state.nodes[node_id]
KeyError: 'id4'
192.168.1.1 - - [05/Apr/2020 04:17:52] "[37mGET /balance HTTP/1.1[0m" 200 -
192.168.1.1 - - [05/Apr/2020 04:17:52] "[35m[1mPOST /new_transaction HTTP/1.1[0m" 500 -
Traceback (most recent call last):
  File "/home/user/.local/lib/python3.5/site-packages/flask/app.py", line 2464, in __call__
    return self.wsgi_app(environ, start_response)
  File "/home/user/.local/lib/python3.5/site-packages/flask/app.py", line 2450, in wsgi_app
    response = self.handle_exception(e)
  File "/home/user/.local/lib/python3.5/site-packages/flask/app.py", line 1867, in handle_exception
    reraise(exc_type, exc_value, tb)
  File "/home/user/.local/lib/python3.5/site-packages/flask/_compat.py", line 39, in reraise
    raise value
  File "/home/user/.local/lib/python3.5/site-packages/flask/app.py", line 2447, in wsgi_app
    response = self.full_dispatch_request()
  File "/home/user/.local/lib/python3.5/site-packages/flask/app.py", line 1952, in full_dispatch_request
    rv = self.handle_user_exception(e)
  File "/home/user/.local/lib/python3.5/site-packages/flask/app.py", line 1821, in handle_user_exception
    reraise(exc_type, exc_value, tb)
  File "/home/user/.local/lib/python3.5/site-packages/flask/_compat.py", line 39, in reraise
    raise value
  File "/home/user/.local/lib/python3.5/site-packages/flask/app.py", line 1950, in full_dispatch_request
    rv = self.dispatch_request()
  File "/home/user/.local/lib/python3.5/site-packages/flask/app.py", line 1936, in dispatch_request
    return self.view_functions[rule.endpoint](**req.view_args)
  File "/home/user/noobcash/noobcash/backend/broadcast.py", line 221, in cli_new_transaction
    node = State.state.nodes[node_id]
KeyError: 'id4'
192.168.1.1 - - [05/Apr/2020 04:17:52] "[37mGET /balance HTTP/1.1[0m" 200 -
192.168.1.1 - - [05/Apr/2020 04:17:52] "[35m[1mPOST /new_transaction HTTP/1.1[0m" 500 -
Traceback (most recent call last):
  File "/home/user/.local/lib/python3.5/site-packages/flask/app.py", line 2464, in __call__
    return self.wsgi_app(environ, start_response)
  File "/home/user/.local/lib/python3.5/site-packages/flask/app.py", line 2450, in wsgi_app
    response = self.handle_exception(e)
  File "/home/user/.local/lib/python3.5/site-packages/flask/app.py", line 1867, in handle_exception
    reraise(exc_type, exc_value, tb)
  File "/home/user/.local/lib/python3.5/site-packages/flask/_compat.py", line 39, in reraise
    raise value
  File "/home/user/.local/lib/python3.5/site-packages/flask/app.py", line 2447, in wsgi_app
    response = self.full_dispatch_request()
  File "/home/user/.local/lib/python3.5/site-packages/flask/app.py", line 1952, in full_dispatch_request
    rv = self.handle_user_exception(e)
  File "/home/user/.local/lib/python3.5/site-packages/flask/app.py", line 1821, in handle_user_exception
    reraise(exc_type, exc_value, tb)
  File "/home/user/.local/lib/python3.5/site-packages/flask/_compat.py", line 39, in reraise
    raise value
  File "/home/user/.local/lib/python3.5/site-packages/flask/app.py", line 1950, in full_dispatch_request
    rv = self.dispatch_request()
  File "/home/user/.local/lib/python3.5/site-packages/flask/app.py", line 1936, in dispatch_request
    return self.view_functions[rule.endpoint](**req.view_args)
  File "/home/user/noobcash/noobcash/backend/broadcast.py", line 221, in cli_new_transaction
    node = State.state.nodes[node_id]
KeyError: 'id3'
192.168.1.1 - - [05/Apr/2020 04:17:52] "[37mGET /balance HTTP/1.1[0m" 200 -
192.168.1.1 - - [05/Apr/2020 04:17:52] "[35m[1mPOST /new_transaction HTTP/1.1[0m" 500 -
Traceback (most recent call last):
  File "/home/user/.local/lib/python3.5/site-packages/flask/app.py", line 2464, in __call__
    return self.wsgi_app(environ, start_response)
  File "/home/user/.local/lib/python3.5/site-packages/flask/app.py", line 2450, in wsgi_app
    response = self.handle_exception(e)
  File "/home/user/.local/lib/python3.5/site-packages/flask/app.py", line 1867, in handle_exception
    reraise(exc_type, exc_value, tb)
  File "/home/user/.local/lib/python3.5/site-packages/flask/_compat.py", line 39, in reraise
    raise value
  File "/home/user/.local/lib/python3.5/site-packages/flask/app.py", line 2447, in wsgi_app
    response = self.full_dispatch_request()
  File "/home/user/.local/lib/python3.5/site-packages/flask/app.py", line 1952, in full_dispatch_request
    rv = self.handle_user_exception(e)
  File "/home/user/.local/lib/python3.5/site-packages/flask/app.py", line 1821, in handle_user_exception
    reraise(exc_type, exc_value, tb)
  File "/home/user/.local/lib/python3.5/site-packages/flask/_compat.py", line 39, in reraise
    raise value
  File "/home/user/.local/lib/python3.5/site-packages/flask/app.py", line 1950, in full_dispatch_request
    rv = self.dispatch_request()
  File "/home/user/.local/lib/python3.5/site-packages/flask/app.py", line 1936, in dispatch_request
    return self.view_functions[rule.endpoint](**req.view_args)
  File "/home/user/noobcash/noobcash/backend/broadcast.py", line 221, in cli_new_transaction
    node = State.state.nodes[node_id]
KeyError: 'id3'
192.168.1.1 - - [05/Apr/2020 04:17:52] "[37mGET /balance HTTP/1.1[0m" 200 -
192.168.1.1 - - [05/Apr/2020 04:17:52] "[35m[1mPOST /new_transaction HTTP/1.1[0m" 500 -
Traceback (most recent call last):
  File "/home/user/.local/lib/python3.5/site-packages/flask/app.py", line 2464, in __call__
    return self.wsgi_app(environ, start_response)
  File "/home/user/.local/lib/python3.5/site-packages/flask/app.py", line 2450, in wsgi_app
    response = self.handle_exception(e)
  File "/home/user/.local/lib/python3.5/site-packages/flask/app.py", line 1867, in handle_exception
    reraise(exc_type, exc_value, tb)
  File "/home/user/.local/lib/python3.5/site-packages/flask/_compat.py", line 39, in reraise
    raise value
  File "/home/user/.local/lib/python3.5/site-packages/flask/app.py", line 2447, in wsgi_app
    response = self.full_dispatch_request()
  File "/home/user/.local/lib/python3.5/site-packages/flask/app.py", line 1952, in full_dispatch_request
    rv = self.handle_user_exception(e)
  File "/home/user/.local/lib/python3.5/site-packages/flask/app.py", line 1821, in handle_user_exception
    reraise(exc_type, exc_value, tb)
  File "/home/user/.local/lib/python3.5/site-packages/flask/_compat.py", line 39, in reraise
    raise value
  File "/home/user/.local/lib/python3.5/site-packages/flask/app.py", line 1950, in full_dispatch_request
    rv = self.dispatch_request()
  File "/home/user/.local/lib/python3.5/site-packages/flask/app.py", line 1936, in dispatch_request
    return self.view_functions[rule.endpoint](**req.view_args)
  File "/home/user/noobcash/noobcash/backend/broadcast.py", line 221, in cli_new_transaction
    node = State.state.nodes[node_id]
KeyError: 'id4'
192.168.1.1 - - [05/Apr/2020 04:17:52] "[37mGET /balance HTTP/1.1[0m" 200 -
192.168.1.1 - - [05/Apr/2020 04:17:52] "[35m[1mPOST /new_transaction HTTP/1.1[0m" 500 -
Traceback (most recent call last):
  File "/home/user/.local/lib/python3.5/site-packages/flask/app.py", line 2464, in __call__
    return self.wsgi_app(environ, start_response)
  File "/home/user/.local/lib/python3.5/site-packages/flask/app.py", line 2450, in wsgi_app
    response = self.handle_exception(e)
  File "/home/user/.local/lib/python3.5/site-packages/flask/app.py", line 1867, in handle_exception
    reraise(exc_type, exc_value, tb)
  File "/home/user/.local/lib/python3.5/site-packages/flask/_compat.py", line 39, in reraise
    raise value
  File "/home/user/.local/lib/python3.5/site-packages/flask/app.py", line 2447, in wsgi_app
    response = self.full_dispatch_request()
  File "/home/user/.local/lib/python3.5/site-packages/flask/app.py", line 1952, in full_dispatch_request
    rv = self.handle_user_exception(e)
  File "/home/user/.local/lib/python3.5/site-packages/flask/app.py", line 1821, in handle_user_exception
    reraise(exc_type, exc_value, tb)
  File "/home/user/.local/lib/python3.5/site-packages/flask/_compat.py", line 39, in reraise
    raise value
  File "/home/user/.local/lib/python3.5/site-packages/flask/app.py", line 1950, in full_dispatch_request
    rv = self.dispatch_request()
  File "/home/user/.local/lib/python3.5/site-packages/flask/app.py", line 1936, in dispatch_request
    return self.view_functions[rule.endpoint](**req.view_args)
  File "/home/user/noobcash/noobcash/backend/broadcast.py", line 221, in cli_new_transaction
    node = State.state.nodes[node_id]
KeyError: 'id2'
192.168.1.1 - - [05/Apr/2020 04:17:52] "[37mGET /balance HTTP/1.1[0m" 200 -
192.168.1.1 - - [05/Apr/2020 04:17:52] "[35m[1mPOST /new_transaction HTTP/1.1[0m" 500 -
Traceback (most recent call last):
  File "/home/user/.local/lib/python3.5/site-packages/flask/app.py", line 2464, in __call__
    return self.wsgi_app(environ, start_response)
  File "/home/user/.local/lib/python3.5/site-packages/flask/app.py", line 2450, in wsgi_app
    response = self.handle_exception(e)
  File "/home/user/.local/lib/python3.5/site-packages/flask/app.py", line 1867, in handle_exception
    reraise(exc_type, exc_value, tb)
  File "/home/user/.local/lib/python3.5/site-packages/flask/_compat.py", line 39, in reraise
    raise value
  File "/home/user/.local/lib/python3.5/site-packages/flask/app.py", line 2447, in wsgi_app
    response = self.full_dispatch_request()
  File "/home/user/.local/lib/python3.5/site-packages/flask/app.py", line 1952, in full_dispatch_request
    rv = self.handle_user_exception(e)
  File "/home/user/.local/lib/python3.5/site-packages/flask/app.py", line 1821, in handle_user_exception
    reraise(exc_type, exc_value, tb)
  File "/home/user/.local/lib/python3.5/site-packages/flask/_compat.py", line 39, in reraise
    raise value
  File "/home/user/.local/lib/python3.5/site-packages/flask/app.py", line 1950, in full_dispatch_request
    rv = self.dispatch_request()
  File "/home/user/.local/lib/python3.5/site-packages/flask/app.py", line 1936, in dispatch_request
    return self.view_functions[rule.endpoint](**req.view_args)
  File "/home/user/noobcash/noobcash/backend/broadcast.py", line 221, in cli_new_transaction
    node = State.state.nodes[node_id]
KeyError: 'id1'
192.168.1.1 - - [05/Apr/2020 04:17:52] "[37mGET /balance HTTP/1.1[0m" 200 -
192.168.1.1 - - [05/Apr/2020 04:17:52] "[35m[1mPOST /new_transaction HTTP/1.1[0m" 500 -
Traceback (most recent call last):
  File "/home/user/.local/lib/python3.5/site-packages/flask/app.py", line 2464, in __call__
    return self.wsgi_app(environ, start_response)
  File "/home/user/.local/lib/python3.5/site-packages/flask/app.py", line 2450, in wsgi_app
    response = self.handle_exception(e)
  File "/home/user/.local/lib/python3.5/site-packages/flask/app.py", line 1867, in handle_exception
    reraise(exc_type, exc_value, tb)
  File "/home/user/.local/lib/python3.5/site-packages/flask/_compat.py", line 39, in reraise
    raise value
  File "/home/user/.local/lib/python3.5/site-packages/flask/app.py", line 2447, in wsgi_app
    response = self.full_dispatch_request()
  File "/home/user/.local/lib/python3.5/site-packages/flask/app.py", line 1952, in full_dispatch_request
    rv = self.handle_user_exception(e)
  File "/home/user/.local/lib/python3.5/site-packages/flask/app.py", line 1821, in handle_user_exception
    reraise(exc_type, exc_value, tb)
  File "/home/user/.local/lib/python3.5/site-packages/flask/_compat.py", line 39, in reraise
    raise value
  File "/home/user/.local/lib/python3.5/site-packages/flask/app.py", line 1950, in full_dispatch_request
    rv = self.dispatch_request()
  File "/home/user/.local/lib/python3.5/site-packages/flask/app.py", line 1936, in dispatch_request
    return self.view_functions[rule.endpoint](**req.view_args)
  File "/home/user/noobcash/noobcash/backend/broadcast.py", line 221, in cli_new_transaction
    node = State.state.nodes[node_id]
KeyError: 'id2'
192.168.1.1 - - [05/Apr/2020 04:17:52] "[37mGET /balance HTTP/1.1[0m" 200 -
192.168.1.1 - - [05/Apr/2020 04:17:52] "[35m[1mPOST /new_transaction HTTP/1.1[0m" 500 -
Traceback (most recent call last):
  File "/home/user/.local/lib/python3.5/site-packages/flask/app.py", line 2464, in __call__
    return self.wsgi_app(environ, start_response)
  File "/home/user/.local/lib/python3.5/site-packages/flask/app.py", line 2450, in wsgi_app
    response = self.handle_exception(e)
  File "/home/user/.local/lib/python3.5/site-packages/flask/app.py", line 1867, in handle_exception
    reraise(exc_type, exc_value, tb)
  File "/home/user/.local/lib/python3.5/site-packages/flask/_compat.py", line 39, in reraise
    raise value
  File "/home/user/.local/lib/python3.5/site-packages/flask/app.py", line 2447, in wsgi_app
    response = self.full_dispatch_request()
  File "/home/user/.local/lib/python3.5/site-packages/flask/app.py", line 1952, in full_dispatch_request
    rv = self.handle_user_exception(e)
  File "/home/user/.local/lib/python3.5/site-packages/flask/app.py", line 1821, in handle_user_exception
    reraise(exc_type, exc_value, tb)
  File "/home/user/.local/lib/python3.5/site-packages/flask/_compat.py", line 39, in reraise
    raise value
  File "/home/user/.local/lib/python3.5/site-packages/flask/app.py", line 1950, in full_dispatch_request
    rv = self.dispatch_request()
  File "/home/user/.local/lib/python3.5/site-packages/flask/app.py", line 1936, in dispatch_request
    return self.view_functions[rule.endpoint](**req.view_args)
  File "/home/user/noobcash/noobcash/backend/broadcast.py", line 221, in cli_new_transaction
    node = State.state.nodes[node_id]
KeyError: 'id4'
192.168.1.1 - - [05/Apr/2020 04:17:52] "[37mGET /balance HTTP/1.1[0m" 200 -
192.168.1.1 - - [05/Apr/2020 04:17:52] "[35m[1mPOST /new_transaction HTTP/1.1[0m" 500 -
Traceback (most recent call last):
  File "/home/user/.local/lib/python3.5/site-packages/flask/app.py", line 2464, in __call__
    return self.wsgi_app(environ, start_response)
  File "/home/user/.local/lib/python3.5/site-packages/flask/app.py", line 2450, in wsgi_app
    response = self.handle_exception(e)
  File "/home/user/.local/lib/python3.5/site-packages/flask/app.py", line 1867, in handle_exception
    reraise(exc_type, exc_value, tb)
  File "/home/user/.local/lib/python3.5/site-packages/flask/_compat.py", line 39, in reraise
    raise value
  File "/home/user/.local/lib/python3.5/site-packages/flask/app.py", line 2447, in wsgi_app
    response = self.full_dispatch_request()
  File "/home/user/.local/lib/python3.5/site-packages/flask/app.py", line 1952, in full_dispatch_request
    rv = self.handle_user_exception(e)
  File "/home/user/.local/lib/python3.5/site-packages/flask/app.py", line 1821, in handle_user_exception
    reraise(exc_type, exc_value, tb)
  File "/home/user/.local/lib/python3.5/site-packages/flask/_compat.py", line 39, in reraise
    raise value
  File "/home/user/.local/lib/python3.5/site-packages/flask/app.py", line 1950, in full_dispatch_request
    rv = self.dispatch_request()
  File "/home/user/.local/lib/python3.5/site-packages/flask/app.py", line 1936, in dispatch_request
    return self.view_functions[rule.endpoint](**req.view_args)
  File "/home/user/noobcash/noobcash/backend/broadcast.py", line 221, in cli_new_transaction
    node = State.state.nodes[node_id]
KeyError: 'id4'
192.168.1.1 - - [05/Apr/2020 04:17:52] "[37mGET /balance HTTP/1.1[0m" 200 -
192.168.1.1 - - [05/Apr/2020 04:17:52] "[35m[1mPOST /new_transaction HTTP/1.1[0m" 500 -
Traceback (most recent call last):
  File "/home/user/.local/lib/python3.5/site-packages/flask/app.py", line 2464, in __call__
    return self.wsgi_app(environ, start_response)
  File "/home/user/.local/lib/python3.5/site-packages/flask/app.py", line 2450, in wsgi_app
    response = self.handle_exception(e)
  File "/home/user/.local/lib/python3.5/site-packages/flask/app.py", line 1867, in handle_exception
    reraise(exc_type, exc_value, tb)
  File "/home/user/.local/lib/python3.5/site-packages/flask/_compat.py", line 39, in reraise
    raise value
  File "/home/user/.local/lib/python3.5/site-packages/flask/app.py", line 2447, in wsgi_app
    response = self.full_dispatch_request()
  File "/home/user/.local/lib/python3.5/site-packages/flask/app.py", line 1952, in full_dispatch_request
    rv = self.handle_user_exception(e)
  File "/home/user/.local/lib/python3.5/site-packages/flask/app.py", line 1821, in handle_user_exception
    reraise(exc_type, exc_value, tb)
  File "/home/user/.local/lib/python3.5/site-packages/flask/_compat.py", line 39, in reraise
    raise value
  File "/home/user/.local/lib/python3.5/site-packages/flask/app.py", line 1950, in full_dispatch_request
    rv = self.dispatch_request()
  File "/home/user/.local/lib/python3.5/site-packages/flask/app.py", line 1936, in dispatch_request
    return self.view_functions[rule.endpoint](**req.view_args)
  File "/home/user/noobcash/noobcash/backend/broadcast.py", line 221, in cli_new_transaction
    node = State.state.nodes[node_id]
KeyError: 'id4'
192.168.1.1 - - [05/Apr/2020 04:17:52] "[37mGET /balance HTTP/1.1[0m" 200 -
192.168.1.1 - - [05/Apr/2020 04:17:52] "[35m[1mPOST /new_transaction HTTP/1.1[0m" 500 -
Traceback (most recent call last):
  File "/home/user/.local/lib/python3.5/site-packages/flask/app.py", line 2464, in __call__
    return self.wsgi_app(environ, start_response)
  File "/home/user/.local/lib/python3.5/site-packages/flask/app.py", line 2450, in wsgi_app
    response = self.handle_exception(e)
  File "/home/user/.local/lib/python3.5/site-packages/flask/app.py", line 1867, in handle_exception
    reraise(exc_type, exc_value, tb)
  File "/home/user/.local/lib/python3.5/site-packages/flask/_compat.py", line 39, in reraise
    raise value
  File "/home/user/.local/lib/python3.5/site-packages/flask/app.py", line 2447, in wsgi_app
    response = self.full_dispatch_request()
  File "/home/user/.local/lib/python3.5/site-packages/flask/app.py", line 1952, in full_dispatch_request
    rv = self.handle_user_exception(e)
  File "/home/user/.local/lib/python3.5/site-packages/flask/app.py", line 1821, in handle_user_exception
    reraise(exc_type, exc_value, tb)
  File "/home/user/.local/lib/python3.5/site-packages/flask/_compat.py", line 39, in reraise
    raise value
  File "/home/user/.local/lib/python3.5/site-packages/flask/app.py", line 1950, in full_dispatch_request
    rv = self.dispatch_request()
  File "/home/user/.local/lib/python3.5/site-packages/flask/app.py", line 1936, in dispatch_request
    return self.view_functions[rule.endpoint](**req.view_args)
  File "/home/user/noobcash/noobcash/backend/broadcast.py", line 221, in cli_new_transaction
    node = State.state.nodes[node_id]
KeyError: 'id1'
192.168.1.1 - - [05/Apr/2020 04:17:52] "[37mGET /balance HTTP/1.1[0m" 200 -
192.168.1.1 - - [05/Apr/2020 04:17:52] "[35m[1mPOST /new_transaction HTTP/1.1[0m" 500 -
Traceback (most recent call last):
  File "/home/user/.local/lib/python3.5/site-packages/flask/app.py", line 2464, in __call__
    return self.wsgi_app(environ, start_response)
  File "/home/user/.local/lib/python3.5/site-packages/flask/app.py", line 2450, in wsgi_app
    response = self.handle_exception(e)
  File "/home/user/.local/lib/python3.5/site-packages/flask/app.py", line 1867, in handle_exception
    reraise(exc_type, exc_value, tb)
  File "/home/user/.local/lib/python3.5/site-packages/flask/_compat.py", line 39, in reraise
    raise value
  File "/home/user/.local/lib/python3.5/site-packages/flask/app.py", line 2447, in wsgi_app
    response = self.full_dispatch_request()
  File "/home/user/.local/lib/python3.5/site-packages/flask/app.py", line 1952, in full_dispatch_request
    rv = self.handle_user_exception(e)
  File "/home/user/.local/lib/python3.5/site-packages/flask/app.py", line 1821, in handle_user_exception
    reraise(exc_type, exc_value, tb)
  File "/home/user/.local/lib/python3.5/site-packages/flask/_compat.py", line 39, in reraise
    raise value
  File "/home/user/.local/lib/python3.5/site-packages/flask/app.py", line 1950, in full_dispatch_request
    rv = self.dispatch_request()
  File "/home/user/.local/lib/python3.5/site-packages/flask/app.py", line 1936, in dispatch_request
    return self.view_functions[rule.endpoint](**req.view_args)
  File "/home/user/noobcash/noobcash/backend/broadcast.py", line 221, in cli_new_transaction
    node = State.state.nodes[node_id]
KeyError: 'id4'
192.168.1.1 - - [05/Apr/2020 04:17:52] "[37mGET /balance HTTP/1.1[0m" 200 -
192.168.1.1 - - [05/Apr/2020 04:17:52] "[35m[1mPOST /new_transaction HTTP/1.1[0m" 500 -
Traceback (most recent call last):
  File "/home/user/.local/lib/python3.5/site-packages/flask/app.py", line 2464, in __call__
    return self.wsgi_app(environ, start_response)
  File "/home/user/.local/lib/python3.5/site-packages/flask/app.py", line 2450, in wsgi_app
    response = self.handle_exception(e)
  File "/home/user/.local/lib/python3.5/site-packages/flask/app.py", line 1867, in handle_exception
    reraise(exc_type, exc_value, tb)
  File "/home/user/.local/lib/python3.5/site-packages/flask/_compat.py", line 39, in reraise
    raise value
  File "/home/user/.local/lib/python3.5/site-packages/flask/app.py", line 2447, in wsgi_app
    response = self.full_dispatch_request()
  File "/home/user/.local/lib/python3.5/site-packages/flask/app.py", line 1952, in full_dispatch_request
    rv = self.handle_user_exception(e)
  File "/home/user/.local/lib/python3.5/site-packages/flask/app.py", line 1821, in handle_user_exception
    reraise(exc_type, exc_value, tb)
  File "/home/user/.local/lib/python3.5/site-packages/flask/_compat.py", line 39, in reraise
    raise value
  File "/home/user/.local/lib/python3.5/site-packages/flask/app.py", line 1950, in full_dispatch_request
    rv = self.dispatch_request()
  File "/home/user/.local/lib/python3.5/site-packages/flask/app.py", line 1936, in dispatch_request
    return self.view_functions[rule.endpoint](**req.view_args)
  File "/home/user/noobcash/noobcash/backend/broadcast.py", line 221, in cli_new_transaction
    node = State.state.nodes[node_id]
KeyError: 'id2'
192.168.1.1 - - [05/Apr/2020 04:17:52] "[37mGET /balance HTTP/1.1[0m" 200 -
192.168.1.1 - - [05/Apr/2020 04:17:52] "[35m[1mPOST /new_transaction HTTP/1.1[0m" 500 -
Traceback (most recent call last):
  File "/home/user/.local/lib/python3.5/site-packages/flask/app.py", line 2464, in __call__
    return self.wsgi_app(environ, start_response)
  File "/home/user/.local/lib/python3.5/site-packages/flask/app.py", line 2450, in wsgi_app
    response = self.handle_exception(e)
  File "/home/user/.local/lib/python3.5/site-packages/flask/app.py", line 1867, in handle_exception
    reraise(exc_type, exc_value, tb)
  File "/home/user/.local/lib/python3.5/site-packages/flask/_compat.py", line 39, in reraise
    raise value
  File "/home/user/.local/lib/python3.5/site-packages/flask/app.py", line 2447, in wsgi_app
    response = self.full_dispatch_request()
  File "/home/user/.local/lib/python3.5/site-packages/flask/app.py", line 1952, in full_dispatch_request
    rv = self.handle_user_exception(e)
  File "/home/user/.local/lib/python3.5/site-packages/flask/app.py", line 1821, in handle_user_exception
    reraise(exc_type, exc_value, tb)
  File "/home/user/.local/lib/python3.5/site-packages/flask/_compat.py", line 39, in reraise
    raise value
  File "/home/user/.local/lib/python3.5/site-packages/flask/app.py", line 1950, in full_dispatch_request
    rv = self.dispatch_request()
  File "/home/user/.local/lib/python3.5/site-packages/flask/app.py", line 1936, in dispatch_request
    return self.view_functions[rule.endpoint](**req.view_args)
  File "/home/user/noobcash/noobcash/backend/broadcast.py", line 221, in cli_new_transaction
    node = State.state.nodes[node_id]
KeyError: 'id3'
192.168.1.1 - - [05/Apr/2020 04:17:52] "[37mGET /balance HTTP/1.1[0m" 200 -
192.168.1.1 - - [05/Apr/2020 04:17:52] "[35m[1mPOST /new_transaction HTTP/1.1[0m" 500 -
Traceback (most recent call last):
  File "/home/user/.local/lib/python3.5/site-packages/flask/app.py", line 2464, in __call__
    return self.wsgi_app(environ, start_response)
  File "/home/user/.local/lib/python3.5/site-packages/flask/app.py", line 2450, in wsgi_app
    response = self.handle_exception(e)
  File "/home/user/.local/lib/python3.5/site-packages/flask/app.py", line 1867, in handle_exception
    reraise(exc_type, exc_value, tb)
  File "/home/user/.local/lib/python3.5/site-packages/flask/_compat.py", line 39, in reraise
    raise value
  File "/home/user/.local/lib/python3.5/site-packages/flask/app.py", line 2447, in wsgi_app
    response = self.full_dispatch_request()
  File "/home/user/.local/lib/python3.5/site-packages/flask/app.py", line 1952, in full_dispatch_request
    rv = self.handle_user_exception(e)
  File "/home/user/.local/lib/python3.5/site-packages/flask/app.py", line 1821, in handle_user_exception
    reraise(exc_type, exc_value, tb)
  File "/home/user/.local/lib/python3.5/site-packages/flask/_compat.py", line 39, in reraise
    raise value
  File "/home/user/.local/lib/python3.5/site-packages/flask/app.py", line 1950, in full_dispatch_request
    rv = self.dispatch_request()
  File "/home/user/.local/lib/python3.5/site-packages/flask/app.py", line 1936, in dispatch_request
    return self.view_functions[rule.endpoint](**req.view_args)
  File "/home/user/noobcash/noobcash/backend/broadcast.py", line 221, in cli_new_transaction
    node = State.state.nodes[node_id]
KeyError: 'id2'
192.168.1.1 - - [05/Apr/2020 04:17:52] "[37mGET /balance HTTP/1.1[0m" 200 -
192.168.1.1 - - [05/Apr/2020 04:17:52] "[35m[1mPOST /new_transaction HTTP/1.1[0m" 500 -
Traceback (most recent call last):
  File "/home/user/.local/lib/python3.5/site-packages/flask/app.py", line 2464, in __call__
    return self.wsgi_app(environ, start_response)
  File "/home/user/.local/lib/python3.5/site-packages/flask/app.py", line 2450, in wsgi_app
    response = self.handle_exception(e)
  File "/home/user/.local/lib/python3.5/site-packages/flask/app.py", line 1867, in handle_exception
    reraise(exc_type, exc_value, tb)
  File "/home/user/.local/lib/python3.5/site-packages/flask/_compat.py", line 39, in reraise
    raise value
  File "/home/user/.local/lib/python3.5/site-packages/flask/app.py", line 2447, in wsgi_app
    response = self.full_dispatch_request()
  File "/home/user/.local/lib/python3.5/site-packages/flask/app.py", line 1952, in full_dispatch_request
    rv = self.handle_user_exception(e)
  File "/home/user/.local/lib/python3.5/site-packages/flask/app.py", line 1821, in handle_user_exception
    reraise(exc_type, exc_value, tb)
  File "/home/user/.local/lib/python3.5/site-packages/flask/_compat.py", line 39, in reraise
    raise value
  File "/home/user/.local/lib/python3.5/site-packages/flask/app.py", line 1950, in full_dispatch_request
    rv = self.dispatch_request()
  File "/home/user/.local/lib/python3.5/site-packages/flask/app.py", line 1936, in dispatch_request
    return self.view_functions[rule.endpoint](**req.view_args)
  File "/home/user/noobcash/noobcash/backend/broadcast.py", line 221, in cli_new_transaction
    node = State.state.nodes[node_id]
KeyError: 'id4'
192.168.1.1 - - [05/Apr/2020 04:17:52] "[37mGET /balance HTTP/1.1[0m" 200 -
192.168.1.1 - - [05/Apr/2020 04:17:52] "[35m[1mPOST /new_transaction HTTP/1.1[0m" 500 -
Traceback (most recent call last):
  File "/home/user/.local/lib/python3.5/site-packages/flask/app.py", line 2464, in __call__
    return self.wsgi_app(environ, start_response)
  File "/home/user/.local/lib/python3.5/site-packages/flask/app.py", line 2450, in wsgi_app
    response = self.handle_exception(e)
  File "/home/user/.local/lib/python3.5/site-packages/flask/app.py", line 1867, in handle_exception
    reraise(exc_type, exc_value, tb)
  File "/home/user/.local/lib/python3.5/site-packages/flask/_compat.py", line 39, in reraise
    raise value
  File "/home/user/.local/lib/python3.5/site-packages/flask/app.py", line 2447, in wsgi_app
    response = self.full_dispatch_request()
  File "/home/user/.local/lib/python3.5/site-packages/flask/app.py", line 1952, in full_dispatch_request
    rv = self.handle_user_exception(e)
  File "/home/user/.local/lib/python3.5/site-packages/flask/app.py", line 1821, in handle_user_exception
    reraise(exc_type, exc_value, tb)
  File "/home/user/.local/lib/python3.5/site-packages/flask/_compat.py", line 39, in reraise
    raise value
  File "/home/user/.local/lib/python3.5/site-packages/flask/app.py", line 1950, in full_dispatch_request
    rv = self.dispatch_request()
  File "/home/user/.local/lib/python3.5/site-packages/flask/app.py", line 1936, in dispatch_request
    return self.view_functions[rule.endpoint](**req.view_args)
  File "/home/user/noobcash/noobcash/backend/broadcast.py", line 221, in cli_new_transaction
    node = State.state.nodes[node_id]
KeyError: 'id2'
192.168.1.1 - - [05/Apr/2020 04:17:52] "[37mGET /balance HTTP/1.1[0m" 200 -
192.168.1.1 - - [05/Apr/2020 04:17:52] "[35m[1mPOST /new_transaction HTTP/1.1[0m" 500 -
Traceback (most recent call last):
  File "/home/user/.local/lib/python3.5/site-packages/flask/app.py", line 2464, in __call__
    return self.wsgi_app(environ, start_response)
  File "/home/user/.local/lib/python3.5/site-packages/flask/app.py", line 2450, in wsgi_app
    response = self.handle_exception(e)
  File "/home/user/.local/lib/python3.5/site-packages/flask/app.py", line 1867, in handle_exception
    reraise(exc_type, exc_value, tb)
  File "/home/user/.local/lib/python3.5/site-packages/flask/_compat.py", line 39, in reraise
    raise value
  File "/home/user/.local/lib/python3.5/site-packages/flask/app.py", line 2447, in wsgi_app
    response = self.full_dispatch_request()
  File "/home/user/.local/lib/python3.5/site-packages/flask/app.py", line 1952, in full_dispatch_request
    rv = self.handle_user_exception(e)
  File "/home/user/.local/lib/python3.5/site-packages/flask/app.py", line 1821, in handle_user_exception
    reraise(exc_type, exc_value, tb)
  File "/home/user/.local/lib/python3.5/site-packages/flask/_compat.py", line 39, in reraise
    raise value
  File "/home/user/.local/lib/python3.5/site-packages/flask/app.py", line 1950, in full_dispatch_request
    rv = self.dispatch_request()
  File "/home/user/.local/lib/python3.5/site-packages/flask/app.py", line 1936, in dispatch_request
    return self.view_functions[rule.endpoint](**req.view_args)
  File "/home/user/noobcash/noobcash/backend/broadcast.py", line 221, in cli_new_transaction
    node = State.state.nodes[node_id]
KeyError: 'id3'
192.168.1.1 - - [05/Apr/2020 04:17:52] "[37mGET /balance HTTP/1.1[0m" 200 -
192.168.1.1 - - [05/Apr/2020 04:17:52] "[35m[1mPOST /new_transaction HTTP/1.1[0m" 500 -
Traceback (most recent call last):
  File "/home/user/.local/lib/python3.5/site-packages/flask/app.py", line 2464, in __call__
    return self.wsgi_app(environ, start_response)
  File "/home/user/.local/lib/python3.5/site-packages/flask/app.py", line 2450, in wsgi_app
    response = self.handle_exception(e)
  File "/home/user/.local/lib/python3.5/site-packages/flask/app.py", line 1867, in handle_exception
    reraise(exc_type, exc_value, tb)
  File "/home/user/.local/lib/python3.5/site-packages/flask/_compat.py", line 39, in reraise
    raise value
  File "/home/user/.local/lib/python3.5/site-packages/flask/app.py", line 2447, in wsgi_app
    response = self.full_dispatch_request()
  File "/home/user/.local/lib/python3.5/site-packages/flask/app.py", line 1952, in full_dispatch_request
    rv = self.handle_user_exception(e)
  File "/home/user/.local/lib/python3.5/site-packages/flask/app.py", line 1821, in handle_user_exception
    reraise(exc_type, exc_value, tb)
  File "/home/user/.local/lib/python3.5/site-packages/flask/_compat.py", line 39, in reraise
    raise value
  File "/home/user/.local/lib/python3.5/site-packages/flask/app.py", line 1950, in full_dispatch_request
    rv = self.dispatch_request()
  File "/home/user/.local/lib/python3.5/site-packages/flask/app.py", line 1936, in dispatch_request
    return self.view_functions[rule.endpoint](**req.view_args)
  File "/home/user/noobcash/noobcash/backend/broadcast.py", line 221, in cli_new_transaction
    node = State.state.nodes[node_id]
KeyError: 'id4'
192.168.1.1 - - [05/Apr/2020 04:17:52] "[37mGET /balance HTTP/1.1[0m" 200 -
192.168.1.1 - - [05/Apr/2020 04:17:52] "[35m[1mPOST /new_transaction HTTP/1.1[0m" 500 -
Traceback (most recent call last):
  File "/home/user/.local/lib/python3.5/site-packages/flask/app.py", line 2464, in __call__
    return self.wsgi_app(environ, start_response)
  File "/home/user/.local/lib/python3.5/site-packages/flask/app.py", line 2450, in wsgi_app
    response = self.handle_exception(e)
  File "/home/user/.local/lib/python3.5/site-packages/flask/app.py", line 1867, in handle_exception
    reraise(exc_type, exc_value, tb)
  File "/home/user/.local/lib/python3.5/site-packages/flask/_compat.py", line 39, in reraise
    raise value
  File "/home/user/.local/lib/python3.5/site-packages/flask/app.py", line 2447, in wsgi_app
    response = self.full_dispatch_request()
  File "/home/user/.local/lib/python3.5/site-packages/flask/app.py", line 1952, in full_dispatch_request
    rv = self.handle_user_exception(e)
  File "/home/user/.local/lib/python3.5/site-packages/flask/app.py", line 1821, in handle_user_exception
    reraise(exc_type, exc_value, tb)
  File "/home/user/.local/lib/python3.5/site-packages/flask/_compat.py", line 39, in reraise
    raise value
  File "/home/user/.local/lib/python3.5/site-packages/flask/app.py", line 1950, in full_dispatch_request
    rv = self.dispatch_request()
  File "/home/user/.local/lib/python3.5/site-packages/flask/app.py", line 1936, in dispatch_request
    return self.view_functions[rule.endpoint](**req.view_args)
  File "/home/user/noobcash/noobcash/backend/broadcast.py", line 221, in cli_new_transaction
    node = State.state.nodes[node_id]
KeyError: 'id4'
192.168.1.1 - - [05/Apr/2020 04:17:52] "[37mGET /balance HTTP/1.1[0m" 200 -
192.168.1.1 - - [05/Apr/2020 04:17:53] "[35m[1mPOST /new_transaction HTTP/1.1[0m" 500 -
Traceback (most recent call last):
  File "/home/user/.local/lib/python3.5/site-packages/flask/app.py", line 2464, in __call__
    return self.wsgi_app(environ, start_response)
  File "/home/user/.local/lib/python3.5/site-packages/flask/app.py", line 2450, in wsgi_app
    response = self.handle_exception(e)
  File "/home/user/.local/lib/python3.5/site-packages/flask/app.py", line 1867, in handle_exception
    reraise(exc_type, exc_value, tb)
  File "/home/user/.local/lib/python3.5/site-packages/flask/_compat.py", line 39, in reraise
    raise value
  File "/home/user/.local/lib/python3.5/site-packages/flask/app.py", line 2447, in wsgi_app
    response = self.full_dispatch_request()
  File "/home/user/.local/lib/python3.5/site-packages/flask/app.py", line 1952, in full_dispatch_request
    rv = self.handle_user_exception(e)
  File "/home/user/.local/lib/python3.5/site-packages/flask/app.py", line 1821, in handle_user_exception
    reraise(exc_type, exc_value, tb)
  File "/home/user/.local/lib/python3.5/site-packages/flask/_compat.py", line 39, in reraise
    raise value
  File "/home/user/.local/lib/python3.5/site-packages/flask/app.py", line 1950, in full_dispatch_request
    rv = self.dispatch_request()
  File "/home/user/.local/lib/python3.5/site-packages/flask/app.py", line 1936, in dispatch_request
    return self.view_functions[rule.endpoint](**req.view_args)
  File "/home/user/noobcash/noobcash/backend/broadcast.py", line 221, in cli_new_transaction
    node = State.state.nodes[node_id]
KeyError: 'id3'
192.168.1.1 - - [05/Apr/2020 04:17:53] "[37mGET /balance HTTP/1.1[0m" 200 -
192.168.1.1 - - [05/Apr/2020 04:17:53] "[35m[1mPOST /new_transaction HTTP/1.1[0m" 500 -
Traceback (most recent call last):
  File "/home/user/.local/lib/python3.5/site-packages/flask/app.py", line 2464, in __call__
    return self.wsgi_app(environ, start_response)
  File "/home/user/.local/lib/python3.5/site-packages/flask/app.py", line 2450, in wsgi_app
    response = self.handle_exception(e)
  File "/home/user/.local/lib/python3.5/site-packages/flask/app.py", line 1867, in handle_exception
    reraise(exc_type, exc_value, tb)
  File "/home/user/.local/lib/python3.5/site-packages/flask/_compat.py", line 39, in reraise
    raise value
  File "/home/user/.local/lib/python3.5/site-packages/flask/app.py", line 2447, in wsgi_app
    response = self.full_dispatch_request()
  File "/home/user/.local/lib/python3.5/site-packages/flask/app.py", line 1952, in full_dispatch_request
    rv = self.handle_user_exception(e)
  File "/home/user/.local/lib/python3.5/site-packages/flask/app.py", line 1821, in handle_user_exception
    reraise(exc_type, exc_value, tb)
  File "/home/user/.local/lib/python3.5/site-packages/flask/_compat.py", line 39, in reraise
    raise value
  File "/home/user/.local/lib/python3.5/site-packages/flask/app.py", line 1950, in full_dispatch_request
    rv = self.dispatch_request()
  File "/home/user/.local/lib/python3.5/site-packages/flask/app.py", line 1936, in dispatch_request
    return self.view_functions[rule.endpoint](**req.view_args)
  File "/home/user/noobcash/noobcash/backend/broadcast.py", line 221, in cli_new_transaction
    node = State.state.nodes[node_id]
KeyError: 'id2'
192.168.1.1 - - [05/Apr/2020 04:17:53] "[37mGET /balance HTTP/1.1[0m" 200 -
192.168.1.1 - - [05/Apr/2020 04:17:53] "[35m[1mPOST /new_transaction HTTP/1.1[0m" 500 -
Traceback (most recent call last):
  File "/home/user/.local/lib/python3.5/site-packages/flask/app.py", line 2464, in __call__
    return self.wsgi_app(environ, start_response)
  File "/home/user/.local/lib/python3.5/site-packages/flask/app.py", line 2450, in wsgi_app
    response = self.handle_exception(e)
  File "/home/user/.local/lib/python3.5/site-packages/flask/app.py", line 1867, in handle_exception
    reraise(exc_type, exc_value, tb)
  File "/home/user/.local/lib/python3.5/site-packages/flask/_compat.py", line 39, in reraise
    raise value
  File "/home/user/.local/lib/python3.5/site-packages/flask/app.py", line 2447, in wsgi_app
    response = self.full_dispatch_request()
  File "/home/user/.local/lib/python3.5/site-packages/flask/app.py", line 1952, in full_dispatch_request
    rv = self.handle_user_exception(e)
  File "/home/user/.local/lib/python3.5/site-packages/flask/app.py", line 1821, in handle_user_exception
    reraise(exc_type, exc_value, tb)
  File "/home/user/.local/lib/python3.5/site-packages/flask/_compat.py", line 39, in reraise
    raise value
  File "/home/user/.local/lib/python3.5/site-packages/flask/app.py", line 1950, in full_dispatch_request
    rv = self.dispatch_request()
  File "/home/user/.local/lib/python3.5/site-packages/flask/app.py", line 1936, in dispatch_request
    return self.view_functions[rule.endpoint](**req.view_args)
  File "/home/user/noobcash/noobcash/backend/broadcast.py", line 221, in cli_new_transaction
    node = State.state.nodes[node_id]
KeyError: 'id4'
192.168.1.1 - - [05/Apr/2020 04:17:53] "[37mGET /balance HTTP/1.1[0m" 200 -
192.168.1.1 - - [05/Apr/2020 04:17:53] "[35m[1mPOST /new_transaction HTTP/1.1[0m" 500 -
Traceback (most recent call last):
  File "/home/user/.local/lib/python3.5/site-packages/flask/app.py", line 2464, in __call__
    return self.wsgi_app(environ, start_response)
  File "/home/user/.local/lib/python3.5/site-packages/flask/app.py", line 2450, in wsgi_app
    response = self.handle_exception(e)
  File "/home/user/.local/lib/python3.5/site-packages/flask/app.py", line 1867, in handle_exception
    reraise(exc_type, exc_value, tb)
  File "/home/user/.local/lib/python3.5/site-packages/flask/_compat.py", line 39, in reraise
    raise value
  File "/home/user/.local/lib/python3.5/site-packages/flask/app.py", line 2447, in wsgi_app
    response = self.full_dispatch_request()
  File "/home/user/.local/lib/python3.5/site-packages/flask/app.py", line 1952, in full_dispatch_request
    rv = self.handle_user_exception(e)
  File "/home/user/.local/lib/python3.5/site-packages/flask/app.py", line 1821, in handle_user_exception
    reraise(exc_type, exc_value, tb)
  File "/home/user/.local/lib/python3.5/site-packages/flask/_compat.py", line 39, in reraise
    raise value
  File "/home/user/.local/lib/python3.5/site-packages/flask/app.py", line 1950, in full_dispatch_request
    rv = self.dispatch_request()
  File "/home/user/.local/lib/python3.5/site-packages/flask/app.py", line 1936, in dispatch_request
    return self.view_functions[rule.endpoint](**req.view_args)
  File "/home/user/noobcash/noobcash/backend/broadcast.py", line 221, in cli_new_transaction
    node = State.state.nodes[node_id]
KeyError: 'id3'
192.168.1.1 - - [05/Apr/2020 04:17:53] "[37mGET /balance HTTP/1.1[0m" 200 -
192.168.1.1 - - [05/Apr/2020 04:17:53] "[35m[1mPOST /new_transaction HTTP/1.1[0m" 500 -
Traceback (most recent call last):
  File "/home/user/.local/lib/python3.5/site-packages/flask/app.py", line 2464, in __call__
    return self.wsgi_app(environ, start_response)
  File "/home/user/.local/lib/python3.5/site-packages/flask/app.py", line 2450, in wsgi_app
    response = self.handle_exception(e)
  File "/home/user/.local/lib/python3.5/site-packages/flask/app.py", line 1867, in handle_exception
    reraise(exc_type, exc_value, tb)
  File "/home/user/.local/lib/python3.5/site-packages/flask/_compat.py", line 39, in reraise
    raise value
  File "/home/user/.local/lib/python3.5/site-packages/flask/app.py", line 2447, in wsgi_app
    response = self.full_dispatch_request()
  File "/home/user/.local/lib/python3.5/site-packages/flask/app.py", line 1952, in full_dispatch_request
    rv = self.handle_user_exception(e)
  File "/home/user/.local/lib/python3.5/site-packages/flask/app.py", line 1821, in handle_user_exception
    reraise(exc_type, exc_value, tb)
  File "/home/user/.local/lib/python3.5/site-packages/flask/_compat.py", line 39, in reraise
    raise value
  File "/home/user/.local/lib/python3.5/site-packages/flask/app.py", line 1950, in full_dispatch_request
    rv = self.dispatch_request()
  File "/home/user/.local/lib/python3.5/site-packages/flask/app.py", line 1936, in dispatch_request
    return self.view_functions[rule.endpoint](**req.view_args)
  File "/home/user/noobcash/noobcash/backend/broadcast.py", line 221, in cli_new_transaction
    node = State.state.nodes[node_id]
KeyError: 'id2'
192.168.1.1 - - [05/Apr/2020 04:17:53] "[37mGET /balance HTTP/1.1[0m" 200 -
192.168.1.1 - - [05/Apr/2020 04:17:53] "[35m[1mPOST /new_transaction HTTP/1.1[0m" 500 -
Traceback (most recent call last):
  File "/home/user/.local/lib/python3.5/site-packages/flask/app.py", line 2464, in __call__
    return self.wsgi_app(environ, start_response)
  File "/home/user/.local/lib/python3.5/site-packages/flask/app.py", line 2450, in wsgi_app
    response = self.handle_exception(e)
  File "/home/user/.local/lib/python3.5/site-packages/flask/app.py", line 1867, in handle_exception
    reraise(exc_type, exc_value, tb)
  File "/home/user/.local/lib/python3.5/site-packages/flask/_compat.py", line 39, in reraise
    raise value
  File "/home/user/.local/lib/python3.5/site-packages/flask/app.py", line 2447, in wsgi_app
    response = self.full_dispatch_request()
  File "/home/user/.local/lib/python3.5/site-packages/flask/app.py", line 1952, in full_dispatch_request
    rv = self.handle_user_exception(e)
  File "/home/user/.local/lib/python3.5/site-packages/flask/app.py", line 1821, in handle_user_exception
    reraise(exc_type, exc_value, tb)
  File "/home/user/.local/lib/python3.5/site-packages/flask/_compat.py", line 39, in reraise
    raise value
  File "/home/user/.local/lib/python3.5/site-packages/flask/app.py", line 1950, in full_dispatch_request
    rv = self.dispatch_request()
  File "/home/user/.local/lib/python3.5/site-packages/flask/app.py", line 1936, in dispatch_request
    return self.view_functions[rule.endpoint](**req.view_args)
  File "/home/user/noobcash/noobcash/backend/broadcast.py", line 221, in cli_new_transaction
    node = State.state.nodes[node_id]
KeyError: 'id2'
192.168.1.1 - - [05/Apr/2020 04:17:53] "[37mGET /balance HTTP/1.1[0m" 200 -
192.168.1.1 - - [05/Apr/2020 04:17:53] "[35m[1mPOST /new_transaction HTTP/1.1[0m" 500 -
Traceback (most recent call last):
  File "/home/user/.local/lib/python3.5/site-packages/flask/app.py", line 2464, in __call__
    return self.wsgi_app(environ, start_response)
  File "/home/user/.local/lib/python3.5/site-packages/flask/app.py", line 2450, in wsgi_app
    response = self.handle_exception(e)
  File "/home/user/.local/lib/python3.5/site-packages/flask/app.py", line 1867, in handle_exception
    reraise(exc_type, exc_value, tb)
  File "/home/user/.local/lib/python3.5/site-packages/flask/_compat.py", line 39, in reraise
    raise value
  File "/home/user/.local/lib/python3.5/site-packages/flask/app.py", line 2447, in wsgi_app
    response = self.full_dispatch_request()
  File "/home/user/.local/lib/python3.5/site-packages/flask/app.py", line 1952, in full_dispatch_request
    rv = self.handle_user_exception(e)
  File "/home/user/.local/lib/python3.5/site-packages/flask/app.py", line 1821, in handle_user_exception
    reraise(exc_type, exc_value, tb)
  File "/home/user/.local/lib/python3.5/site-packages/flask/_compat.py", line 39, in reraise
    raise value
  File "/home/user/.local/lib/python3.5/site-packages/flask/app.py", line 1950, in full_dispatch_request
    rv = self.dispatch_request()
  File "/home/user/.local/lib/python3.5/site-packages/flask/app.py", line 1936, in dispatch_request
    return self.view_functions[rule.endpoint](**req.view_args)
  File "/home/user/noobcash/noobcash/backend/broadcast.py", line 221, in cli_new_transaction
    node = State.state.nodes[node_id]
KeyError: 'id2'
192.168.1.1 - - [05/Apr/2020 04:17:53] "[37mGET /balance HTTP/1.1[0m" 200 -
192.168.1.1 - - [05/Apr/2020 04:17:53] "[35m[1mPOST /new_transaction HTTP/1.1[0m" 500 -
Traceback (most recent call last):
  File "/home/user/.local/lib/python3.5/site-packages/flask/app.py", line 2464, in __call__
    return self.wsgi_app(environ, start_response)
  File "/home/user/.local/lib/python3.5/site-packages/flask/app.py", line 2450, in wsgi_app
    response = self.handle_exception(e)
  File "/home/user/.local/lib/python3.5/site-packages/flask/app.py", line 1867, in handle_exception
    reraise(exc_type, exc_value, tb)
  File "/home/user/.local/lib/python3.5/site-packages/flask/_compat.py", line 39, in reraise
    raise value
  File "/home/user/.local/lib/python3.5/site-packages/flask/app.py", line 2447, in wsgi_app
    response = self.full_dispatch_request()
  File "/home/user/.local/lib/python3.5/site-packages/flask/app.py", line 1952, in full_dispatch_request
    rv = self.handle_user_exception(e)
  File "/home/user/.local/lib/python3.5/site-packages/flask/app.py", line 1821, in handle_user_exception
    reraise(exc_type, exc_value, tb)
  File "/home/user/.local/lib/python3.5/site-packages/flask/_compat.py", line 39, in reraise
    raise value
  File "/home/user/.local/lib/python3.5/site-packages/flask/app.py", line 1950, in full_dispatch_request
    rv = self.dispatch_request()
  File "/home/user/.local/lib/python3.5/site-packages/flask/app.py", line 1936, in dispatch_request
    return self.view_functions[rule.endpoint](**req.view_args)
  File "/home/user/noobcash/noobcash/backend/broadcast.py", line 221, in cli_new_transaction
    node = State.state.nodes[node_id]
KeyError: 'id3'
192.168.1.1 - - [05/Apr/2020 04:17:53] "[37mGET /balance HTTP/1.1[0m" 200 -
192.168.1.1 - - [05/Apr/2020 04:17:53] "[35m[1mPOST /new_transaction HTTP/1.1[0m" 500 -
Traceback (most recent call last):
  File "/home/user/.local/lib/python3.5/site-packages/flask/app.py", line 2464, in __call__
    return self.wsgi_app(environ, start_response)
  File "/home/user/.local/lib/python3.5/site-packages/flask/app.py", line 2450, in wsgi_app
    response = self.handle_exception(e)
  File "/home/user/.local/lib/python3.5/site-packages/flask/app.py", line 1867, in handle_exception
    reraise(exc_type, exc_value, tb)
  File "/home/user/.local/lib/python3.5/site-packages/flask/_compat.py", line 39, in reraise
    raise value
  File "/home/user/.local/lib/python3.5/site-packages/flask/app.py", line 2447, in wsgi_app
    response = self.full_dispatch_request()
  File "/home/user/.local/lib/python3.5/site-packages/flask/app.py", line 1952, in full_dispatch_request
    rv = self.handle_user_exception(e)
  File "/home/user/.local/lib/python3.5/site-packages/flask/app.py", line 1821, in handle_user_exception
    reraise(exc_type, exc_value, tb)
  File "/home/user/.local/lib/python3.5/site-packages/flask/_compat.py", line 39, in reraise
    raise value
  File "/home/user/.local/lib/python3.5/site-packages/flask/app.py", line 1950, in full_dispatch_request
    rv = self.dispatch_request()
  File "/home/user/.local/lib/python3.5/site-packages/flask/app.py", line 1936, in dispatch_request
    return self.view_functions[rule.endpoint](**req.view_args)
  File "/home/user/noobcash/noobcash/backend/broadcast.py", line 221, in cli_new_transaction
    node = State.state.nodes[node_id]
KeyError: 'id3'
192.168.1.1 - - [05/Apr/2020 04:17:53] "[37mGET /balance HTTP/1.1[0m" 200 -
192.168.1.1 - - [05/Apr/2020 04:17:53] "[35m[1mPOST /new_transaction HTTP/1.1[0m" 500 -
Traceback (most recent call last):
  File "/home/user/.local/lib/python3.5/site-packages/flask/app.py", line 2464, in __call__
    return self.wsgi_app(environ, start_response)
  File "/home/user/.local/lib/python3.5/site-packages/flask/app.py", line 2450, in wsgi_app
    response = self.handle_exception(e)
  File "/home/user/.local/lib/python3.5/site-packages/flask/app.py", line 1867, in handle_exception
    reraise(exc_type, exc_value, tb)
  File "/home/user/.local/lib/python3.5/site-packages/flask/_compat.py", line 39, in reraise
    raise value
  File "/home/user/.local/lib/python3.5/site-packages/flask/app.py", line 2447, in wsgi_app
    response = self.full_dispatch_request()
  File "/home/user/.local/lib/python3.5/site-packages/flask/app.py", line 1952, in full_dispatch_request
    rv = self.handle_user_exception(e)
  File "/home/user/.local/lib/python3.5/site-packages/flask/app.py", line 1821, in handle_user_exception
    reraise(exc_type, exc_value, tb)
  File "/home/user/.local/lib/python3.5/site-packages/flask/_compat.py", line 39, in reraise
    raise value
  File "/home/user/.local/lib/python3.5/site-packages/flask/app.py", line 1950, in full_dispatch_request
    rv = self.dispatch_request()
  File "/home/user/.local/lib/python3.5/site-packages/flask/app.py", line 1936, in dispatch_request
    return self.view_functions[rule.endpoint](**req.view_args)
  File "/home/user/noobcash/noobcash/backend/broadcast.py", line 221, in cli_new_transaction
    node = State.state.nodes[node_id]
KeyError: 'id1'
192.168.1.1 - - [05/Apr/2020 04:17:53] "[37mGET /balance HTTP/1.1[0m" 200 -
192.168.1.1 - - [05/Apr/2020 04:17:53] "[35m[1mPOST /new_transaction HTTP/1.1[0m" 500 -
Traceback (most recent call last):
  File "/home/user/.local/lib/python3.5/site-packages/flask/app.py", line 2464, in __call__
    return self.wsgi_app(environ, start_response)
  File "/home/user/.local/lib/python3.5/site-packages/flask/app.py", line 2450, in wsgi_app
    response = self.handle_exception(e)
  File "/home/user/.local/lib/python3.5/site-packages/flask/app.py", line 1867, in handle_exception
    reraise(exc_type, exc_value, tb)
  File "/home/user/.local/lib/python3.5/site-packages/flask/_compat.py", line 39, in reraise
    raise value
  File "/home/user/.local/lib/python3.5/site-packages/flask/app.py", line 2447, in wsgi_app
    response = self.full_dispatch_request()
  File "/home/user/.local/lib/python3.5/site-packages/flask/app.py", line 1952, in full_dispatch_request
    rv = self.handle_user_exception(e)
  File "/home/user/.local/lib/python3.5/site-packages/flask/app.py", line 1821, in handle_user_exception
    reraise(exc_type, exc_value, tb)
  File "/home/user/.local/lib/python3.5/site-packages/flask/_compat.py", line 39, in reraise
    raise value
  File "/home/user/.local/lib/python3.5/site-packages/flask/app.py", line 1950, in full_dispatch_request
    rv = self.dispatch_request()
  File "/home/user/.local/lib/python3.5/site-packages/flask/app.py", line 1936, in dispatch_request
    return self.view_functions[rule.endpoint](**req.view_args)
  File "/home/user/noobcash/noobcash/backend/broadcast.py", line 221, in cli_new_transaction
    node = State.state.nodes[node_id]
KeyError: 'id2'
192.168.1.1 - - [05/Apr/2020 04:17:53] "[37mGET /balance HTTP/1.1[0m" 200 -
192.168.1.1 - - [05/Apr/2020 04:17:53] "[35m[1mPOST /new_transaction HTTP/1.1[0m" 500 -
Traceback (most recent call last):
  File "/home/user/.local/lib/python3.5/site-packages/flask/app.py", line 2464, in __call__
    return self.wsgi_app(environ, start_response)
  File "/home/user/.local/lib/python3.5/site-packages/flask/app.py", line 2450, in wsgi_app
    response = self.handle_exception(e)
  File "/home/user/.local/lib/python3.5/site-packages/flask/app.py", line 1867, in handle_exception
    reraise(exc_type, exc_value, tb)
  File "/home/user/.local/lib/python3.5/site-packages/flask/_compat.py", line 39, in reraise
    raise value
  File "/home/user/.local/lib/python3.5/site-packages/flask/app.py", line 2447, in wsgi_app
    response = self.full_dispatch_request()
  File "/home/user/.local/lib/python3.5/site-packages/flask/app.py", line 1952, in full_dispatch_request
    rv = self.handle_user_exception(e)
  File "/home/user/.local/lib/python3.5/site-packages/flask/app.py", line 1821, in handle_user_exception
    reraise(exc_type, exc_value, tb)
  File "/home/user/.local/lib/python3.5/site-packages/flask/_compat.py", line 39, in reraise
    raise value
  File "/home/user/.local/lib/python3.5/site-packages/flask/app.py", line 1950, in full_dispatch_request
    rv = self.dispatch_request()
  File "/home/user/.local/lib/python3.5/site-packages/flask/app.py", line 1936, in dispatch_request
    return self.view_functions[rule.endpoint](**req.view_args)
  File "/home/user/noobcash/noobcash/backend/broadcast.py", line 221, in cli_new_transaction
    node = State.state.nodes[node_id]
KeyError: 'id3'
192.168.1.1 - - [05/Apr/2020 04:17:53] "[37mGET /balance HTTP/1.1[0m" 200 -
192.168.1.1 - - [05/Apr/2020 04:17:53] "[35m[1mPOST /new_transaction HTTP/1.1[0m" 500 -
Traceback (most recent call last):
  File "/home/user/.local/lib/python3.5/site-packages/flask/app.py", line 2464, in __call__
    return self.wsgi_app(environ, start_response)
  File "/home/user/.local/lib/python3.5/site-packages/flask/app.py", line 2450, in wsgi_app
    response = self.handle_exception(e)
  File "/home/user/.local/lib/python3.5/site-packages/flask/app.py", line 1867, in handle_exception
    reraise(exc_type, exc_value, tb)
  File "/home/user/.local/lib/python3.5/site-packages/flask/_compat.py", line 39, in reraise
    raise value
  File "/home/user/.local/lib/python3.5/site-packages/flask/app.py", line 2447, in wsgi_app
    response = self.full_dispatch_request()
  File "/home/user/.local/lib/python3.5/site-packages/flask/app.py", line 1952, in full_dispatch_request
    rv = self.handle_user_exception(e)
  File "/home/user/.local/lib/python3.5/site-packages/flask/app.py", line 1821, in handle_user_exception
    reraise(exc_type, exc_value, tb)
  File "/home/user/.local/lib/python3.5/site-packages/flask/_compat.py", line 39, in reraise
    raise value
  File "/home/user/.local/lib/python3.5/site-packages/flask/app.py", line 1950, in full_dispatch_request
    rv = self.dispatch_request()
  File "/home/user/.local/lib/python3.5/site-packages/flask/app.py", line 1936, in dispatch_request
    return self.view_functions[rule.endpoint](**req.view_args)
  File "/home/user/noobcash/noobcash/backend/broadcast.py", line 221, in cli_new_transaction
    node = State.state.nodes[node_id]
KeyError: 'id2'
192.168.1.1 - - [05/Apr/2020 04:17:53] "[37mGET /balance HTTP/1.1[0m" 200 -
192.168.1.1 - - [05/Apr/2020 04:17:53] "[35m[1mPOST /new_transaction HTTP/1.1[0m" 500 -
Traceback (most recent call last):
  File "/home/user/.local/lib/python3.5/site-packages/flask/app.py", line 2464, in __call__
    return self.wsgi_app(environ, start_response)
  File "/home/user/.local/lib/python3.5/site-packages/flask/app.py", line 2450, in wsgi_app
    response = self.handle_exception(e)
  File "/home/user/.local/lib/python3.5/site-packages/flask/app.py", line 1867, in handle_exception
    reraise(exc_type, exc_value, tb)
  File "/home/user/.local/lib/python3.5/site-packages/flask/_compat.py", line 39, in reraise
    raise value
  File "/home/user/.local/lib/python3.5/site-packages/flask/app.py", line 2447, in wsgi_app
    response = self.full_dispatch_request()
  File "/home/user/.local/lib/python3.5/site-packages/flask/app.py", line 1952, in full_dispatch_request
    rv = self.handle_user_exception(e)
  File "/home/user/.local/lib/python3.5/site-packages/flask/app.py", line 1821, in handle_user_exception
    reraise(exc_type, exc_value, tb)
  File "/home/user/.local/lib/python3.5/site-packages/flask/_compat.py", line 39, in reraise
    raise value
  File "/home/user/.local/lib/python3.5/site-packages/flask/app.py", line 1950, in full_dispatch_request
    rv = self.dispatch_request()
  File "/home/user/.local/lib/python3.5/site-packages/flask/app.py", line 1936, in dispatch_request
    return self.view_functions[rule.endpoint](**req.view_args)
  File "/home/user/noobcash/noobcash/backend/broadcast.py", line 221, in cli_new_transaction
    node = State.state.nodes[node_id]
KeyError: 'id2'
192.168.1.1 - - [05/Apr/2020 04:17:53] "[37mGET /balance HTTP/1.1[0m" 200 -
192.168.1.1 - - [05/Apr/2020 04:17:53] "[35m[1mPOST /new_transaction HTTP/1.1[0m" 500 -
Traceback (most recent call last):
  File "/home/user/.local/lib/python3.5/site-packages/flask/app.py", line 2464, in __call__
    return self.wsgi_app(environ, start_response)
  File "/home/user/.local/lib/python3.5/site-packages/flask/app.py", line 2450, in wsgi_app
    response = self.handle_exception(e)
  File "/home/user/.local/lib/python3.5/site-packages/flask/app.py", line 1867, in handle_exception
    reraise(exc_type, exc_value, tb)
  File "/home/user/.local/lib/python3.5/site-packages/flask/_compat.py", line 39, in reraise
    raise value
  File "/home/user/.local/lib/python3.5/site-packages/flask/app.py", line 2447, in wsgi_app
    response = self.full_dispatch_request()
  File "/home/user/.local/lib/python3.5/site-packages/flask/app.py", line 1952, in full_dispatch_request
    rv = self.handle_user_exception(e)
  File "/home/user/.local/lib/python3.5/site-packages/flask/app.py", line 1821, in handle_user_exception
    reraise(exc_type, exc_value, tb)
  File "/home/user/.local/lib/python3.5/site-packages/flask/_compat.py", line 39, in reraise
    raise value
  File "/home/user/.local/lib/python3.5/site-packages/flask/app.py", line 1950, in full_dispatch_request
    rv = self.dispatch_request()
  File "/home/user/.local/lib/python3.5/site-packages/flask/app.py", line 1936, in dispatch_request
    return self.view_functions[rule.endpoint](**req.view_args)
  File "/home/user/noobcash/noobcash/backend/broadcast.py", line 221, in cli_new_transaction
    node = State.state.nodes[node_id]
KeyError: 'id1'
192.168.1.1 - - [05/Apr/2020 04:17:53] "[37mGET /balance HTTP/1.1[0m" 200 -
192.168.1.1 - - [05/Apr/2020 04:17:53] "[35m[1mPOST /new_transaction HTTP/1.1[0m" 500 -
Traceback (most recent call last):
  File "/home/user/.local/lib/python3.5/site-packages/flask/app.py", line 2464, in __call__
    return self.wsgi_app(environ, start_response)
  File "/home/user/.local/lib/python3.5/site-packages/flask/app.py", line 2450, in wsgi_app
    response = self.handle_exception(e)
  File "/home/user/.local/lib/python3.5/site-packages/flask/app.py", line 1867, in handle_exception
    reraise(exc_type, exc_value, tb)
  File "/home/user/.local/lib/python3.5/site-packages/flask/_compat.py", line 39, in reraise
    raise value
  File "/home/user/.local/lib/python3.5/site-packages/flask/app.py", line 2447, in wsgi_app
    response = self.full_dispatch_request()
  File "/home/user/.local/lib/python3.5/site-packages/flask/app.py", line 1952, in full_dispatch_request
    rv = self.handle_user_exception(e)
  File "/home/user/.local/lib/python3.5/site-packages/flask/app.py", line 1821, in handle_user_exception
    reraise(exc_type, exc_value, tb)
  File "/home/user/.local/lib/python3.5/site-packages/flask/_compat.py", line 39, in reraise
    raise value
  File "/home/user/.local/lib/python3.5/site-packages/flask/app.py", line 1950, in full_dispatch_request
    rv = self.dispatch_request()
  File "/home/user/.local/lib/python3.5/site-packages/flask/app.py", line 1936, in dispatch_request
    return self.view_functions[rule.endpoint](**req.view_args)
  File "/home/user/noobcash/noobcash/backend/broadcast.py", line 221, in cli_new_transaction
    node = State.state.nodes[node_id]
KeyError: 'id1'
192.168.1.1 - - [05/Apr/2020 04:17:53] "[37mGET /balance HTTP/1.1[0m" 200 -
192.168.1.1 - - [05/Apr/2020 04:17:53] "[35m[1mPOST /new_transaction HTTP/1.1[0m" 500 -
Traceback (most recent call last):
  File "/home/user/.local/lib/python3.5/site-packages/flask/app.py", line 2464, in __call__
    return self.wsgi_app(environ, start_response)
  File "/home/user/.local/lib/python3.5/site-packages/flask/app.py", line 2450, in wsgi_app
    response = self.handle_exception(e)
  File "/home/user/.local/lib/python3.5/site-packages/flask/app.py", line 1867, in handle_exception
    reraise(exc_type, exc_value, tb)
  File "/home/user/.local/lib/python3.5/site-packages/flask/_compat.py", line 39, in reraise
    raise value
  File "/home/user/.local/lib/python3.5/site-packages/flask/app.py", line 2447, in wsgi_app
    response = self.full_dispatch_request()
  File "/home/user/.local/lib/python3.5/site-packages/flask/app.py", line 1952, in full_dispatch_request
    rv = self.handle_user_exception(e)
  File "/home/user/.local/lib/python3.5/site-packages/flask/app.py", line 1821, in handle_user_exception
    reraise(exc_type, exc_value, tb)
  File "/home/user/.local/lib/python3.5/site-packages/flask/_compat.py", line 39, in reraise
    raise value
  File "/home/user/.local/lib/python3.5/site-packages/flask/app.py", line 1950, in full_dispatch_request
    rv = self.dispatch_request()
  File "/home/user/.local/lib/python3.5/site-packages/flask/app.py", line 1936, in dispatch_request
    return self.view_functions[rule.endpoint](**req.view_args)
  File "/home/user/noobcash/noobcash/backend/broadcast.py", line 221, in cli_new_transaction
    node = State.state.nodes[node_id]
KeyError: 'id3'
192.168.1.1 - - [05/Apr/2020 04:17:53] "[37mGET /balance HTTP/1.1[0m" 200 -
192.168.1.1 - - [05/Apr/2020 04:17:53] "[35m[1mPOST /new_transaction HTTP/1.1[0m" 500 -
Traceback (most recent call last):
  File "/home/user/.local/lib/python3.5/site-packages/flask/app.py", line 2464, in __call__
    return self.wsgi_app(environ, start_response)
  File "/home/user/.local/lib/python3.5/site-packages/flask/app.py", line 2450, in wsgi_app
    response = self.handle_exception(e)
  File "/home/user/.local/lib/python3.5/site-packages/flask/app.py", line 1867, in handle_exception
    reraise(exc_type, exc_value, tb)
  File "/home/user/.local/lib/python3.5/site-packages/flask/_compat.py", line 39, in reraise
    raise value
  File "/home/user/.local/lib/python3.5/site-packages/flask/app.py", line 2447, in wsgi_app
    response = self.full_dispatch_request()
  File "/home/user/.local/lib/python3.5/site-packages/flask/app.py", line 1952, in full_dispatch_request
    rv = self.handle_user_exception(e)
  File "/home/user/.local/lib/python3.5/site-packages/flask/app.py", line 1821, in handle_user_exception
    reraise(exc_type, exc_value, tb)
  File "/home/user/.local/lib/python3.5/site-packages/flask/_compat.py", line 39, in reraise
    raise value
  File "/home/user/.local/lib/python3.5/site-packages/flask/app.py", line 1950, in full_dispatch_request
    rv = self.dispatch_request()
  File "/home/user/.local/lib/python3.5/site-packages/flask/app.py", line 1936, in dispatch_request
    return self.view_functions[rule.endpoint](**req.view_args)
  File "/home/user/noobcash/noobcash/backend/broadcast.py", line 221, in cli_new_transaction
    node = State.state.nodes[node_id]
KeyError: 'id4'
192.168.1.1 - - [05/Apr/2020 04:17:53] "[37mGET /balance HTTP/1.1[0m" 200 -
192.168.1.1 - - [05/Apr/2020 04:17:53] "[35m[1mPOST /new_transaction HTTP/1.1[0m" 500 -
Traceback (most recent call last):
  File "/home/user/.local/lib/python3.5/site-packages/flask/app.py", line 2464, in __call__
    return self.wsgi_app(environ, start_response)
  File "/home/user/.local/lib/python3.5/site-packages/flask/app.py", line 2450, in wsgi_app
    response = self.handle_exception(e)
  File "/home/user/.local/lib/python3.5/site-packages/flask/app.py", line 1867, in handle_exception
    reraise(exc_type, exc_value, tb)
  File "/home/user/.local/lib/python3.5/site-packages/flask/_compat.py", line 39, in reraise
    raise value
  File "/home/user/.local/lib/python3.5/site-packages/flask/app.py", line 2447, in wsgi_app
    response = self.full_dispatch_request()
  File "/home/user/.local/lib/python3.5/site-packages/flask/app.py", line 1952, in full_dispatch_request
    rv = self.handle_user_exception(e)
  File "/home/user/.local/lib/python3.5/site-packages/flask/app.py", line 1821, in handle_user_exception
    reraise(exc_type, exc_value, tb)
  File "/home/user/.local/lib/python3.5/site-packages/flask/_compat.py", line 39, in reraise
    raise value
  File "/home/user/.local/lib/python3.5/site-packages/flask/app.py", line 1950, in full_dispatch_request
    rv = self.dispatch_request()
  File "/home/user/.local/lib/python3.5/site-packages/flask/app.py", line 1936, in dispatch_request
    return self.view_functions[rule.endpoint](**req.view_args)
  File "/home/user/noobcash/noobcash/backend/broadcast.py", line 221, in cli_new_transaction
    node = State.state.nodes[node_id]
KeyError: 'id3'
192.168.1.1 - - [05/Apr/2020 04:17:53] "[37mGET /balance HTTP/1.1[0m" 200 -
192.168.1.1 - - [05/Apr/2020 04:17:53] "[35m[1mPOST /new_transaction HTTP/1.1[0m" 500 -
Traceback (most recent call last):
  File "/home/user/.local/lib/python3.5/site-packages/flask/app.py", line 2464, in __call__
    return self.wsgi_app(environ, start_response)
  File "/home/user/.local/lib/python3.5/site-packages/flask/app.py", line 2450, in wsgi_app
    response = self.handle_exception(e)
  File "/home/user/.local/lib/python3.5/site-packages/flask/app.py", line 1867, in handle_exception
    reraise(exc_type, exc_value, tb)
  File "/home/user/.local/lib/python3.5/site-packages/flask/_compat.py", line 39, in reraise
    raise value
  File "/home/user/.local/lib/python3.5/site-packages/flask/app.py", line 2447, in wsgi_app
    response = self.full_dispatch_request()
  File "/home/user/.local/lib/python3.5/site-packages/flask/app.py", line 1952, in full_dispatch_request
    rv = self.handle_user_exception(e)
  File "/home/user/.local/lib/python3.5/site-packages/flask/app.py", line 1821, in handle_user_exception
    reraise(exc_type, exc_value, tb)
  File "/home/user/.local/lib/python3.5/site-packages/flask/_compat.py", line 39, in reraise
    raise value
  File "/home/user/.local/lib/python3.5/site-packages/flask/app.py", line 1950, in full_dispatch_request
    rv = self.dispatch_request()
  File "/home/user/.local/lib/python3.5/site-packages/flask/app.py", line 1936, in dispatch_request
    return self.view_functions[rule.endpoint](**req.view_args)
  File "/home/user/noobcash/noobcash/backend/broadcast.py", line 221, in cli_new_transaction
    node = State.state.nodes[node_id]
KeyError: 'id1'
192.168.1.1 - - [05/Apr/2020 04:17:53] "[37mGET /balance HTTP/1.1[0m" 200 -
192.168.1.1 - - [05/Apr/2020 04:17:53] "[35m[1mPOST /new_transaction HTTP/1.1[0m" 500 -
Traceback (most recent call last):
  File "/home/user/.local/lib/python3.5/site-packages/flask/app.py", line 2464, in __call__
    return self.wsgi_app(environ, start_response)
  File "/home/user/.local/lib/python3.5/site-packages/flask/app.py", line 2450, in wsgi_app
    response = self.handle_exception(e)
  File "/home/user/.local/lib/python3.5/site-packages/flask/app.py", line 1867, in handle_exception
    reraise(exc_type, exc_value, tb)
  File "/home/user/.local/lib/python3.5/site-packages/flask/_compat.py", line 39, in reraise
    raise value
  File "/home/user/.local/lib/python3.5/site-packages/flask/app.py", line 2447, in wsgi_app
    response = self.full_dispatch_request()
  File "/home/user/.local/lib/python3.5/site-packages/flask/app.py", line 1952, in full_dispatch_request
    rv = self.handle_user_exception(e)
  File "/home/user/.local/lib/python3.5/site-packages/flask/app.py", line 1821, in handle_user_exception
    reraise(exc_type, exc_value, tb)
  File "/home/user/.local/lib/python3.5/site-packages/flask/_compat.py", line 39, in reraise
    raise value
  File "/home/user/.local/lib/python3.5/site-packages/flask/app.py", line 1950, in full_dispatch_request
    rv = self.dispatch_request()
  File "/home/user/.local/lib/python3.5/site-packages/flask/app.py", line 1936, in dispatch_request
    return self.view_functions[rule.endpoint](**req.view_args)
  File "/home/user/noobcash/noobcash/backend/broadcast.py", line 221, in cli_new_transaction
    node = State.state.nodes[node_id]
KeyError: 'id1'
192.168.1.1 - - [05/Apr/2020 04:17:53] "[37mGET /balance HTTP/1.1[0m" 200 -
192.168.1.1 - - [05/Apr/2020 04:17:53] "[35m[1mPOST /new_transaction HTTP/1.1[0m" 500 -
Traceback (most recent call last):
  File "/home/user/.local/lib/python3.5/site-packages/flask/app.py", line 2464, in __call__
    return self.wsgi_app(environ, start_response)
  File "/home/user/.local/lib/python3.5/site-packages/flask/app.py", line 2450, in wsgi_app
    response = self.handle_exception(e)
  File "/home/user/.local/lib/python3.5/site-packages/flask/app.py", line 1867, in handle_exception
    reraise(exc_type, exc_value, tb)
  File "/home/user/.local/lib/python3.5/site-packages/flask/_compat.py", line 39, in reraise
    raise value
  File "/home/user/.local/lib/python3.5/site-packages/flask/app.py", line 2447, in wsgi_app
    response = self.full_dispatch_request()
  File "/home/user/.local/lib/python3.5/site-packages/flask/app.py", line 1952, in full_dispatch_request
    rv = self.handle_user_exception(e)
  File "/home/user/.local/lib/python3.5/site-packages/flask/app.py", line 1821, in handle_user_exception
    reraise(exc_type, exc_value, tb)
  File "/home/user/.local/lib/python3.5/site-packages/flask/_compat.py", line 39, in reraise
    raise value
  File "/home/user/.local/lib/python3.5/site-packages/flask/app.py", line 1950, in full_dispatch_request
    rv = self.dispatch_request()
  File "/home/user/.local/lib/python3.5/site-packages/flask/app.py", line 1936, in dispatch_request
    return self.view_functions[rule.endpoint](**req.view_args)
  File "/home/user/noobcash/noobcash/backend/broadcast.py", line 221, in cli_new_transaction
    node = State.state.nodes[node_id]
KeyError: 'id1'
192.168.1.1 - - [05/Apr/2020 04:17:53] "[37mGET /balance HTTP/1.1[0m" 200 -
192.168.1.1 - - [05/Apr/2020 04:17:53] "[35m[1mPOST /new_transaction HTTP/1.1[0m" 500 -
Traceback (most recent call last):
  File "/home/user/.local/lib/python3.5/site-packages/flask/app.py", line 2464, in __call__
    return self.wsgi_app(environ, start_response)
  File "/home/user/.local/lib/python3.5/site-packages/flask/app.py", line 2450, in wsgi_app
    response = self.handle_exception(e)
  File "/home/user/.local/lib/python3.5/site-packages/flask/app.py", line 1867, in handle_exception
    reraise(exc_type, exc_value, tb)
  File "/home/user/.local/lib/python3.5/site-packages/flask/_compat.py", line 39, in reraise
    raise value
  File "/home/user/.local/lib/python3.5/site-packages/flask/app.py", line 2447, in wsgi_app
    response = self.full_dispatch_request()
  File "/home/user/.local/lib/python3.5/site-packages/flask/app.py", line 1952, in full_dispatch_request
    rv = self.handle_user_exception(e)
  File "/home/user/.local/lib/python3.5/site-packages/flask/app.py", line 1821, in handle_user_exception
    reraise(exc_type, exc_value, tb)
  File "/home/user/.local/lib/python3.5/site-packages/flask/_compat.py", line 39, in reraise
    raise value
  File "/home/user/.local/lib/python3.5/site-packages/flask/app.py", line 1950, in full_dispatch_request
    rv = self.dispatch_request()
  File "/home/user/.local/lib/python3.5/site-packages/flask/app.py", line 1936, in dispatch_request
    return self.view_functions[rule.endpoint](**req.view_args)
  File "/home/user/noobcash/noobcash/backend/broadcast.py", line 221, in cli_new_transaction
    node = State.state.nodes[node_id]
KeyError: 'id4'
192.168.1.1 - - [05/Apr/2020 04:17:53] "[37mGET /balance HTTP/1.1[0m" 200 -
192.168.1.1 - - [05/Apr/2020 04:17:53] "[35m[1mPOST /new_transaction HTTP/1.1[0m" 500 -
Traceback (most recent call last):
  File "/home/user/.local/lib/python3.5/site-packages/flask/app.py", line 2464, in __call__
    return self.wsgi_app(environ, start_response)
  File "/home/user/.local/lib/python3.5/site-packages/flask/app.py", line 2450, in wsgi_app
    response = self.handle_exception(e)
  File "/home/user/.local/lib/python3.5/site-packages/flask/app.py", line 1867, in handle_exception
    reraise(exc_type, exc_value, tb)
  File "/home/user/.local/lib/python3.5/site-packages/flask/_compat.py", line 39, in reraise
    raise value
  File "/home/user/.local/lib/python3.5/site-packages/flask/app.py", line 2447, in wsgi_app
    response = self.full_dispatch_request()
  File "/home/user/.local/lib/python3.5/site-packages/flask/app.py", line 1952, in full_dispatch_request
    rv = self.handle_user_exception(e)
  File "/home/user/.local/lib/python3.5/site-packages/flask/app.py", line 1821, in handle_user_exception
    reraise(exc_type, exc_value, tb)
  File "/home/user/.local/lib/python3.5/site-packages/flask/_compat.py", line 39, in reraise
    raise value
  File "/home/user/.local/lib/python3.5/site-packages/flask/app.py", line 1950, in full_dispatch_request
    rv = self.dispatch_request()
  File "/home/user/.local/lib/python3.5/site-packages/flask/app.py", line 1936, in dispatch_request
    return self.view_functions[rule.endpoint](**req.view_args)
  File "/home/user/noobcash/noobcash/backend/broadcast.py", line 221, in cli_new_transaction
    node = State.state.nodes[node_id]
KeyError: 'id4'
192.168.1.1 - - [05/Apr/2020 04:17:53] "[37mGET /balance HTTP/1.1[0m" 200 -
192.168.1.1 - - [05/Apr/2020 04:17:53] "[35m[1mPOST /new_transaction HTTP/1.1[0m" 500 -
Traceback (most recent call last):
  File "/home/user/.local/lib/python3.5/site-packages/flask/app.py", line 2464, in __call__
    return self.wsgi_app(environ, start_response)
  File "/home/user/.local/lib/python3.5/site-packages/flask/app.py", line 2450, in wsgi_app
    response = self.handle_exception(e)
  File "/home/user/.local/lib/python3.5/site-packages/flask/app.py", line 1867, in handle_exception
    reraise(exc_type, exc_value, tb)
  File "/home/user/.local/lib/python3.5/site-packages/flask/_compat.py", line 39, in reraise
    raise value
  File "/home/user/.local/lib/python3.5/site-packages/flask/app.py", line 2447, in wsgi_app
    response = self.full_dispatch_request()
  File "/home/user/.local/lib/python3.5/site-packages/flask/app.py", line 1952, in full_dispatch_request
    rv = self.handle_user_exception(e)
  File "/home/user/.local/lib/python3.5/site-packages/flask/app.py", line 1821, in handle_user_exception
    reraise(exc_type, exc_value, tb)
  File "/home/user/.local/lib/python3.5/site-packages/flask/_compat.py", line 39, in reraise
    raise value
  File "/home/user/.local/lib/python3.5/site-packages/flask/app.py", line 1950, in full_dispatch_request
    rv = self.dispatch_request()
  File "/home/user/.local/lib/python3.5/site-packages/flask/app.py", line 1936, in dispatch_request
    return self.view_functions[rule.endpoint](**req.view_args)
  File "/home/user/noobcash/noobcash/backend/broadcast.py", line 221, in cli_new_transaction
    node = State.state.nodes[node_id]
KeyError: 'id2'
192.168.1.1 - - [05/Apr/2020 04:17:53] "[37mGET /balance HTTP/1.1[0m" 200 -
192.168.1.1 - - [05/Apr/2020 04:17:53] "[35m[1mPOST /new_transaction HTTP/1.1[0m" 500 -
Traceback (most recent call last):
  File "/home/user/.local/lib/python3.5/site-packages/flask/app.py", line 2464, in __call__
    return self.wsgi_app(environ, start_response)
  File "/home/user/.local/lib/python3.5/site-packages/flask/app.py", line 2450, in wsgi_app
    response = self.handle_exception(e)
  File "/home/user/.local/lib/python3.5/site-packages/flask/app.py", line 1867, in handle_exception
    reraise(exc_type, exc_value, tb)
  File "/home/user/.local/lib/python3.5/site-packages/flask/_compat.py", line 39, in reraise
    raise value
  File "/home/user/.local/lib/python3.5/site-packages/flask/app.py", line 2447, in wsgi_app
    response = self.full_dispatch_request()
  File "/home/user/.local/lib/python3.5/site-packages/flask/app.py", line 1952, in full_dispatch_request
    rv = self.handle_user_exception(e)
  File "/home/user/.local/lib/python3.5/site-packages/flask/app.py", line 1821, in handle_user_exception
    reraise(exc_type, exc_value, tb)
  File "/home/user/.local/lib/python3.5/site-packages/flask/_compat.py", line 39, in reraise
    raise value
  File "/home/user/.local/lib/python3.5/site-packages/flask/app.py", line 1950, in full_dispatch_request
    rv = self.dispatch_request()
  File "/home/user/.local/lib/python3.5/site-packages/flask/app.py", line 1936, in dispatch_request
    return self.view_functions[rule.endpoint](**req.view_args)
  File "/home/user/noobcash/noobcash/backend/broadcast.py", line 221, in cli_new_transaction
    node = State.state.nodes[node_id]
KeyError: 'id1'
192.168.1.1 - - [05/Apr/2020 04:17:53] "[37mGET /balance HTTP/1.1[0m" 200 -
192.168.1.1 - - [05/Apr/2020 04:17:53] "[35m[1mPOST /new_transaction HTTP/1.1[0m" 500 -
Traceback (most recent call last):
  File "/home/user/.local/lib/python3.5/site-packages/flask/app.py", line 2464, in __call__
    return self.wsgi_app(environ, start_response)
  File "/home/user/.local/lib/python3.5/site-packages/flask/app.py", line 2450, in wsgi_app
    response = self.handle_exception(e)
  File "/home/user/.local/lib/python3.5/site-packages/flask/app.py", line 1867, in handle_exception
    reraise(exc_type, exc_value, tb)
  File "/home/user/.local/lib/python3.5/site-packages/flask/_compat.py", line 39, in reraise
    raise value
  File "/home/user/.local/lib/python3.5/site-packages/flask/app.py", line 2447, in wsgi_app
    response = self.full_dispatch_request()
  File "/home/user/.local/lib/python3.5/site-packages/flask/app.py", line 1952, in full_dispatch_request
    rv = self.handle_user_exception(e)
  File "/home/user/.local/lib/python3.5/site-packages/flask/app.py", line 1821, in handle_user_exception
    reraise(exc_type, exc_value, tb)
  File "/home/user/.local/lib/python3.5/site-packages/flask/_compat.py", line 39, in reraise
    raise value
  File "/home/user/.local/lib/python3.5/site-packages/flask/app.py", line 1950, in full_dispatch_request
    rv = self.dispatch_request()
  File "/home/user/.local/lib/python3.5/site-packages/flask/app.py", line 1936, in dispatch_request
    return self.view_functions[rule.endpoint](**req.view_args)
  File "/home/user/noobcash/noobcash/backend/broadcast.py", line 221, in cli_new_transaction
    node = State.state.nodes[node_id]
KeyError: 'id1'
192.168.1.1 - - [05/Apr/2020 04:17:53] "[37mGET /balance HTTP/1.1[0m" 200 -
192.168.1.1 - - [05/Apr/2020 04:17:53] "[35m[1mPOST /new_transaction HTTP/1.1[0m" 500 -
Traceback (most recent call last):
  File "/home/user/.local/lib/python3.5/site-packages/flask/app.py", line 2464, in __call__
    return self.wsgi_app(environ, start_response)
  File "/home/user/.local/lib/python3.5/site-packages/flask/app.py", line 2450, in wsgi_app
    response = self.handle_exception(e)
  File "/home/user/.local/lib/python3.5/site-packages/flask/app.py", line 1867, in handle_exception
    reraise(exc_type, exc_value, tb)
  File "/home/user/.local/lib/python3.5/site-packages/flask/_compat.py", line 39, in reraise
    raise value
  File "/home/user/.local/lib/python3.5/site-packages/flask/app.py", line 2447, in wsgi_app
    response = self.full_dispatch_request()
  File "/home/user/.local/lib/python3.5/site-packages/flask/app.py", line 1952, in full_dispatch_request
    rv = self.handle_user_exception(e)
  File "/home/user/.local/lib/python3.5/site-packages/flask/app.py", line 1821, in handle_user_exception
    reraise(exc_type, exc_value, tb)
  File "/home/user/.local/lib/python3.5/site-packages/flask/_compat.py", line 39, in reraise
    raise value
  File "/home/user/.local/lib/python3.5/site-packages/flask/app.py", line 1950, in full_dispatch_request
    rv = self.dispatch_request()
  File "/home/user/.local/lib/python3.5/site-packages/flask/app.py", line 1936, in dispatch_request
    return self.view_functions[rule.endpoint](**req.view_args)
  File "/home/user/noobcash/noobcash/backend/broadcast.py", line 221, in cli_new_transaction
    node = State.state.nodes[node_id]
KeyError: 'id3'
192.168.1.1 - - [05/Apr/2020 04:17:53] "[37mGET /balance HTTP/1.1[0m" 200 -
192.168.1.1 - - [05/Apr/2020 04:17:53] "[35m[1mPOST /new_transaction HTTP/1.1[0m" 500 -
Traceback (most recent call last):
  File "/home/user/.local/lib/python3.5/site-packages/flask/app.py", line 2464, in __call__
    return self.wsgi_app(environ, start_response)
  File "/home/user/.local/lib/python3.5/site-packages/flask/app.py", line 2450, in wsgi_app
    response = self.handle_exception(e)
  File "/home/user/.local/lib/python3.5/site-packages/flask/app.py", line 1867, in handle_exception
    reraise(exc_type, exc_value, tb)
  File "/home/user/.local/lib/python3.5/site-packages/flask/_compat.py", line 39, in reraise
    raise value
  File "/home/user/.local/lib/python3.5/site-packages/flask/app.py", line 2447, in wsgi_app
    response = self.full_dispatch_request()
  File "/home/user/.local/lib/python3.5/site-packages/flask/app.py", line 1952, in full_dispatch_request
    rv = self.handle_user_exception(e)
  File "/home/user/.local/lib/python3.5/site-packages/flask/app.py", line 1821, in handle_user_exception
    reraise(exc_type, exc_value, tb)
  File "/home/user/.local/lib/python3.5/site-packages/flask/_compat.py", line 39, in reraise
    raise value
  File "/home/user/.local/lib/python3.5/site-packages/flask/app.py", line 1950, in full_dispatch_request
    rv = self.dispatch_request()
  File "/home/user/.local/lib/python3.5/site-packages/flask/app.py", line 1936, in dispatch_request
    return self.view_functions[rule.endpoint](**req.view_args)
  File "/home/user/noobcash/noobcash/backend/broadcast.py", line 221, in cli_new_transaction
    node = State.state.nodes[node_id]
KeyError: 'id1'
192.168.1.1 - - [05/Apr/2020 04:17:53] "[37mGET /balance HTTP/1.1[0m" 200 -
192.168.1.1 - - [05/Apr/2020 04:17:53] "[35m[1mPOST /new_transaction HTTP/1.1[0m" 500 -
Traceback (most recent call last):
  File "/home/user/.local/lib/python3.5/site-packages/flask/app.py", line 2464, in __call__
    return self.wsgi_app(environ, start_response)
  File "/home/user/.local/lib/python3.5/site-packages/flask/app.py", line 2450, in wsgi_app
    response = self.handle_exception(e)
  File "/home/user/.local/lib/python3.5/site-packages/flask/app.py", line 1867, in handle_exception
    reraise(exc_type, exc_value, tb)
  File "/home/user/.local/lib/python3.5/site-packages/flask/_compat.py", line 39, in reraise
    raise value
  File "/home/user/.local/lib/python3.5/site-packages/flask/app.py", line 2447, in wsgi_app
    response = self.full_dispatch_request()
  File "/home/user/.local/lib/python3.5/site-packages/flask/app.py", line 1952, in full_dispatch_request
    rv = self.handle_user_exception(e)
  File "/home/user/.local/lib/python3.5/site-packages/flask/app.py", line 1821, in handle_user_exception
    reraise(exc_type, exc_value, tb)
  File "/home/user/.local/lib/python3.5/site-packages/flask/_compat.py", line 39, in reraise
    raise value
  File "/home/user/.local/lib/python3.5/site-packages/flask/app.py", line 1950, in full_dispatch_request
    rv = self.dispatch_request()
  File "/home/user/.local/lib/python3.5/site-packages/flask/app.py", line 1936, in dispatch_request
    return self.view_functions[rule.endpoint](**req.view_args)
  File "/home/user/noobcash/noobcash/backend/broadcast.py", line 221, in cli_new_transaction
    node = State.state.nodes[node_id]
KeyError: 'id1'
192.168.1.1 - - [05/Apr/2020 04:17:53] "[37mGET /balance HTTP/1.1[0m" 200 -
192.168.1.1 - - [05/Apr/2020 04:17:53] "[35m[1mPOST /new_transaction HTTP/1.1[0m" 500 -
Traceback (most recent call last):
  File "/home/user/.local/lib/python3.5/site-packages/flask/app.py", line 2464, in __call__
    return self.wsgi_app(environ, start_response)
  File "/home/user/.local/lib/python3.5/site-packages/flask/app.py", line 2450, in wsgi_app
    response = self.handle_exception(e)
  File "/home/user/.local/lib/python3.5/site-packages/flask/app.py", line 1867, in handle_exception
    reraise(exc_type, exc_value, tb)
  File "/home/user/.local/lib/python3.5/site-packages/flask/_compat.py", line 39, in reraise
    raise value
  File "/home/user/.local/lib/python3.5/site-packages/flask/app.py", line 2447, in wsgi_app
    response = self.full_dispatch_request()
  File "/home/user/.local/lib/python3.5/site-packages/flask/app.py", line 1952, in full_dispatch_request
    rv = self.handle_user_exception(e)
  File "/home/user/.local/lib/python3.5/site-packages/flask/app.py", line 1821, in handle_user_exception
    reraise(exc_type, exc_value, tb)
  File "/home/user/.local/lib/python3.5/site-packages/flask/_compat.py", line 39, in reraise
    raise value
  File "/home/user/.local/lib/python3.5/site-packages/flask/app.py", line 1950, in full_dispatch_request
    rv = self.dispatch_request()
  File "/home/user/.local/lib/python3.5/site-packages/flask/app.py", line 1936, in dispatch_request
    return self.view_functions[rule.endpoint](**req.view_args)
  File "/home/user/noobcash/noobcash/backend/broadcast.py", line 221, in cli_new_transaction
    node = State.state.nodes[node_id]
KeyError: 'id1'
192.168.1.1 - - [05/Apr/2020 04:17:53] "[37mGET /balance HTTP/1.1[0m" 200 -
192.168.1.1 - - [05/Apr/2020 04:17:53] "[35m[1mPOST /new_transaction HTTP/1.1[0m" 500 -
Traceback (most recent call last):
  File "/home/user/.local/lib/python3.5/site-packages/flask/app.py", line 2464, in __call__
    return self.wsgi_app(environ, start_response)
  File "/home/user/.local/lib/python3.5/site-packages/flask/app.py", line 2450, in wsgi_app
    response = self.handle_exception(e)
  File "/home/user/.local/lib/python3.5/site-packages/flask/app.py", line 1867, in handle_exception
    reraise(exc_type, exc_value, tb)
  File "/home/user/.local/lib/python3.5/site-packages/flask/_compat.py", line 39, in reraise
    raise value
  File "/home/user/.local/lib/python3.5/site-packages/flask/app.py", line 2447, in wsgi_app
    response = self.full_dispatch_request()
  File "/home/user/.local/lib/python3.5/site-packages/flask/app.py", line 1952, in full_dispatch_request
    rv = self.handle_user_exception(e)
  File "/home/user/.local/lib/python3.5/site-packages/flask/app.py", line 1821, in handle_user_exception
    reraise(exc_type, exc_value, tb)
  File "/home/user/.local/lib/python3.5/site-packages/flask/_compat.py", line 39, in reraise
    raise value
  File "/home/user/.local/lib/python3.5/site-packages/flask/app.py", line 1950, in full_dispatch_request
    rv = self.dispatch_request()
  File "/home/user/.local/lib/python3.5/site-packages/flask/app.py", line 1936, in dispatch_request
    return self.view_functions[rule.endpoint](**req.view_args)
  File "/home/user/noobcash/noobcash/backend/broadcast.py", line 221, in cli_new_transaction
    node = State.state.nodes[node_id]
KeyError: 'id4'
192.168.1.1 - - [05/Apr/2020 04:17:53] "[37mGET /balance HTTP/1.1[0m" 200 -
192.168.1.1 - - [05/Apr/2020 04:17:53] "[35m[1mPOST /new_transaction HTTP/1.1[0m" 500 -
Traceback (most recent call last):
  File "/home/user/.local/lib/python3.5/site-packages/flask/app.py", line 2464, in __call__
    return self.wsgi_app(environ, start_response)
  File "/home/user/.local/lib/python3.5/site-packages/flask/app.py", line 2450, in wsgi_app
    response = self.handle_exception(e)
  File "/home/user/.local/lib/python3.5/site-packages/flask/app.py", line 1867, in handle_exception
    reraise(exc_type, exc_value, tb)
  File "/home/user/.local/lib/python3.5/site-packages/flask/_compat.py", line 39, in reraise
    raise value
  File "/home/user/.local/lib/python3.5/site-packages/flask/app.py", line 2447, in wsgi_app
    response = self.full_dispatch_request()
  File "/home/user/.local/lib/python3.5/site-packages/flask/app.py", line 1952, in full_dispatch_request
    rv = self.handle_user_exception(e)
  File "/home/user/.local/lib/python3.5/site-packages/flask/app.py", line 1821, in handle_user_exception
    reraise(exc_type, exc_value, tb)
  File "/home/user/.local/lib/python3.5/site-packages/flask/_compat.py", line 39, in reraise
    raise value
  File "/home/user/.local/lib/python3.5/site-packages/flask/app.py", line 1950, in full_dispatch_request
    rv = self.dispatch_request()
  File "/home/user/.local/lib/python3.5/site-packages/flask/app.py", line 1936, in dispatch_request
    return self.view_functions[rule.endpoint](**req.view_args)
  File "/home/user/noobcash/noobcash/backend/broadcast.py", line 221, in cli_new_transaction
    node = State.state.nodes[node_id]
KeyError: 'id3'
192.168.1.1 - - [05/Apr/2020 04:17:53] "[37mGET /balance HTTP/1.1[0m" 200 -
192.168.1.1 - - [05/Apr/2020 04:17:53] "[35m[1mPOST /new_transaction HTTP/1.1[0m" 500 -
Traceback (most recent call last):
  File "/home/user/.local/lib/python3.5/site-packages/flask/app.py", line 2464, in __call__
    return self.wsgi_app(environ, start_response)
  File "/home/user/.local/lib/python3.5/site-packages/flask/app.py", line 2450, in wsgi_app
    response = self.handle_exception(e)
  File "/home/user/.local/lib/python3.5/site-packages/flask/app.py", line 1867, in handle_exception
    reraise(exc_type, exc_value, tb)
  File "/home/user/.local/lib/python3.5/site-packages/flask/_compat.py", line 39, in reraise
    raise value
  File "/home/user/.local/lib/python3.5/site-packages/flask/app.py", line 2447, in wsgi_app
    response = self.full_dispatch_request()
  File "/home/user/.local/lib/python3.5/site-packages/flask/app.py", line 1952, in full_dispatch_request
    rv = self.handle_user_exception(e)
  File "/home/user/.local/lib/python3.5/site-packages/flask/app.py", line 1821, in handle_user_exception
    reraise(exc_type, exc_value, tb)
  File "/home/user/.local/lib/python3.5/site-packages/flask/_compat.py", line 39, in reraise
    raise value
  File "/home/user/.local/lib/python3.5/site-packages/flask/app.py", line 1950, in full_dispatch_request
    rv = self.dispatch_request()
  File "/home/user/.local/lib/python3.5/site-packages/flask/app.py", line 1936, in dispatch_request
    return self.view_functions[rule.endpoint](**req.view_args)
  File "/home/user/noobcash/noobcash/backend/broadcast.py", line 221, in cli_new_transaction
    node = State.state.nodes[node_id]
KeyError: 'id4'
192.168.1.1 - - [05/Apr/2020 04:17:53] "[37mGET /balance HTTP/1.1[0m" 200 -
192.168.1.1 - - [05/Apr/2020 04:17:53] "[35m[1mPOST /new_transaction HTTP/1.1[0m" 500 -
Traceback (most recent call last):
  File "/home/user/.local/lib/python3.5/site-packages/flask/app.py", line 2464, in __call__
    return self.wsgi_app(environ, start_response)
  File "/home/user/.local/lib/python3.5/site-packages/flask/app.py", line 2450, in wsgi_app
    response = self.handle_exception(e)
  File "/home/user/.local/lib/python3.5/site-packages/flask/app.py", line 1867, in handle_exception
    reraise(exc_type, exc_value, tb)
  File "/home/user/.local/lib/python3.5/site-packages/flask/_compat.py", line 39, in reraise
    raise value
  File "/home/user/.local/lib/python3.5/site-packages/flask/app.py", line 2447, in wsgi_app
    response = self.full_dispatch_request()
  File "/home/user/.local/lib/python3.5/site-packages/flask/app.py", line 1952, in full_dispatch_request
    rv = self.handle_user_exception(e)
  File "/home/user/.local/lib/python3.5/site-packages/flask/app.py", line 1821, in handle_user_exception
    reraise(exc_type, exc_value, tb)
  File "/home/user/.local/lib/python3.5/site-packages/flask/_compat.py", line 39, in reraise
    raise value
  File "/home/user/.local/lib/python3.5/site-packages/flask/app.py", line 1950, in full_dispatch_request
    rv = self.dispatch_request()
  File "/home/user/.local/lib/python3.5/site-packages/flask/app.py", line 1936, in dispatch_request
    return self.view_functions[rule.endpoint](**req.view_args)
  File "/home/user/noobcash/noobcash/backend/broadcast.py", line 221, in cli_new_transaction
    node = State.state.nodes[node_id]
KeyError: 'id2'
192.168.1.1 - - [05/Apr/2020 04:17:53] "[37mGET /balance HTTP/1.1[0m" 200 -
192.168.1.1 - - [05/Apr/2020 04:17:53] "[35m[1mPOST /new_transaction HTTP/1.1[0m" 500 -
Traceback (most recent call last):
  File "/home/user/.local/lib/python3.5/site-packages/flask/app.py", line 2464, in __call__
    return self.wsgi_app(environ, start_response)
  File "/home/user/.local/lib/python3.5/site-packages/flask/app.py", line 2450, in wsgi_app
    response = self.handle_exception(e)
  File "/home/user/.local/lib/python3.5/site-packages/flask/app.py", line 1867, in handle_exception
    reraise(exc_type, exc_value, tb)
  File "/home/user/.local/lib/python3.5/site-packages/flask/_compat.py", line 39, in reraise
    raise value
  File "/home/user/.local/lib/python3.5/site-packages/flask/app.py", line 2447, in wsgi_app
    response = self.full_dispatch_request()
  File "/home/user/.local/lib/python3.5/site-packages/flask/app.py", line 1952, in full_dispatch_request
    rv = self.handle_user_exception(e)
  File "/home/user/.local/lib/python3.5/site-packages/flask/app.py", line 1821, in handle_user_exception
    reraise(exc_type, exc_value, tb)
  File "/home/user/.local/lib/python3.5/site-packages/flask/_compat.py", line 39, in reraise
    raise value
  File "/home/user/.local/lib/python3.5/site-packages/flask/app.py", line 1950, in full_dispatch_request
    rv = self.dispatch_request()
  File "/home/user/.local/lib/python3.5/site-packages/flask/app.py", line 1936, in dispatch_request
    return self.view_functions[rule.endpoint](**req.view_args)
  File "/home/user/noobcash/noobcash/backend/broadcast.py", line 221, in cli_new_transaction
    node = State.state.nodes[node_id]
KeyError: 'id3'
192.168.1.1 - - [05/Apr/2020 04:17:53] "[37mGET /balance HTTP/1.1[0m" 200 -
192.168.1.1 - - [05/Apr/2020 04:17:53] "[35m[1mPOST /new_transaction HTTP/1.1[0m" 500 -
Traceback (most recent call last):
  File "/home/user/.local/lib/python3.5/site-packages/flask/app.py", line 2464, in __call__
    return self.wsgi_app(environ, start_response)
  File "/home/user/.local/lib/python3.5/site-packages/flask/app.py", line 2450, in wsgi_app
    response = self.handle_exception(e)
  File "/home/user/.local/lib/python3.5/site-packages/flask/app.py", line 1867, in handle_exception
    reraise(exc_type, exc_value, tb)
  File "/home/user/.local/lib/python3.5/site-packages/flask/_compat.py", line 39, in reraise
    raise value
  File "/home/user/.local/lib/python3.5/site-packages/flask/app.py", line 2447, in wsgi_app
    response = self.full_dispatch_request()
  File "/home/user/.local/lib/python3.5/site-packages/flask/app.py", line 1952, in full_dispatch_request
    rv = self.handle_user_exception(e)
  File "/home/user/.local/lib/python3.5/site-packages/flask/app.py", line 1821, in handle_user_exception
    reraise(exc_type, exc_value, tb)
  File "/home/user/.local/lib/python3.5/site-packages/flask/_compat.py", line 39, in reraise
    raise value
  File "/home/user/.local/lib/python3.5/site-packages/flask/app.py", line 1950, in full_dispatch_request
    rv = self.dispatch_request()
  File "/home/user/.local/lib/python3.5/site-packages/flask/app.py", line 1936, in dispatch_request
    return self.view_functions[rule.endpoint](**req.view_args)
  File "/home/user/noobcash/noobcash/backend/broadcast.py", line 221, in cli_new_transaction
    node = State.state.nodes[node_id]
KeyError: 'id3'
192.168.1.1 - - [05/Apr/2020 04:17:53] "[37mGET /balance HTTP/1.1[0m" 200 -
192.168.1.1 - - [05/Apr/2020 04:17:53] "[35m[1mPOST /new_transaction HTTP/1.1[0m" 500 -
Traceback (most recent call last):
  File "/home/user/.local/lib/python3.5/site-packages/flask/app.py", line 2464, in __call__
    return self.wsgi_app(environ, start_response)
  File "/home/user/.local/lib/python3.5/site-packages/flask/app.py", line 2450, in wsgi_app
    response = self.handle_exception(e)
  File "/home/user/.local/lib/python3.5/site-packages/flask/app.py", line 1867, in handle_exception
    reraise(exc_type, exc_value, tb)
  File "/home/user/.local/lib/python3.5/site-packages/flask/_compat.py", line 39, in reraise
    raise value
  File "/home/user/.local/lib/python3.5/site-packages/flask/app.py", line 2447, in wsgi_app
    response = self.full_dispatch_request()
  File "/home/user/.local/lib/python3.5/site-packages/flask/app.py", line 1952, in full_dispatch_request
    rv = self.handle_user_exception(e)
  File "/home/user/.local/lib/python3.5/site-packages/flask/app.py", line 1821, in handle_user_exception
    reraise(exc_type, exc_value, tb)
  File "/home/user/.local/lib/python3.5/site-packages/flask/_compat.py", line 39, in reraise
    raise value
  File "/home/user/.local/lib/python3.5/site-packages/flask/app.py", line 1950, in full_dispatch_request
    rv = self.dispatch_request()
  File "/home/user/.local/lib/python3.5/site-packages/flask/app.py", line 1936, in dispatch_request
    return self.view_functions[rule.endpoint](**req.view_args)
  File "/home/user/noobcash/noobcash/backend/broadcast.py", line 221, in cli_new_transaction
    node = State.state.nodes[node_id]
KeyError: 'id1'
192.168.1.1 - - [05/Apr/2020 04:17:53] "[37mGET /balance HTTP/1.1[0m" 200 -
192.168.1.1 - - [05/Apr/2020 04:17:53] "[35m[1mPOST /new_transaction HTTP/1.1[0m" 500 -
Traceback (most recent call last):
  File "/home/user/.local/lib/python3.5/site-packages/flask/app.py", line 2464, in __call__
    return self.wsgi_app(environ, start_response)
  File "/home/user/.local/lib/python3.5/site-packages/flask/app.py", line 2450, in wsgi_app
    response = self.handle_exception(e)
  File "/home/user/.local/lib/python3.5/site-packages/flask/app.py", line 1867, in handle_exception
    reraise(exc_type, exc_value, tb)
  File "/home/user/.local/lib/python3.5/site-packages/flask/_compat.py", line 39, in reraise
    raise value
  File "/home/user/.local/lib/python3.5/site-packages/flask/app.py", line 2447, in wsgi_app
    response = self.full_dispatch_request()
  File "/home/user/.local/lib/python3.5/site-packages/flask/app.py", line 1952, in full_dispatch_request
    rv = self.handle_user_exception(e)
  File "/home/user/.local/lib/python3.5/site-packages/flask/app.py", line 1821, in handle_user_exception
    reraise(exc_type, exc_value, tb)
  File "/home/user/.local/lib/python3.5/site-packages/flask/_compat.py", line 39, in reraise
    raise value
  File "/home/user/.local/lib/python3.5/site-packages/flask/app.py", line 1950, in full_dispatch_request
    rv = self.dispatch_request()
  File "/home/user/.local/lib/python3.5/site-packages/flask/app.py", line 1936, in dispatch_request
    return self.view_functions[rule.endpoint](**req.view_args)
  File "/home/user/noobcash/noobcash/backend/broadcast.py", line 221, in cli_new_transaction
    node = State.state.nodes[node_id]
KeyError: 'id3'
192.168.1.1 - - [05/Apr/2020 04:17:53] "[37mGET /balance HTTP/1.1[0m" 200 -
192.168.1.1 - - [05/Apr/2020 04:17:53] "[35m[1mPOST /new_transaction HTTP/1.1[0m" 500 -
Traceback (most recent call last):
  File "/home/user/.local/lib/python3.5/site-packages/flask/app.py", line 2464, in __call__
    return self.wsgi_app(environ, start_response)
  File "/home/user/.local/lib/python3.5/site-packages/flask/app.py", line 2450, in wsgi_app
    response = self.handle_exception(e)
  File "/home/user/.local/lib/python3.5/site-packages/flask/app.py", line 1867, in handle_exception
    reraise(exc_type, exc_value, tb)
  File "/home/user/.local/lib/python3.5/site-packages/flask/_compat.py", line 39, in reraise
    raise value
  File "/home/user/.local/lib/python3.5/site-packages/flask/app.py", line 2447, in wsgi_app
    response = self.full_dispatch_request()
  File "/home/user/.local/lib/python3.5/site-packages/flask/app.py", line 1952, in full_dispatch_request
    rv = self.handle_user_exception(e)
  File "/home/user/.local/lib/python3.5/site-packages/flask/app.py", line 1821, in handle_user_exception
    reraise(exc_type, exc_value, tb)
  File "/home/user/.local/lib/python3.5/site-packages/flask/_compat.py", line 39, in reraise
    raise value
  File "/home/user/.local/lib/python3.5/site-packages/flask/app.py", line 1950, in full_dispatch_request
    rv = self.dispatch_request()
  File "/home/user/.local/lib/python3.5/site-packages/flask/app.py", line 1936, in dispatch_request
    return self.view_functions[rule.endpoint](**req.view_args)
  File "/home/user/noobcash/noobcash/backend/broadcast.py", line 221, in cli_new_transaction
    node = State.state.nodes[node_id]
KeyError: 'id2'
192.168.1.1 - - [05/Apr/2020 04:17:53] "[37mGET /balance HTTP/1.1[0m" 200 -
192.168.1.1 - - [05/Apr/2020 04:17:53] "[35m[1mPOST /new_transaction HTTP/1.1[0m" 500 -
Traceback (most recent call last):
  File "/home/user/.local/lib/python3.5/site-packages/flask/app.py", line 2464, in __call__
    return self.wsgi_app(environ, start_response)
  File "/home/user/.local/lib/python3.5/site-packages/flask/app.py", line 2450, in wsgi_app
    response = self.handle_exception(e)
  File "/home/user/.local/lib/python3.5/site-packages/flask/app.py", line 1867, in handle_exception
    reraise(exc_type, exc_value, tb)
  File "/home/user/.local/lib/python3.5/site-packages/flask/_compat.py", line 39, in reraise
    raise value
  File "/home/user/.local/lib/python3.5/site-packages/flask/app.py", line 2447, in wsgi_app
    response = self.full_dispatch_request()
  File "/home/user/.local/lib/python3.5/site-packages/flask/app.py", line 1952, in full_dispatch_request
    rv = self.handle_user_exception(e)
  File "/home/user/.local/lib/python3.5/site-packages/flask/app.py", line 1821, in handle_user_exception
    reraise(exc_type, exc_value, tb)
  File "/home/user/.local/lib/python3.5/site-packages/flask/_compat.py", line 39, in reraise
    raise value
  File "/home/user/.local/lib/python3.5/site-packages/flask/app.py", line 1950, in full_dispatch_request
    rv = self.dispatch_request()
  File "/home/user/.local/lib/python3.5/site-packages/flask/app.py", line 1936, in dispatch_request
    return self.view_functions[rule.endpoint](**req.view_args)
  File "/home/user/noobcash/noobcash/backend/broadcast.py", line 221, in cli_new_transaction
    node = State.state.nodes[node_id]
KeyError: 'id4'
192.168.1.1 - - [05/Apr/2020 04:17:53] "[37mGET /balance HTTP/1.1[0m" 200 -
192.168.1.1 - - [05/Apr/2020 04:17:53] "[35m[1mPOST /new_transaction HTTP/1.1[0m" 500 -
Traceback (most recent call last):
  File "/home/user/.local/lib/python3.5/site-packages/flask/app.py", line 2464, in __call__
    return self.wsgi_app(environ, start_response)
  File "/home/user/.local/lib/python3.5/site-packages/flask/app.py", line 2450, in wsgi_app
    response = self.handle_exception(e)
  File "/home/user/.local/lib/python3.5/site-packages/flask/app.py", line 1867, in handle_exception
    reraise(exc_type, exc_value, tb)
  File "/home/user/.local/lib/python3.5/site-packages/flask/_compat.py", line 39, in reraise
    raise value
  File "/home/user/.local/lib/python3.5/site-packages/flask/app.py", line 2447, in wsgi_app
    response = self.full_dispatch_request()
  File "/home/user/.local/lib/python3.5/site-packages/flask/app.py", line 1952, in full_dispatch_request
    rv = self.handle_user_exception(e)
  File "/home/user/.local/lib/python3.5/site-packages/flask/app.py", line 1821, in handle_user_exception
    reraise(exc_type, exc_value, tb)
  File "/home/user/.local/lib/python3.5/site-packages/flask/_compat.py", line 39, in reraise
    raise value
  File "/home/user/.local/lib/python3.5/site-packages/flask/app.py", line 1950, in full_dispatch_request
    rv = self.dispatch_request()
  File "/home/user/.local/lib/python3.5/site-packages/flask/app.py", line 1936, in dispatch_request
    return self.view_functions[rule.endpoint](**req.view_args)
  File "/home/user/noobcash/noobcash/backend/broadcast.py", line 221, in cli_new_transaction
    node = State.state.nodes[node_id]
KeyError: 'id2'
192.168.1.1 - - [05/Apr/2020 04:17:53] "[37mGET /balance HTTP/1.1[0m" 200 -
192.168.1.1 - - [05/Apr/2020 04:17:53] "[35m[1mPOST /new_transaction HTTP/1.1[0m" 500 -
Traceback (most recent call last):
  File "/home/user/.local/lib/python3.5/site-packages/flask/app.py", line 2464, in __call__
    return self.wsgi_app(environ, start_response)
  File "/home/user/.local/lib/python3.5/site-packages/flask/app.py", line 2450, in wsgi_app
    response = self.handle_exception(e)
  File "/home/user/.local/lib/python3.5/site-packages/flask/app.py", line 1867, in handle_exception
    reraise(exc_type, exc_value, tb)
  File "/home/user/.local/lib/python3.5/site-packages/flask/_compat.py", line 39, in reraise
    raise value
  File "/home/user/.local/lib/python3.5/site-packages/flask/app.py", line 2447, in wsgi_app
    response = self.full_dispatch_request()
  File "/home/user/.local/lib/python3.5/site-packages/flask/app.py", line 1952, in full_dispatch_request
    rv = self.handle_user_exception(e)
  File "/home/user/.local/lib/python3.5/site-packages/flask/app.py", line 1821, in handle_user_exception
    reraise(exc_type, exc_value, tb)
  File "/home/user/.local/lib/python3.5/site-packages/flask/_compat.py", line 39, in reraise
    raise value
  File "/home/user/.local/lib/python3.5/site-packages/flask/app.py", line 1950, in full_dispatch_request
    rv = self.dispatch_request()
  File "/home/user/.local/lib/python3.5/site-packages/flask/app.py", line 1936, in dispatch_request
    return self.view_functions[rule.endpoint](**req.view_args)
  File "/home/user/noobcash/noobcash/backend/broadcast.py", line 221, in cli_new_transaction
    node = State.state.nodes[node_id]
KeyError: 'id4'
192.168.1.1 - - [05/Apr/2020 04:17:53] "[37mGET /balance HTTP/1.1[0m" 200 -
192.168.1.1 - - [05/Apr/2020 04:17:53] "[35m[1mPOST /new_transaction HTTP/1.1[0m" 500 -
Traceback (most recent call last):
  File "/home/user/.local/lib/python3.5/site-packages/flask/app.py", line 2464, in __call__
    return self.wsgi_app(environ, start_response)
  File "/home/user/.local/lib/python3.5/site-packages/flask/app.py", line 2450, in wsgi_app
    response = self.handle_exception(e)
  File "/home/user/.local/lib/python3.5/site-packages/flask/app.py", line 1867, in handle_exception
    reraise(exc_type, exc_value, tb)
  File "/home/user/.local/lib/python3.5/site-packages/flask/_compat.py", line 39, in reraise
    raise value
  File "/home/user/.local/lib/python3.5/site-packages/flask/app.py", line 2447, in wsgi_app
    response = self.full_dispatch_request()
  File "/home/user/.local/lib/python3.5/site-packages/flask/app.py", line 1952, in full_dispatch_request
    rv = self.handle_user_exception(e)
  File "/home/user/.local/lib/python3.5/site-packages/flask/app.py", line 1821, in handle_user_exception
    reraise(exc_type, exc_value, tb)
  File "/home/user/.local/lib/python3.5/site-packages/flask/_compat.py", line 39, in reraise
    raise value
  File "/home/user/.local/lib/python3.5/site-packages/flask/app.py", line 1950, in full_dispatch_request
    rv = self.dispatch_request()
  File "/home/user/.local/lib/python3.5/site-packages/flask/app.py", line 1936, in dispatch_request
    return self.view_functions[rule.endpoint](**req.view_args)
  File "/home/user/noobcash/noobcash/backend/broadcast.py", line 221, in cli_new_transaction
    node = State.state.nodes[node_id]
KeyError: 'id2'
192.168.1.1 - - [05/Apr/2020 04:17:53] "[37mGET /balance HTTP/1.1[0m" 200 -
192.168.1.1 - - [05/Apr/2020 04:17:53] "[35m[1mPOST /new_transaction HTTP/1.1[0m" 500 -
Traceback (most recent call last):
  File "/home/user/.local/lib/python3.5/site-packages/flask/app.py", line 2464, in __call__
    return self.wsgi_app(environ, start_response)
  File "/home/user/.local/lib/python3.5/site-packages/flask/app.py", line 2450, in wsgi_app
    response = self.handle_exception(e)
  File "/home/user/.local/lib/python3.5/site-packages/flask/app.py", line 1867, in handle_exception
    reraise(exc_type, exc_value, tb)
  File "/home/user/.local/lib/python3.5/site-packages/flask/_compat.py", line 39, in reraise
    raise value
  File "/home/user/.local/lib/python3.5/site-packages/flask/app.py", line 2447, in wsgi_app
    response = self.full_dispatch_request()
  File "/home/user/.local/lib/python3.5/site-packages/flask/app.py", line 1952, in full_dispatch_request
    rv = self.handle_user_exception(e)
  File "/home/user/.local/lib/python3.5/site-packages/flask/app.py", line 1821, in handle_user_exception
    reraise(exc_type, exc_value, tb)
  File "/home/user/.local/lib/python3.5/site-packages/flask/_compat.py", line 39, in reraise
    raise value
  File "/home/user/.local/lib/python3.5/site-packages/flask/app.py", line 1950, in full_dispatch_request
    rv = self.dispatch_request()
  File "/home/user/.local/lib/python3.5/site-packages/flask/app.py", line 1936, in dispatch_request
    return self.view_functions[rule.endpoint](**req.view_args)
  File "/home/user/noobcash/noobcash/backend/broadcast.py", line 221, in cli_new_transaction
    node = State.state.nodes[node_id]
KeyError: 'id3'
192.168.1.1 - - [05/Apr/2020 04:17:53] "[37mGET /balance HTTP/1.1[0m" 200 -
192.168.1.1 - - [05/Apr/2020 04:17:53] "[35m[1mPOST /new_transaction HTTP/1.1[0m" 500 -
Traceback (most recent call last):
  File "/home/user/.local/lib/python3.5/site-packages/flask/app.py", line 2464, in __call__
    return self.wsgi_app(environ, start_response)
  File "/home/user/.local/lib/python3.5/site-packages/flask/app.py", line 2450, in wsgi_app
    response = self.handle_exception(e)
  File "/home/user/.local/lib/python3.5/site-packages/flask/app.py", line 1867, in handle_exception
    reraise(exc_type, exc_value, tb)
  File "/home/user/.local/lib/python3.5/site-packages/flask/_compat.py", line 39, in reraise
    raise value
  File "/home/user/.local/lib/python3.5/site-packages/flask/app.py", line 2447, in wsgi_app
    response = self.full_dispatch_request()
  File "/home/user/.local/lib/python3.5/site-packages/flask/app.py", line 1952, in full_dispatch_request
    rv = self.handle_user_exception(e)
  File "/home/user/.local/lib/python3.5/site-packages/flask/app.py", line 1821, in handle_user_exception
    reraise(exc_type, exc_value, tb)
  File "/home/user/.local/lib/python3.5/site-packages/flask/_compat.py", line 39, in reraise
    raise value
  File "/home/user/.local/lib/python3.5/site-packages/flask/app.py", line 1950, in full_dispatch_request
    rv = self.dispatch_request()
  File "/home/user/.local/lib/python3.5/site-packages/flask/app.py", line 1936, in dispatch_request
    return self.view_functions[rule.endpoint](**req.view_args)
  File "/home/user/noobcash/noobcash/backend/broadcast.py", line 221, in cli_new_transaction
    node = State.state.nodes[node_id]
KeyError: 'id3'
192.168.1.1 - - [05/Apr/2020 04:17:53] "[37mGET /balance HTTP/1.1[0m" 200 -
192.168.1.1 - - [05/Apr/2020 04:17:53] "[35m[1mPOST /new_transaction HTTP/1.1[0m" 500 -
Traceback (most recent call last):
  File "/home/user/.local/lib/python3.5/site-packages/flask/app.py", line 2464, in __call__
    return self.wsgi_app(environ, start_response)
  File "/home/user/.local/lib/python3.5/site-packages/flask/app.py", line 2450, in wsgi_app
    response = self.handle_exception(e)
  File "/home/user/.local/lib/python3.5/site-packages/flask/app.py", line 1867, in handle_exception
    reraise(exc_type, exc_value, tb)
  File "/home/user/.local/lib/python3.5/site-packages/flask/_compat.py", line 39, in reraise
    raise value
  File "/home/user/.local/lib/python3.5/site-packages/flask/app.py", line 2447, in wsgi_app
    response = self.full_dispatch_request()
  File "/home/user/.local/lib/python3.5/site-packages/flask/app.py", line 1952, in full_dispatch_request
    rv = self.handle_user_exception(e)
  File "/home/user/.local/lib/python3.5/site-packages/flask/app.py", line 1821, in handle_user_exception
    reraise(exc_type, exc_value, tb)
  File "/home/user/.local/lib/python3.5/site-packages/flask/_compat.py", line 39, in reraise
    raise value
  File "/home/user/.local/lib/python3.5/site-packages/flask/app.py", line 1950, in full_dispatch_request
    rv = self.dispatch_request()
  File "/home/user/.local/lib/python3.5/site-packages/flask/app.py", line 1936, in dispatch_request
    return self.view_functions[rule.endpoint](**req.view_args)
  File "/home/user/noobcash/noobcash/backend/broadcast.py", line 221, in cli_new_transaction
    node = State.state.nodes[node_id]
KeyError: 'id4'
192.168.1.1 - - [05/Apr/2020 04:17:53] "[37mGET /balance HTTP/1.1[0m" 200 -
192.168.1.1 - - [05/Apr/2020 04:17:54] "[35m[1mPOST /new_transaction HTTP/1.1[0m" 500 -
Traceback (most recent call last):
  File "/home/user/.local/lib/python3.5/site-packages/flask/app.py", line 2464, in __call__
    return self.wsgi_app(environ, start_response)
  File "/home/user/.local/lib/python3.5/site-packages/flask/app.py", line 2450, in wsgi_app
    response = self.handle_exception(e)
  File "/home/user/.local/lib/python3.5/site-packages/flask/app.py", line 1867, in handle_exception
    reraise(exc_type, exc_value, tb)
  File "/home/user/.local/lib/python3.5/site-packages/flask/_compat.py", line 39, in reraise
    raise value
  File "/home/user/.local/lib/python3.5/site-packages/flask/app.py", line 2447, in wsgi_app
    response = self.full_dispatch_request()
  File "/home/user/.local/lib/python3.5/site-packages/flask/app.py", line 1952, in full_dispatch_request
    rv = self.handle_user_exception(e)
  File "/home/user/.local/lib/python3.5/site-packages/flask/app.py", line 1821, in handle_user_exception
    reraise(exc_type, exc_value, tb)
  File "/home/user/.local/lib/python3.5/site-packages/flask/_compat.py", line 39, in reraise
    raise value
  File "/home/user/.local/lib/python3.5/site-packages/flask/app.py", line 1950, in full_dispatch_request
    rv = self.dispatch_request()
  File "/home/user/.local/lib/python3.5/site-packages/flask/app.py", line 1936, in dispatch_request
    return self.view_functions[rule.endpoint](**req.view_args)
  File "/home/user/noobcash/noobcash/backend/broadcast.py", line 221, in cli_new_transaction
    node = State.state.nodes[node_id]
KeyError: 'id4'
192.168.1.1 - - [05/Apr/2020 04:17:54] "[37mGET /balance HTTP/1.1[0m" 200 -
192.168.1.1 - - [05/Apr/2020 04:17:54] "[35m[1mPOST /new_transaction HTTP/1.1[0m" 500 -
Traceback (most recent call last):
  File "/home/user/.local/lib/python3.5/site-packages/flask/app.py", line 2464, in __call__
    return self.wsgi_app(environ, start_response)
  File "/home/user/.local/lib/python3.5/site-packages/flask/app.py", line 2450, in wsgi_app
    response = self.handle_exception(e)
  File "/home/user/.local/lib/python3.5/site-packages/flask/app.py", line 1867, in handle_exception
    reraise(exc_type, exc_value, tb)
  File "/home/user/.local/lib/python3.5/site-packages/flask/_compat.py", line 39, in reraise
    raise value
  File "/home/user/.local/lib/python3.5/site-packages/flask/app.py", line 2447, in wsgi_app
    response = self.full_dispatch_request()
  File "/home/user/.local/lib/python3.5/site-packages/flask/app.py", line 1952, in full_dispatch_request
    rv = self.handle_user_exception(e)
  File "/home/user/.local/lib/python3.5/site-packages/flask/app.py", line 1821, in handle_user_exception
    reraise(exc_type, exc_value, tb)
  File "/home/user/.local/lib/python3.5/site-packages/flask/_compat.py", line 39, in reraise
    raise value
  File "/home/user/.local/lib/python3.5/site-packages/flask/app.py", line 1950, in full_dispatch_request
    rv = self.dispatch_request()
  File "/home/user/.local/lib/python3.5/site-packages/flask/app.py", line 1936, in dispatch_request
    return self.view_functions[rule.endpoint](**req.view_args)
  File "/home/user/noobcash/noobcash/backend/broadcast.py", line 221, in cli_new_transaction
    node = State.state.nodes[node_id]
KeyError: 'id3'
192.168.1.1 - - [05/Apr/2020 04:17:54] "[37mGET /balance HTTP/1.1[0m" 200 -
192.168.1.1 - - [05/Apr/2020 04:17:54] "[35m[1mPOST /new_transaction HTTP/1.1[0m" 500 -
Traceback (most recent call last):
  File "/home/user/.local/lib/python3.5/site-packages/flask/app.py", line 2464, in __call__
    return self.wsgi_app(environ, start_response)
  File "/home/user/.local/lib/python3.5/site-packages/flask/app.py", line 2450, in wsgi_app
    response = self.handle_exception(e)
  File "/home/user/.local/lib/python3.5/site-packages/flask/app.py", line 1867, in handle_exception
    reraise(exc_type, exc_value, tb)
  File "/home/user/.local/lib/python3.5/site-packages/flask/_compat.py", line 39, in reraise
    raise value
  File "/home/user/.local/lib/python3.5/site-packages/flask/app.py", line 2447, in wsgi_app
    response = self.full_dispatch_request()
  File "/home/user/.local/lib/python3.5/site-packages/flask/app.py", line 1952, in full_dispatch_request
    rv = self.handle_user_exception(e)
  File "/home/user/.local/lib/python3.5/site-packages/flask/app.py", line 1821, in handle_user_exception
    reraise(exc_type, exc_value, tb)
  File "/home/user/.local/lib/python3.5/site-packages/flask/_compat.py", line 39, in reraise
    raise value
  File "/home/user/.local/lib/python3.5/site-packages/flask/app.py", line 1950, in full_dispatch_request
    rv = self.dispatch_request()
  File "/home/user/.local/lib/python3.5/site-packages/flask/app.py", line 1936, in dispatch_request
    return self.view_functions[rule.endpoint](**req.view_args)
  File "/home/user/noobcash/noobcash/backend/broadcast.py", line 221, in cli_new_transaction
    node = State.state.nodes[node_id]
KeyError: 'id1'
192.168.1.1 - - [05/Apr/2020 04:17:54] "[37mGET /balance HTTP/1.1[0m" 200 -
192.168.1.1 - - [05/Apr/2020 04:17:54] "[35m[1mPOST /new_transaction HTTP/1.1[0m" 500 -
Traceback (most recent call last):
  File "/home/user/.local/lib/python3.5/site-packages/flask/app.py", line 2464, in __call__
    return self.wsgi_app(environ, start_response)
  File "/home/user/.local/lib/python3.5/site-packages/flask/app.py", line 2450, in wsgi_app
    response = self.handle_exception(e)
  File "/home/user/.local/lib/python3.5/site-packages/flask/app.py", line 1867, in handle_exception
    reraise(exc_type, exc_value, tb)
  File "/home/user/.local/lib/python3.5/site-packages/flask/_compat.py", line 39, in reraise
    raise value
  File "/home/user/.local/lib/python3.5/site-packages/flask/app.py", line 2447, in wsgi_app
    response = self.full_dispatch_request()
  File "/home/user/.local/lib/python3.5/site-packages/flask/app.py", line 1952, in full_dispatch_request
    rv = self.handle_user_exception(e)
  File "/home/user/.local/lib/python3.5/site-packages/flask/app.py", line 1821, in handle_user_exception
    reraise(exc_type, exc_value, tb)
  File "/home/user/.local/lib/python3.5/site-packages/flask/_compat.py", line 39, in reraise
    raise value
  File "/home/user/.local/lib/python3.5/site-packages/flask/app.py", line 1950, in full_dispatch_request
    rv = self.dispatch_request()
  File "/home/user/.local/lib/python3.5/site-packages/flask/app.py", line 1936, in dispatch_request
    return self.view_functions[rule.endpoint](**req.view_args)
  File "/home/user/noobcash/noobcash/backend/broadcast.py", line 221, in cli_new_transaction
    node = State.state.nodes[node_id]
KeyError: 'id1'
192.168.1.1 - - [05/Apr/2020 04:17:54] "[37mGET /balance HTTP/1.1[0m" 200 -
192.168.1.1 - - [05/Apr/2020 04:17:54] "[35m[1mPOST /new_transaction HTTP/1.1[0m" 500 -
Traceback (most recent call last):
  File "/home/user/.local/lib/python3.5/site-packages/flask/app.py", line 2464, in __call__
    return self.wsgi_app(environ, start_response)
  File "/home/user/.local/lib/python3.5/site-packages/flask/app.py", line 2450, in wsgi_app
    response = self.handle_exception(e)
  File "/home/user/.local/lib/python3.5/site-packages/flask/app.py", line 1867, in handle_exception
    reraise(exc_type, exc_value, tb)
  File "/home/user/.local/lib/python3.5/site-packages/flask/_compat.py", line 39, in reraise
    raise value
  File "/home/user/.local/lib/python3.5/site-packages/flask/app.py", line 2447, in wsgi_app
    response = self.full_dispatch_request()
  File "/home/user/.local/lib/python3.5/site-packages/flask/app.py", line 1952, in full_dispatch_request
    rv = self.handle_user_exception(e)
  File "/home/user/.local/lib/python3.5/site-packages/flask/app.py", line 1821, in handle_user_exception
    reraise(exc_type, exc_value, tb)
  File "/home/user/.local/lib/python3.5/site-packages/flask/_compat.py", line 39, in reraise
    raise value
  File "/home/user/.local/lib/python3.5/site-packages/flask/app.py", line 1950, in full_dispatch_request
    rv = self.dispatch_request()
  File "/home/user/.local/lib/python3.5/site-packages/flask/app.py", line 1936, in dispatch_request
    return self.view_functions[rule.endpoint](**req.view_args)
  File "/home/user/noobcash/noobcash/backend/broadcast.py", line 221, in cli_new_transaction
    node = State.state.nodes[node_id]
KeyError: 'id3'
192.168.1.1 - - [05/Apr/2020 04:17:54] "[37mGET /balance HTTP/1.1[0m" 200 -
192.168.1.1 - - [05/Apr/2020 04:17:54] "[35m[1mPOST /new_transaction HTTP/1.1[0m" 500 -
Traceback (most recent call last):
  File "/home/user/.local/lib/python3.5/site-packages/flask/app.py", line 2464, in __call__
    return self.wsgi_app(environ, start_response)
  File "/home/user/.local/lib/python3.5/site-packages/flask/app.py", line 2450, in wsgi_app
    response = self.handle_exception(e)
  File "/home/user/.local/lib/python3.5/site-packages/flask/app.py", line 1867, in handle_exception
    reraise(exc_type, exc_value, tb)
  File "/home/user/.local/lib/python3.5/site-packages/flask/_compat.py", line 39, in reraise
    raise value
  File "/home/user/.local/lib/python3.5/site-packages/flask/app.py", line 2447, in wsgi_app
    response = self.full_dispatch_request()
  File "/home/user/.local/lib/python3.5/site-packages/flask/app.py", line 1952, in full_dispatch_request
    rv = self.handle_user_exception(e)
  File "/home/user/.local/lib/python3.5/site-packages/flask/app.py", line 1821, in handle_user_exception
    reraise(exc_type, exc_value, tb)
  File "/home/user/.local/lib/python3.5/site-packages/flask/_compat.py", line 39, in reraise
    raise value
  File "/home/user/.local/lib/python3.5/site-packages/flask/app.py", line 1950, in full_dispatch_request
    rv = self.dispatch_request()
  File "/home/user/.local/lib/python3.5/site-packages/flask/app.py", line 1936, in dispatch_request
    return self.view_functions[rule.endpoint](**req.view_args)
  File "/home/user/noobcash/noobcash/backend/broadcast.py", line 221, in cli_new_transaction
    node = State.state.nodes[node_id]
KeyError: 'id1'
192.168.1.1 - - [05/Apr/2020 04:17:54] "[37mGET /balance HTTP/1.1[0m" 200 -
192.168.1.1 - - [05/Apr/2020 04:17:54] "[35m[1mPOST /new_transaction HTTP/1.1[0m" 500 -
Traceback (most recent call last):
  File "/home/user/.local/lib/python3.5/site-packages/flask/app.py", line 2464, in __call__
    return self.wsgi_app(environ, start_response)
  File "/home/user/.local/lib/python3.5/site-packages/flask/app.py", line 2450, in wsgi_app
    response = self.handle_exception(e)
  File "/home/user/.local/lib/python3.5/site-packages/flask/app.py", line 1867, in handle_exception
    reraise(exc_type, exc_value, tb)
  File "/home/user/.local/lib/python3.5/site-packages/flask/_compat.py", line 39, in reraise
    raise value
  File "/home/user/.local/lib/python3.5/site-packages/flask/app.py", line 2447, in wsgi_app
    response = self.full_dispatch_request()
  File "/home/user/.local/lib/python3.5/site-packages/flask/app.py", line 1952, in full_dispatch_request
    rv = self.handle_user_exception(e)
  File "/home/user/.local/lib/python3.5/site-packages/flask/app.py", line 1821, in handle_user_exception
    reraise(exc_type, exc_value, tb)
  File "/home/user/.local/lib/python3.5/site-packages/flask/_compat.py", line 39, in reraise
    raise value
  File "/home/user/.local/lib/python3.5/site-packages/flask/app.py", line 1950, in full_dispatch_request
    rv = self.dispatch_request()
  File "/home/user/.local/lib/python3.5/site-packages/flask/app.py", line 1936, in dispatch_request
    return self.view_functions[rule.endpoint](**req.view_args)
  File "/home/user/noobcash/noobcash/backend/broadcast.py", line 221, in cli_new_transaction
    node = State.state.nodes[node_id]
KeyError: 'id2'
192.168.1.1 - - [05/Apr/2020 04:17:54] "[37mGET /balance HTTP/1.1[0m" 200 -
192.168.1.1 - - [05/Apr/2020 04:17:54] "[35m[1mPOST /new_transaction HTTP/1.1[0m" 500 -
Traceback (most recent call last):
  File "/home/user/.local/lib/python3.5/site-packages/flask/app.py", line 2464, in __call__
    return self.wsgi_app(environ, start_response)
  File "/home/user/.local/lib/python3.5/site-packages/flask/app.py", line 2450, in wsgi_app
    response = self.handle_exception(e)
  File "/home/user/.local/lib/python3.5/site-packages/flask/app.py", line 1867, in handle_exception
    reraise(exc_type, exc_value, tb)
  File "/home/user/.local/lib/python3.5/site-packages/flask/_compat.py", line 39, in reraise
    raise value
  File "/home/user/.local/lib/python3.5/site-packages/flask/app.py", line 2447, in wsgi_app
    response = self.full_dispatch_request()
  File "/home/user/.local/lib/python3.5/site-packages/flask/app.py", line 1952, in full_dispatch_request
    rv = self.handle_user_exception(e)
  File "/home/user/.local/lib/python3.5/site-packages/flask/app.py", line 1821, in handle_user_exception
    reraise(exc_type, exc_value, tb)
  File "/home/user/.local/lib/python3.5/site-packages/flask/_compat.py", line 39, in reraise
    raise value
  File "/home/user/.local/lib/python3.5/site-packages/flask/app.py", line 1950, in full_dispatch_request
    rv = self.dispatch_request()
  File "/home/user/.local/lib/python3.5/site-packages/flask/app.py", line 1936, in dispatch_request
    return self.view_functions[rule.endpoint](**req.view_args)
  File "/home/user/noobcash/noobcash/backend/broadcast.py", line 221, in cli_new_transaction
    node = State.state.nodes[node_id]
KeyError: 'id2'
192.168.1.1 - - [05/Apr/2020 04:17:54] "[37mGET /balance HTTP/1.1[0m" 200 -
192.168.1.1 - - [05/Apr/2020 04:17:54] "[35m[1mPOST /new_transaction HTTP/1.1[0m" 500 -
Traceback (most recent call last):
  File "/home/user/.local/lib/python3.5/site-packages/flask/app.py", line 2464, in __call__
    return self.wsgi_app(environ, start_response)
  File "/home/user/.local/lib/python3.5/site-packages/flask/app.py", line 2450, in wsgi_app
    response = self.handle_exception(e)
  File "/home/user/.local/lib/python3.5/site-packages/flask/app.py", line 1867, in handle_exception
    reraise(exc_type, exc_value, tb)
  File "/home/user/.local/lib/python3.5/site-packages/flask/_compat.py", line 39, in reraise
    raise value
  File "/home/user/.local/lib/python3.5/site-packages/flask/app.py", line 2447, in wsgi_app
    response = self.full_dispatch_request()
  File "/home/user/.local/lib/python3.5/site-packages/flask/app.py", line 1952, in full_dispatch_request
    rv = self.handle_user_exception(e)
  File "/home/user/.local/lib/python3.5/site-packages/flask/app.py", line 1821, in handle_user_exception
    reraise(exc_type, exc_value, tb)
  File "/home/user/.local/lib/python3.5/site-packages/flask/_compat.py", line 39, in reraise
    raise value
  File "/home/user/.local/lib/python3.5/site-packages/flask/app.py", line 1950, in full_dispatch_request
    rv = self.dispatch_request()
  File "/home/user/.local/lib/python3.5/site-packages/flask/app.py", line 1936, in dispatch_request
    return self.view_functions[rule.endpoint](**req.view_args)
  File "/home/user/noobcash/noobcash/backend/broadcast.py", line 221, in cli_new_transaction
    node = State.state.nodes[node_id]
KeyError: 'id3'
192.168.1.1 - - [05/Apr/2020 04:17:54] "[37mGET /balance HTTP/1.1[0m" 200 -
192.168.1.1 - - [05/Apr/2020 04:17:54] "[35m[1mPOST /new_transaction HTTP/1.1[0m" 500 -
Traceback (most recent call last):
  File "/home/user/.local/lib/python3.5/site-packages/flask/app.py", line 2464, in __call__
    return self.wsgi_app(environ, start_response)
  File "/home/user/.local/lib/python3.5/site-packages/flask/app.py", line 2450, in wsgi_app
    response = self.handle_exception(e)
  File "/home/user/.local/lib/python3.5/site-packages/flask/app.py", line 1867, in handle_exception
    reraise(exc_type, exc_value, tb)
  File "/home/user/.local/lib/python3.5/site-packages/flask/_compat.py", line 39, in reraise
    raise value
  File "/home/user/.local/lib/python3.5/site-packages/flask/app.py", line 2447, in wsgi_app
    response = self.full_dispatch_request()
  File "/home/user/.local/lib/python3.5/site-packages/flask/app.py", line 1952, in full_dispatch_request
    rv = self.handle_user_exception(e)
  File "/home/user/.local/lib/python3.5/site-packages/flask/app.py", line 1821, in handle_user_exception
    reraise(exc_type, exc_value, tb)
  File "/home/user/.local/lib/python3.5/site-packages/flask/_compat.py", line 39, in reraise
    raise value
  File "/home/user/.local/lib/python3.5/site-packages/flask/app.py", line 1950, in full_dispatch_request
    rv = self.dispatch_request()
  File "/home/user/.local/lib/python3.5/site-packages/flask/app.py", line 1936, in dispatch_request
    return self.view_functions[rule.endpoint](**req.view_args)
  File "/home/user/noobcash/noobcash/backend/broadcast.py", line 221, in cli_new_transaction
    node = State.state.nodes[node_id]
KeyError: 'id1'
192.168.1.1 - - [05/Apr/2020 04:17:54] "[37mGET /balance HTTP/1.1[0m" 200 -
192.168.1.1 - - [05/Apr/2020 04:17:54] "[35m[1mPOST /new_transaction HTTP/1.1[0m" 500 -
Traceback (most recent call last):
  File "/home/user/.local/lib/python3.5/site-packages/flask/app.py", line 2464, in __call__
    return self.wsgi_app(environ, start_response)
  File "/home/user/.local/lib/python3.5/site-packages/flask/app.py", line 2450, in wsgi_app
    response = self.handle_exception(e)
  File "/home/user/.local/lib/python3.5/site-packages/flask/app.py", line 1867, in handle_exception
    reraise(exc_type, exc_value, tb)
  File "/home/user/.local/lib/python3.5/site-packages/flask/_compat.py", line 39, in reraise
    raise value
  File "/home/user/.local/lib/python3.5/site-packages/flask/app.py", line 2447, in wsgi_app
    response = self.full_dispatch_request()
  File "/home/user/.local/lib/python3.5/site-packages/flask/app.py", line 1952, in full_dispatch_request
    rv = self.handle_user_exception(e)
  File "/home/user/.local/lib/python3.5/site-packages/flask/app.py", line 1821, in handle_user_exception
    reraise(exc_type, exc_value, tb)
  File "/home/user/.local/lib/python3.5/site-packages/flask/_compat.py", line 39, in reraise
    raise value
  File "/home/user/.local/lib/python3.5/site-packages/flask/app.py", line 1950, in full_dispatch_request
    rv = self.dispatch_request()
  File "/home/user/.local/lib/python3.5/site-packages/flask/app.py", line 1936, in dispatch_request
    return self.view_functions[rule.endpoint](**req.view_args)
  File "/home/user/noobcash/noobcash/backend/broadcast.py", line 221, in cli_new_transaction
    node = State.state.nodes[node_id]
KeyError: 'id2'
192.168.1.1 - - [05/Apr/2020 04:17:54] "[37mGET /balance HTTP/1.1[0m" 200 -
192.168.1.1 - - [05/Apr/2020 04:17:54] "[35m[1mPOST /new_transaction HTTP/1.1[0m" 500 -
Traceback (most recent call last):
  File "/home/user/.local/lib/python3.5/site-packages/flask/app.py", line 2464, in __call__
    return self.wsgi_app(environ, start_response)
  File "/home/user/.local/lib/python3.5/site-packages/flask/app.py", line 2450, in wsgi_app
    response = self.handle_exception(e)
  File "/home/user/.local/lib/python3.5/site-packages/flask/app.py", line 1867, in handle_exception
    reraise(exc_type, exc_value, tb)
  File "/home/user/.local/lib/python3.5/site-packages/flask/_compat.py", line 39, in reraise
    raise value
  File "/home/user/.local/lib/python3.5/site-packages/flask/app.py", line 2447, in wsgi_app
    response = self.full_dispatch_request()
  File "/home/user/.local/lib/python3.5/site-packages/flask/app.py", line 1952, in full_dispatch_request
    rv = self.handle_user_exception(e)
  File "/home/user/.local/lib/python3.5/site-packages/flask/app.py", line 1821, in handle_user_exception
    reraise(exc_type, exc_value, tb)
  File "/home/user/.local/lib/python3.5/site-packages/flask/_compat.py", line 39, in reraise
    raise value
  File "/home/user/.local/lib/python3.5/site-packages/flask/app.py", line 1950, in full_dispatch_request
    rv = self.dispatch_request()
  File "/home/user/.local/lib/python3.5/site-packages/flask/app.py", line 1936, in dispatch_request
    return self.view_functions[rule.endpoint](**req.view_args)
  File "/home/user/noobcash/noobcash/backend/broadcast.py", line 221, in cli_new_transaction
    node = State.state.nodes[node_id]
KeyError: 'id3'
192.168.1.1 - - [05/Apr/2020 04:17:54] "[37mGET /balance HTTP/1.1[0m" 200 -
