 * Serving Flask app "server" (lazy loading)
 * Environment: production
   WARNING: This is a development server. Do not use it in a production deployment.
   Use a production WSGI server instead.
 * Debug mode: on
 * Running on http://localhost:1238/ (Press CTRL+C to quit)
 * Restarting with stat
 * Debugger is active!
 * Debugger PIN: 237-852-435
127.0.0.1 - - [05/Apr/2020 01:28:14] "[37mPOST /receive_info HTTP/1.1[0m" 200 -
Received Transaction and is :  True
127.0.0.1 - - [05/Apr/2020 01:28:14] "[37mPOST /receive_transaction HTTP/1.1[0m" 200 -
Received Transaction and is :  True
127.0.0.1 - - [05/Apr/2020 01:28:14] "[37mPOST /receive_transaction HTTP/1.1[0m" 200 -
Received Transaction and is :  True
127.0.0.1 - - [05/Apr/2020 01:28:14] "[37mPOST /receive_transaction HTTP/1.1[0m" 200 -
Received Transaction and is :  True
127.0.0.1 - - [05/Apr/2020 01:28:14] "[37mPOST /receive_transaction HTTP/1.1[0m" 200 -
127.0.0.1 - - [05/Apr/2020 01:28:14] "[37mPOST /start HTTP/1.1[0m" 200 -
Our very own id is : 4
127.0.0.1 - - [05/Apr/2020 01:28:14] "[37mPOST /start_client HTTP/1.1[0m" 200 -
127.0.0.1 - - [05/Apr/2020 01:28:14] "[37mGET /notify_start HTTP/1.1[0m" 200 -
Requesting lock
Acquiring lock
Inital block was valid, no need to resolve conflict
Running average block addition time:  0.0004267692565917969
Releasing lock
Received Transaction and is :  True
127.0.0.1 - - [05/Apr/2020 01:28:14] "[37mPOST /receive_transaction HTTP/1.1[0m" 200 -
Received Transaction and is :  True
127.0.0.1 - - [05/Apr/2020 01:28:14] "[37mPOST /receive_transaction HTTP/1.1[0m" 200 -
Received Transaction and is :  True
127.0.0.1 - - [05/Apr/2020 01:28:14] "[37mPOST /receive_transaction HTTP/1.1[0m" 200 -
Received Transaction and is :  True
127.0.0.1 - - [05/Apr/2020 01:28:14] "[37mPOST /receive_transaction HTTP/1.1[0m" 200 -
127.0.0.1 - - [05/Apr/2020 01:28:38] "[1m[35mPOST /new_transaction HTTP/1.1[0m" 500 -
Requesting lock
Acquiring lock
Inital block was valid, no need to resolve conflict
Running average block addition time:  0.0006371736526489258
Releasing lock
Traceback (most recent call last):
  File "/home/nikitas/anaconda3/lib/python3.7/site-packages/urllib3/connectionpool.py", line 377, in _make_request
    httplib_response = conn.getresponse(buffering=True)
TypeError: getresponse() got an unexpected keyword argument 'buffering'

During handling of the above exception, another exception occurred:

Traceback (most recent call last):
  File "/home/nikitas/anaconda3/lib/python3.7/site-packages/urllib3/connectionpool.py", line 600, in urlopen
    chunked=chunked)
  File "/home/nikitas/anaconda3/lib/python3.7/site-packages/urllib3/connectionpool.py", line 384, in _make_request
    six.raise_from(e, None)
  File "<string>", line 2, in raise_from
    
  File "/home/nikitas/anaconda3/lib/python3.7/site-packages/urllib3/connectionpool.py", line 380, in _make_request
    httplib_response = conn.getresponse()
  File "/home/nikitas/anaconda3/lib/python3.7/http/client.py", line 1336, in getresponse
    response.begin()
  File "/home/nikitas/anaconda3/lib/python3.7/http/client.py", line 306, in begin
    version, status, reason = self._read_status()
  File "/home/nikitas/anaconda3/lib/python3.7/http/client.py", line 275, in _read_status
    raise RemoteDisconnected("Remote end closed connection without"
http.client.RemoteDisconnected: Remote end closed connection without response

During handling of the above exception, another exception occurred:

Traceback (most recent call last):
  File "/home/nikitas/anaconda3/lib/python3.7/site-packages/requests/adapters.py", line 449, in send
    timeout=timeout
  File "/home/nikitas/anaconda3/lib/python3.7/site-packages/urllib3/connectionpool.py", line 638, in urlopen
    _stacktrace=sys.exc_info()[2])
  File "/home/nikitas/anaconda3/lib/python3.7/site-packages/urllib3/util/retry.py", line 368, in increment
    raise six.reraise(type(error), error, _stacktrace)
  File "/home/nikitas/anaconda3/lib/python3.7/site-packages/urllib3/packages/six.py", line 685, in reraise
    raise value.with_traceback(tb)
  File "/home/nikitas/anaconda3/lib/python3.7/site-packages/urllib3/connectionpool.py", line 600, in urlopen
    chunked=chunked)
  File "/home/nikitas/anaconda3/lib/python3.7/site-packages/urllib3/connectionpool.py", line 384, in _make_request
    six.raise_from(e, None)
  File "<string>", line 2, in raise_from
    
  File "/home/nikitas/anaconda3/lib/python3.7/site-packages/urllib3/connectionpool.py", line 380, in _make_request
    httplib_response = conn.getresponse()
  File "/home/nikitas/anaconda3/lib/python3.7/http/client.py", line 1336, in getresponse
    response.begin()
  File "/home/nikitas/anaconda3/lib/python3.7/http/client.py", line 306, in begin
    version, status, reason = self._read_status()
  File "/home/nikitas/anaconda3/lib/python3.7/http/client.py", line 275, in _read_status
    raise RemoteDisconnected("Remote end closed connection without"
urllib3.exceptions.ProtocolError: ('Connection aborted.', RemoteDisconnected('Remote end closed connection without response'))

During handling of the above exception, another exception occurred:

Traceback (most recent call last):
  File "/home/nikitas/anaconda3/lib/python3.7/site-packages/flask/app.py", line 2463, in __call__
    return self.wsgi_app(environ, start_response)
  File "/home/nikitas/anaconda3/lib/python3.7/site-packages/flask/app.py", line 2449, in wsgi_app
    response = self.handle_exception(e)
  File "/home/nikitas/anaconda3/lib/python3.7/site-packages/flask/app.py", line 1866, in handle_exception
    reraise(exc_type, exc_value, tb)
  File "/home/nikitas/anaconda3/lib/python3.7/site-packages/flask/_compat.py", line 39, in reraise
    raise value
  File "/home/nikitas/anaconda3/lib/python3.7/site-packages/flask/app.py", line 2446, in wsgi_app
    response = self.full_dispatch_request()
  File "/home/nikitas/anaconda3/lib/python3.7/site-packages/flask/app.py", line 1951, in full_dispatch_request
    rv = self.handle_user_exception(e)
  File "/home/nikitas/anaconda3/lib/python3.7/site-packages/flask/app.py", line 1820, in handle_user_exception
    reraise(exc_type, exc_value, tb)
  File "/home/nikitas/anaconda3/lib/python3.7/site-packages/flask/_compat.py", line 39, in reraise
    raise value
  File "/home/nikitas/anaconda3/lib/python3.7/site-packages/flask/app.py", line 1949, in full_dispatch_request
    rv = self.dispatch_request()
  File "/home/nikitas/anaconda3/lib/python3.7/site-packages/flask/app.py", line 1935, in dispatch_request
    return self.view_functions[rule.endpoint](**req.view_args)
  File "/home/nikitas/Desktop/distrib/noobcash/backend/broadcast.py", line 215, in cli_new_transaction
    if (new_transaction(node['pub'], amount)):
  File "/home/nikitas/Desktop/distrib/noobcash/backend/broadcast.py", line 82, in new_transaction
    t = Transaction.create_transaction(receiver, amount)
  File "/home/nikitas/Desktop/distrib/noobcash/backend/transaction.py", line 174, in create_transaction
    State.state.mine_block()
  File "/home/nikitas/Desktop/distrib/noobcash/backend/state.py", line 80, in mine_block
    broadcast.broadcast_block(block)
  File "/home/nikitas/Desktop/distrib/noobcash/backend/broadcast.py", line 22, in broadcast_block
    return broadcast(json_block,'receive_block',node_id)
  File "/home/nikitas/Desktop/distrib/noobcash/backend/broadcast.py", line 41, in broadcast
    response = requests.post('{}/{}'.format(ip,rest_point), json=json_obj)
  File "/home/nikitas/anaconda3/lib/python3.7/site-packages/requests/api.py", line 116, in post
    return request('post', url, data=data, json=json, **kwargs)
  File "/home/nikitas/anaconda3/lib/python3.7/site-packages/requests/api.py", line 60, in request
    return session.request(method=method, url=url, **kwargs)
  File "/home/nikitas/anaconda3/lib/python3.7/site-packages/requests/sessions.py", line 533, in request
    resp = self.send(prep, **send_kwargs)
  File "/home/nikitas/anaconda3/lib/python3.7/site-packages/requests/sessions.py", line 646, in send
    r = adapter.send(request, **kwargs)
  File "/home/nikitas/anaconda3/lib/python3.7/site-packages/requests/adapters.py", line 498, in send
    raise ConnectionError(err, request=request)
requests.exceptions.ConnectionError: ('Connection aborted.', RemoteDisconnected('Remote end closed connection without response'))
127.0.0.1 - - [05/Apr/2020 01:28:38] "[1m[35mPOST /new_transaction HTTP/1.1[0m" 500 -
Traceback (most recent call last):
  File "/home/nikitas/anaconda3/lib/python3.7/site-packages/urllib3/connection.py", line 159, in _new_conn
    (self._dns_host, self.port), self.timeout, **extra_kw)
  File "/home/nikitas/anaconda3/lib/python3.7/site-packages/urllib3/util/connection.py", line 80, in create_connection
    raise err
  File "/home/nikitas/anaconda3/lib/python3.7/site-packages/urllib3/util/connection.py", line 70, in create_connection
    sock.connect(sa)
ConnectionRefusedError: [Errno 111] Connection refused

During handling of the above exception, another exception occurred:

Traceback (most recent call last):
  File "/home/nikitas/anaconda3/lib/python3.7/site-packages/urllib3/connectionpool.py", line 600, in urlopen
    chunked=chunked)
  File "/home/nikitas/anaconda3/lib/python3.7/site-packages/urllib3/connectionpool.py", line 354, in _make_request
    conn.request(method, url, **httplib_request_kw)
  File "/home/nikitas/anaconda3/lib/python3.7/http/client.py", line 1244, in request
    self._send_request(method, url, body, headers, encode_chunked)
  File "/home/nikitas/anaconda3/lib/python3.7/http/client.py", line 1290, in _send_request
    self.endheaders(body, encode_chunked=encode_chunked)
  File "/home/nikitas/anaconda3/lib/python3.7/http/client.py", line 1239, in endheaders
    self._send_output(message_body, encode_chunked=encode_chunked)
  File "/home/nikitas/anaconda3/lib/python3.7/http/client.py", line 1026, in _send_output
    self.send(msg)
  File "/home/nikitas/anaconda3/lib/python3.7/http/client.py", line 966, in send
    self.connect()
  File "/home/nikitas/anaconda3/lib/python3.7/site-packages/urllib3/connection.py", line 181, in connect
    conn = self._new_conn()
  File "/home/nikitas/anaconda3/lib/python3.7/site-packages/urllib3/connection.py", line 168, in _new_conn
    self, "Failed to establish a new connection: %s" % e)
urllib3.exceptions.NewConnectionError: <urllib3.connection.HTTPConnection object at 0x7f07d8a32fd0>: Failed to establish a new connection: [Errno 111] Connection refused

During handling of the above exception, another exception occurred:

Traceback (most recent call last):
  File "/home/nikitas/anaconda3/lib/python3.7/site-packages/requests/adapters.py", line 449, in send
    timeout=timeout
  File "/home/nikitas/anaconda3/lib/python3.7/site-packages/urllib3/connectionpool.py", line 638, in urlopen
    _stacktrace=sys.exc_info()[2])
  File "/home/nikitas/anaconda3/lib/python3.7/site-packages/urllib3/util/retry.py", line 399, in increment
    raise MaxRetryError(_pool, url, error or ResponseError(cause))
urllib3.exceptions.MaxRetryError: HTTPConnectionPool(host='localhost', port=1234): Max retries exceeded with url: /receive_block (Caused by NewConnectionError('<urllib3.connection.HTTPConnection object at 0x7f07d8a32fd0>: Failed to establish a new connection: [Errno 111] Connection refused'))

During handling of the above exception, another exception occurred:

Traceback (most recent call last):
  File "/home/nikitas/anaconda3/lib/python3.7/site-packages/flask/app.py", line 2463, in __call__
    return self.wsgi_app(environ, start_response)
  File "/home/nikitas/anaconda3/lib/python3.7/site-packages/flask/app.py", line 2449, in wsgi_app
    response = self.handle_exception(e)
  File "/home/nikitas/anaconda3/lib/python3.7/site-packages/flask/app.py", line 1866, in handle_exception
    reraise(exc_type, exc_value, tb)
  File "/home/nikitas/anaconda3/lib/python3.7/site-packages/flask/_compat.py", line 39, in reraise
    raise value
  File "/home/nikitas/anaconda3/lib/python3.7/site-packages/flask/app.py", line 2446, in wsgi_app
    response = self.full_dispatch_request()
  File "/home/nikitas/anaconda3/lib/python3.7/site-packages/flask/app.py", line 1951, in full_dispatch_request
    rv = self.handle_user_exception(e)
  File "/home/nikitas/anaconda3/lib/python3.7/site-packages/flask/app.py", line 1820, in handle_user_exception
    reraise(exc_type, exc_value, tb)
  File "/home/nikitas/anaconda3/lib/python3.7/site-packages/flask/_compat.py", line 39, in reraise
    raise value
  File "/home/nikitas/anaconda3/lib/python3.7/site-packages/flask/app.py", line 1949, in full_dispatch_request
    rv = self.dispatch_request()
  File "/home/nikitas/anaconda3/lib/python3.7/site-packages/flask/app.py", line 1935, in dispatch_request
    return self.view_functions[rule.endpoint](**req.view_args)
  File "/home/nikitas/Desktop/distrib/noobcash/backend/broadcast.py", line 215, in cli_new_transaction
    if (new_transaction(node['pub'], amount)):
  File "/home/nikitas/Desktop/distrib/noobcash/backend/broadcast.py", line 82, in new_transaction
    t = Transaction.create_transaction(receiver, amount)
  File "/home/nikitas/Desktop/distrib/noobcash/backend/transaction.py", line 174, in create_transaction
    State.state.mine_block()
  File "/home/nikitas/Desktop/distrib/noobcash/backend/state.py", line 80, in mine_block
    broadcast.broadcast_block(block)
  File "/home/nikitas/Desktop/distrib/noobcash/backend/broadcast.py", line 22, in broadcast_block
    return broadcast(json_block,'receive_block',node_id)
  File "/home/nikitas/Desktop/distrib/noobcash/backend/broadcast.py", line 41, in broadcast
    response = requests.post('{}/{}'.format(ip,rest_point), json=json_obj)
  File "/home/nikitas/anaconda3/lib/python3.7/site-packages/requests/api.py", line 116, in post
    return request('post', url, data=data, json=json, **kwargs)
  File "/home/nikitas/anaconda3/lib/python3.7/site-packages/requests/api.py", line 60, in request
    return session.request(method=method, url=url, **kwargs)
  File "/home/nikitas/anaconda3/lib/python3.7/site-packages/requests/sessions.py", line 533, in request
    resp = self.send(prep, **send_kwargs)
  File "/home/nikitas/anaconda3/lib/python3.7/site-packages/requests/sessions.py", line 646, in send
    r = adapter.send(request, **kwargs)
  File "/home/nikitas/anaconda3/lib/python3.7/site-packages/requests/adapters.py", line 516, in send
    raise ConnectionError(e, request=request)
requests.exceptions.ConnectionError: HTTPConnectionPool(host='localhost', port=1234): Max retries exceeded with url: /receive_block (Caused by NewConnectionError('<urllib3.connection.HTTPConnection object at 0x7f07d8a32fd0>: Failed to establish a new connection: [Errno 111] Connection refused'))
127.0.0.1 - - [05/Apr/2020 01:28:38] "[1m[35mPOST /new_transaction HTTP/1.1[0m" 500 -
Traceback (most recent call last):
  File "/home/nikitas/anaconda3/lib/python3.7/site-packages/urllib3/connection.py", line 159, in _new_conn
    (self._dns_host, self.port), self.timeout, **extra_kw)
  File "/home/nikitas/anaconda3/lib/python3.7/site-packages/urllib3/util/connection.py", line 80, in create_connection
    raise err
  File "/home/nikitas/anaconda3/lib/python3.7/site-packages/urllib3/util/connection.py", line 70, in create_connection
    sock.connect(sa)
ConnectionRefusedError: [Errno 111] Connection refused

During handling of the above exception, another exception occurred:

Traceback (most recent call last):
  File "/home/nikitas/anaconda3/lib/python3.7/site-packages/urllib3/connectionpool.py", line 600, in urlopen
    chunked=chunked)
  File "/home/nikitas/anaconda3/lib/python3.7/site-packages/urllib3/connectionpool.py", line 354, in _make_request
    conn.request(method, url, **httplib_request_kw)
  File "/home/nikitas/anaconda3/lib/python3.7/http/client.py", line 1244, in request
    self._send_request(method, url, body, headers, encode_chunked)
  File "/home/nikitas/anaconda3/lib/python3.7/http/client.py", line 1290, in _send_request
    self.endheaders(body, encode_chunked=encode_chunked)
  File "/home/nikitas/anaconda3/lib/python3.7/http/client.py", line 1239, in endheaders
    self._send_output(message_body, encode_chunked=encode_chunked)
  File "/home/nikitas/anaconda3/lib/python3.7/http/client.py", line 1026, in _send_output
    self.send(msg)
  File "/home/nikitas/anaconda3/lib/python3.7/http/client.py", line 966, in send
    self.connect()
  File "/home/nikitas/anaconda3/lib/python3.7/site-packages/urllib3/connection.py", line 181, in connect
    conn = self._new_conn()
  File "/home/nikitas/anaconda3/lib/python3.7/site-packages/urllib3/connection.py", line 168, in _new_conn
    self, "Failed to establish a new connection: %s" % e)
urllib3.exceptions.NewConnectionError: <urllib3.connection.HTTPConnection object at 0x7f07d8749bd0>: Failed to establish a new connection: [Errno 111] Connection refused

During handling of the above exception, another exception occurred:

Traceback (most recent call last):
  File "/home/nikitas/anaconda3/lib/python3.7/site-packages/requests/adapters.py", line 449, in send
    timeout=timeout
  File "/home/nikitas/anaconda3/lib/python3.7/site-packages/urllib3/connectionpool.py", line 638, in urlopen
    _stacktrace=sys.exc_info()[2])
  File "/home/nikitas/anaconda3/lib/python3.7/site-packages/urllib3/util/retry.py", line 399, in increment
    raise MaxRetryError(_pool, url, error or ResponseError(cause))
urllib3.exceptions.MaxRetryError: HTTPConnectionPool(host='localhost', port=1234): Max retries exceeded with url: /receive_transaction (Caused by NewConnectionError('<urllib3.connection.HTTPConnection object at 0x7f07d8749bd0>: Failed to establish a new connection: [Errno 111] Connection refused'))

During handling of the above exception, another exception occurred:

Traceback (most recent call last):
  File "/home/nikitas/anaconda3/lib/python3.7/site-packages/flask/app.py", line 2463, in __call__
    return self.wsgi_app(environ, start_response)
  File "/home/nikitas/anaconda3/lib/python3.7/site-packages/flask/app.py", line 2449, in wsgi_app
    response = self.handle_exception(e)
  File "/home/nikitas/anaconda3/lib/python3.7/site-packages/flask/app.py", line 1866, in handle_exception
    reraise(exc_type, exc_value, tb)
  File "/home/nikitas/anaconda3/lib/python3.7/site-packages/flask/_compat.py", line 39, in reraise
    raise value
  File "/home/nikitas/anaconda3/lib/python3.7/site-packages/flask/app.py", line 2446, in wsgi_app
    response = self.full_dispatch_request()
  File "/home/nikitas/anaconda3/lib/python3.7/site-packages/flask/app.py", line 1951, in full_dispatch_request
    rv = self.handle_user_exception(e)
  File "/home/nikitas/anaconda3/lib/python3.7/site-packages/flask/app.py", line 1820, in handle_user_exception
    reraise(exc_type, exc_value, tb)
  File "/home/nikitas/anaconda3/lib/python3.7/site-packages/flask/_compat.py", line 39, in reraise
    raise value
  File "/home/nikitas/anaconda3/lib/python3.7/site-packages/flask/app.py", line 1949, in full_dispatch_request
    rv = self.dispatch_request()
  File "/home/nikitas/anaconda3/lib/python3.7/site-packages/flask/app.py", line 1935, in dispatch_request
    return self.view_functions[rule.endpoint](**req.view_args)
  File "/home/nikitas/Desktop/distrib/noobcash/backend/broadcast.py", line 215, in cli_new_transaction
    if (new_transaction(node['pub'], amount)):
  File "/home/nikitas/Desktop/distrib/noobcash/backend/broadcast.py", line 85, in new_transaction
    return broadcast_transaction(t,new_id)
  File "/home/nikitas/Desktop/distrib/noobcash/backend/broadcast.py", line 26, in broadcast_transaction
    return broadcast(json_t,'receive_transaction',node_id)
  File "/home/nikitas/Desktop/distrib/noobcash/backend/broadcast.py", line 41, in broadcast
    response = requests.post('{}/{}'.format(ip,rest_point), json=json_obj)
  File "/home/nikitas/anaconda3/lib/python3.7/site-packages/requests/api.py", line 116, in post
    return request('post', url, data=data, json=json, **kwargs)
  File "/home/nikitas/anaconda3/lib/python3.7/site-packages/requests/api.py", line 60, in request
    return session.request(method=method, url=url, **kwargs)
  File "/home/nikitas/anaconda3/lib/python3.7/site-packages/requests/sessions.py", line 533, in request
    resp = self.send(prep, **send_kwargs)
  File "/home/nikitas/anaconda3/lib/python3.7/site-packages/requests/sessions.py", line 646, in send
    r = adapter.send(request, **kwargs)
  File "/home/nikitas/anaconda3/lib/python3.7/site-packages/requests/adapters.py", line 516, in send
    raise ConnectionError(e, request=request)
requests.exceptions.ConnectionError: HTTPConnectionPool(host='localhost', port=1234): Max retries exceeded with url: /receive_transaction (Caused by NewConnectionError('<urllib3.connection.HTTPConnection object at 0x7f07d8749bd0>: Failed to establish a new connection: [Errno 111] Connection refused'))
127.0.0.1 - - [05/Apr/2020 01:28:38] "[1m[35mPOST /new_transaction HTTP/1.1[0m" 500 -
Traceback (most recent call last):
  File "/home/nikitas/anaconda3/lib/python3.7/site-packages/urllib3/connection.py", line 159, in _new_conn
    (self._dns_host, self.port), self.timeout, **extra_kw)
  File "/home/nikitas/anaconda3/lib/python3.7/site-packages/urllib3/util/connection.py", line 80, in create_connection
    raise err
  File "/home/nikitas/anaconda3/lib/python3.7/site-packages/urllib3/util/connection.py", line 70, in create_connection
    sock.connect(sa)
ConnectionRefusedError: [Errno 111] Connection refused

During handling of the above exception, another exception occurred:

Traceback (most recent call last):
  File "/home/nikitas/anaconda3/lib/python3.7/site-packages/urllib3/connectionpool.py", line 600, in urlopen
    chunked=chunked)
  File "/home/nikitas/anaconda3/lib/python3.7/site-packages/urllib3/connectionpool.py", line 354, in _make_request
    conn.request(method, url, **httplib_request_kw)
  File "/home/nikitas/anaconda3/lib/python3.7/http/client.py", line 1244, in request
    self._send_request(method, url, body, headers, encode_chunked)
  File "/home/nikitas/anaconda3/lib/python3.7/http/client.py", line 1290, in _send_request
    self.endheaders(body, encode_chunked=encode_chunked)
  File "/home/nikitas/anaconda3/lib/python3.7/http/client.py", line 1239, in endheaders
    self._send_output(message_body, encode_chunked=encode_chunked)
  File "/home/nikitas/anaconda3/lib/python3.7/http/client.py", line 1026, in _send_output
    self.send(msg)
  File "/home/nikitas/anaconda3/lib/python3.7/http/client.py", line 966, in send
    self.connect()
  File "/home/nikitas/anaconda3/lib/python3.7/site-packages/urllib3/connection.py", line 181, in connect
    conn = self._new_conn()
  File "/home/nikitas/anaconda3/lib/python3.7/site-packages/urllib3/connection.py", line 168, in _new_conn
    self, "Failed to establish a new connection: %s" % e)
urllib3.exceptions.NewConnectionError: <urllib3.connection.HTTPConnection object at 0x7f07d8451110>: Failed to establish a new connection: [Errno 111] Connection refused

During handling of the above exception, another exception occurred:

Traceback (most recent call last):
  File "/home/nikitas/anaconda3/lib/python3.7/site-packages/requests/adapters.py", line 449, in send
    timeout=timeout
  File "/home/nikitas/anaconda3/lib/python3.7/site-packages/urllib3/connectionpool.py", line 638, in urlopen
    _stacktrace=sys.exc_info()[2])
  File "/home/nikitas/anaconda3/lib/python3.7/site-packages/urllib3/util/retry.py", line 399, in increment
    raise MaxRetryError(_pool, url, error or ResponseError(cause))
urllib3.exceptions.MaxRetryError: HTTPConnectionPool(host='localhost', port=1234): Max retries exceeded with url: /receive_transaction (Caused by NewConnectionError('<urllib3.connection.HTTPConnection object at 0x7f07d8451110>: Failed to establish a new connection: [Errno 111] Connection refused'))

During handling of the above exception, another exception occurred:

Traceback (most recent call last):
  File "/home/nikitas/anaconda3/lib/python3.7/site-packages/flask/app.py", line 2463, in __call__
    return self.wsgi_app(environ, start_response)
  File "/home/nikitas/anaconda3/lib/python3.7/site-packages/flask/app.py", line 2449, in wsgi_app
    response = self.handle_exception(e)
  File "/home/nikitas/anaconda3/lib/python3.7/site-packages/flask/app.py", line 1866, in handle_exception
    reraise(exc_type, exc_value, tb)
  File "/home/nikitas/anaconda3/lib/python3.7/site-packages/flask/_compat.py", line 39, in reraise
    raise value
  File "/home/nikitas/anaconda3/lib/python3.7/site-packages/flask/app.py", line 2446, in wsgi_app
    response = self.full_dispatch_request()
  File "/home/nikitas/anaconda3/lib/python3.7/site-packages/flask/app.py", line 1951, in full_dispatch_request
    rv = self.handle_user_exception(e)
  File "/home/nikitas/anaconda3/lib/python3.7/site-packages/flask/app.py", line 1820, in handle_user_exception
    reraise(exc_type, exc_value, tb)
  File "/home/nikitas/anaconda3/lib/python3.7/site-packages/flask/_compat.py", line 39, in reraise
    raise value
  File "/home/nikitas/anaconda3/lib/python3.7/site-packages/flask/app.py", line 1949, in full_dispatch_request
    rv = self.dispatch_request()
  File "/home/nikitas/anaconda3/lib/python3.7/site-packages/flask/app.py", line 1935, in dispatch_request
    return self.view_functions[rule.endpoint](**req.view_args)
  File "/home/nikitas/Desktop/distrib/noobcash/backend/broadcast.py", line 215, in cli_new_transaction
    if (new_transaction(node['pub'], amount)):
  File "/home/nikitas/Desktop/distrib/noobcash/backend/broadcast.py", line 85, in new_transaction
    return broadcast_transaction(t,new_id)
  File "/home/nikitas/Desktop/distrib/noobcash/backend/broadcast.py", line 26, in broadcast_transaction
    return broadcast(json_t,'receive_transaction',node_id)
  File "/home/nikitas/Desktop/distrib/noobcash/backend/broadcast.py", line 41, in broadcast
    response = requests.post('{}/{}'.format(ip,rest_point), json=json_obj)
  File "/home/nikitas/anaconda3/lib/python3.7/site-packages/requests/api.py", line 116, in post
    return request('post', url, data=data, json=json, **kwargs)
  File "/home/nikitas/anaconda3/lib/python3.7/site-packages/requests/api.py", line 60, in request
    return session.request(method=method, url=url, **kwargs)
  File "/home/nikitas/anaconda3/lib/python3.7/site-packages/requests/sessions.py", line 533, in request
    resp = self.send(prep, **send_kwargs)
  File "/home/nikitas/anaconda3/lib/python3.7/site-packages/requests/sessions.py", line 646, in send
    r = adapter.send(request, **kwargs)
  File "/home/nikitas/anaconda3/lib/python3.7/site-packages/requests/adapters.py", line 516, in send
    raise ConnectionError(e, request=request)
requests.exceptions.ConnectionError: HTTPConnectionPool(host='localhost', port=1234): Max retries exceeded with url: /receive_transaction (Caused by NewConnectionError('<urllib3.connection.HTTPConnection object at 0x7f07d8451110>: Failed to establish a new connection: [Errno 111] Connection refused'))
127.0.0.1 - - [05/Apr/2020 01:28:38] "[1m[35mPOST /new_transaction HTTP/1.1[0m" 500 -
Traceback (most recent call last):
  File "/home/nikitas/anaconda3/lib/python3.7/site-packages/urllib3/connection.py", line 159, in _new_conn
    (self._dns_host, self.port), self.timeout, **extra_kw)
  File "/home/nikitas/anaconda3/lib/python3.7/site-packages/urllib3/util/connection.py", line 80, in create_connection
    raise err
  File "/home/nikitas/anaconda3/lib/python3.7/site-packages/urllib3/util/connection.py", line 70, in create_connection
    sock.connect(sa)
ConnectionRefusedError: [Errno 111] Connection refused

During handling of the above exception, another exception occurred:

Traceback (most recent call last):
  File "/home/nikitas/anaconda3/lib/python3.7/site-packages/urllib3/connectionpool.py", line 600, in urlopen
    chunked=chunked)
  File "/home/nikitas/anaconda3/lib/python3.7/site-packages/urllib3/connectionpool.py", line 354, in _make_request
    conn.request(method, url, **httplib_request_kw)
  File "/home/nikitas/anaconda3/lib/python3.7/http/client.py", line 1244, in request
    self._send_request(method, url, body, headers, encode_chunked)
  File "/home/nikitas/anaconda3/lib/python3.7/http/client.py", line 1290, in _send_request
    self.endheaders(body, encode_chunked=encode_chunked)
  File "/home/nikitas/anaconda3/lib/python3.7/http/client.py", line 1239, in endheaders
    self._send_output(message_body, encode_chunked=encode_chunked)
  File "/home/nikitas/anaconda3/lib/python3.7/http/client.py", line 1026, in _send_output
    self.send(msg)
  File "/home/nikitas/anaconda3/lib/python3.7/http/client.py", line 966, in send
    self.connect()
  File "/home/nikitas/anaconda3/lib/python3.7/site-packages/urllib3/connection.py", line 181, in connect
    conn = self._new_conn()
  File "/home/nikitas/anaconda3/lib/python3.7/site-packages/urllib3/connection.py", line 168, in _new_conn
    self, "Failed to establish a new connection: %s" % e)
urllib3.exceptions.NewConnectionError: <urllib3.connection.HTTPConnection object at 0x7f07d8152650>: Failed to establish a new connection: [Errno 111] Connection refused

During handling of the above exception, another exception occurred:

Traceback (most recent call last):
  File "/home/nikitas/anaconda3/lib/python3.7/site-packages/requests/adapters.py", line 449, in send
    timeout=timeout
  File "/home/nikitas/anaconda3/lib/python3.7/site-packages/urllib3/connectionpool.py", line 638, in urlopen
    _stacktrace=sys.exc_info()[2])
  File "/home/nikitas/anaconda3/lib/python3.7/site-packages/urllib3/util/retry.py", line 399, in increment
    raise MaxRetryError(_pool, url, error or ResponseError(cause))
urllib3.exceptions.MaxRetryError: HTTPConnectionPool(host='localhost', port=1234): Max retries exceeded with url: /receive_transaction (Caused by NewConnectionError('<urllib3.connection.HTTPConnection object at 0x7f07d8152650>: Failed to establish a new connection: [Errno 111] Connection refused'))

During handling of the above exception, another exception occurred:

Traceback (most recent call last):
  File "/home/nikitas/anaconda3/lib/python3.7/site-packages/flask/app.py", line 2463, in __call__
    return self.wsgi_app(environ, start_response)
  File "/home/nikitas/anaconda3/lib/python3.7/site-packages/flask/app.py", line 2449, in wsgi_app
    response = self.handle_exception(e)
  File "/home/nikitas/anaconda3/lib/python3.7/site-packages/flask/app.py", line 1866, in handle_exception
    reraise(exc_type, exc_value, tb)
  File "/home/nikitas/anaconda3/lib/python3.7/site-packages/flask/_compat.py", line 39, in reraise
    raise value
  File "/home/nikitas/anaconda3/lib/python3.7/site-packages/flask/app.py", line 2446, in wsgi_app
    response = self.full_dispatch_request()
  File "/home/nikitas/anaconda3/lib/python3.7/site-packages/flask/app.py", line 1951, in full_dispatch_request
    rv = self.handle_user_exception(e)
  File "/home/nikitas/anaconda3/lib/python3.7/site-packages/flask/app.py", line 1820, in handle_user_exception
    reraise(exc_type, exc_value, tb)
  File "/home/nikitas/anaconda3/lib/python3.7/site-packages/flask/_compat.py", line 39, in reraise
    raise value
  File "/home/nikitas/anaconda3/lib/python3.7/site-packages/flask/app.py", line 1949, in full_dispatch_request
    rv = self.dispatch_request()
  File "/home/nikitas/anaconda3/lib/python3.7/site-packages/flask/app.py", line 1935, in dispatch_request
    return self.view_functions[rule.endpoint](**req.view_args)
  File "/home/nikitas/Desktop/distrib/noobcash/backend/broadcast.py", line 215, in cli_new_transaction
    if (new_transaction(node['pub'], amount)):
  File "/home/nikitas/Desktop/distrib/noobcash/backend/broadcast.py", line 85, in new_transaction
    return broadcast_transaction(t,new_id)
  File "/home/nikitas/Desktop/distrib/noobcash/backend/broadcast.py", line 26, in broadcast_transaction
    return broadcast(json_t,'receive_transaction',node_id)
  File "/home/nikitas/Desktop/distrib/noobcash/backend/broadcast.py", line 41, in broadcast
    response = requests.post('{}/{}'.format(ip,rest_point), json=json_obj)
  File "/home/nikitas/anaconda3/lib/python3.7/site-packages/requests/api.py", line 116, in post
    return request('post', url, data=data, json=json, **kwargs)
  File "/home/nikitas/anaconda3/lib/python3.7/site-packages/requests/api.py", line 60, in request
    return session.request(method=method, url=url, **kwargs)
  File "/home/nikitas/anaconda3/lib/python3.7/site-packages/requests/sessions.py", line 533, in request
    resp = self.send(prep, **send_kwargs)
  File "/home/nikitas/anaconda3/lib/python3.7/site-packages/requests/sessions.py", line 646, in send
    r = adapter.send(request, **kwargs)
  File "/home/nikitas/anaconda3/lib/python3.7/site-packages/requests/adapters.py", line 516, in send
    raise ConnectionError(e, request=request)
requests.exceptions.ConnectionError: HTTPConnectionPool(host='localhost', port=1234): Max retries exceeded with url: /receive_transaction (Caused by NewConnectionError('<urllib3.connection.HTTPConnection object at 0x7f07d8152650>: Failed to establish a new connection: [Errno 111] Connection refused'))
127.0.0.1 - - [05/Apr/2020 01:28:38] "[1m[35mPOST /new_transaction HTTP/1.1[0m" 500 -
Requesting lock
Acquiring lock
Inital block was valid, no need to resolve conflict
Running average block addition time:  0.0006492137908935547
Releasing lock
